Workbook

Sheet PROCESO
A1: AGRO PACAYALES · PLANTA CAMOTE 2026 | KARDEX POR CALIDAD — Proceso · Envío · Devolución · Saldo en planta (jabas y kg) | X1: Factor kg/unidad
A2: Calidades A/P/C/M en jabas · Chancho en sacos (1 saco = 95 kg). Conversión jaba→kg: A=15 · P=18 · C=17 · M=17. Saldo en planta = Apertura + Procesado − Enviado + Devuelto. | X2: A | Y2: 15
X3: P | Y3: 18
A4: DETALLE DIARIO POR CALIDAD | E4: PROCESO | I4: ENVIO DE PRODUCTO | X4: C | Y4: 17
A5: Fecha Compra | B5: Compra sacos | C5: Peso aprox | D5: Compra kg | E5: Fecha Proceso | F5: Calidad | G5: Proceso jabas | H5: Proceso kg | I5: Fecha Envio | J5: N° Guía | K5: Envío jabas | L5: Envío kg | M5: Devolución Jabas | N5: Reproceso Kg | O5: Trasiego jabas | P5: Trasiego Kg | Q5: Saldo jabas | R5: Saldo kg | S5: Nota | X5: M | Y5: 17
A6: SAB 11-07 | F6: A | H6: =G6*VLOOKUP(F6,$X$2:$Y$7,2,FALSE()) -> 0 | J6: Apertura | L6: =K6*VLOOKUP(F6,$X$2:$Y$7,2,FALSE()) -> 0 | Q6: 8 | R6: =Q6*VLOOKUP(F6,$X$2:$Y$7,2,FALSE()) -> 120 | X6: Chancho | Y6: 95
F7: P | H7: =G7*VLOOKUP(F7,$X$2:$Y$7,2,FALSE()) -> 0 | J7: Apertura | L7: =K7*VLOOKUP(F7,$X$2:$Y$7,2,FALSE()) -> 0 | Q7: 0 | R7: =Q7*VLOOKUP(F7,$X$2:$Y$7,2,FALSE()) -> 0 | X7: Malogrado | Y7: 1
F8: C | H8: =G8*VLOOKUP(F8,$X$2:$Y$7,2,FALSE()) -> 0 | J8: Apertura | L8: =K8*VLOOKUP(F8,$X$2:$Y$7,2,FALSE()) -> 0 | Q8: 0 | R8: =Q8*VLOOKUP(F8,$X$2:$Y$7,2,FALSE()) -> 0
F9: M | H9: =G9*VLOOKUP(F9,$X$2:$Y$7,2,FALSE()) -> 0 | J9: Apertura | L9: =K9*VLOOKUP(F9,$X$2:$Y$7,2,FALSE()) -> 0 | Q9: 7 | R9: =Q9*VLOOKUP(F9,$X$2:$Y$7,2,FALSE()) -> 119
F10: Chancho | H10: =G10*VLOOKUP(F10,$X$2:$Y$7,2,FALSE()) -> 0 | L10: =K10*VLOOKUP(F10,$X$2:$Y$7,2,FALSE()) -> 0 | Q10: 20 | R10: =Q10*VLOOKUP(F10,$X$2:$Y$7,2,FALSE()) -> 1900
F11: Malogrado
A12: DOM 12-07 | B12: 30 | C12: 95 | D12: =B12*C12 -> 2850 | F12: A | G12: 59 | H12: =G12*VLOOKUP(F12,$X$2:$Y$7,2,FALSE()) -> 885 | I12: DOM 12-07 | J12: 2977 | K12: 67 | L12: =K12*VLOOKUP(F12,$X$2:$Y$7,2,FALSE()) -> 1005 | Q12: =Q6+G12-K12+M12-O12 -> 0 | R12: =R6+H12-L12+N12-O12*VLOOKUP(F12,$X$2:$Y$7,2,FALSE()) -> 0
F13: P | G13: 11 | H13: =G13*VLOOKUP(F13,$X$2:$Y$7,2,FALSE()) -> 198 | J13: 2977 | K13: 11 | L13: =K13*VLOOKUP(F13,$X$2:$Y$7,2,FALSE()) -> 198 | Q13: =Q7+G13-K13+M13-O13 -> 0 | R13: =R7+H13-L13+N13-O13*VLOOKUP(F13,$X$2:$Y$7,2,FALSE()) -> 0
F14: C | G14: 12 | H14: =G14*VLOOKUP(F14,$X$2:$Y$7,2,FALSE()) -> 204 | J14: 2977 | K14: 12 | L14: =K14*VLOOKUP(F14,$X$2:$Y$7,2,FALSE()) -> 204 | Q14: =Q8+G14-K14+M14-O14 -> 0 | R14: =R8+H14-L14+N14-O14*VLOOKUP(F14,$X$2:$Y$7,2,FALSE()) -> 0
F15: M | G15: 64 | H15: =G15*VLOOKUP(F15,$X$2:$Y$7,2,FALSE()) -> 1088 | J15: 2977 | K15: 42 | L15: =K15*VLOOKUP(F15,$X$2:$Y$7,2,FALSE()) -> 714 | Q15: =Q9+G15-K15+M15-O15 -> 29 | R15: =R9+H15-L15+N15-O15*VLOOKUP(F15,$X$2:$Y$7,2,FALSE()) -> 493
F16: Chancho | G16: 6 | H16: =G16*VLOOKUP(F16,$X$2:$Y$7,2,FALSE()) -> 570 | K16: 0 | L16: =K16*VLOOKUP(F16,$X$2:$Y$7,2,FALSE()) -> 0 | Q16: =Q10+G16-K16+M16-O16 -> 26 | R16: =R10+H16-L16+N16-O16*VLOOKUP(F16,$X$2:$Y$7,2,FALSE()) -> 2470
F17: Malogrado
A18: LUN 13-07 | B18: 40 | C18: 95 | D18: =B18*C18 -> 3800 | F18: A | G18: 107 | H18: =G18*VLOOKUP(F18,$X$2:$Y$7,2,FALSE()) -> 1605 | I18: LUN 13-07 | J18: 2980 | K18: 67 | L18: =K18*VLOOKUP(F18,$X$2:$Y$7,2,FALSE()) -> 1005 | Q18: =Q12+G18-K18+M18-O18 -> 40 | R18: =R12+H18-L18+N18-O18*VLOOKUP(F18,$X$2:$Y$7,2,FALSE()) -> 600
F19: P | G19: 11 | H19: =G19*VLOOKUP(F19,$X$2:$Y$7,2,FALSE()) -> 198 | J19: 2980 | K19: 11 | L19: =K19*VLOOKUP(F19,$X$2:$Y$7,2,FALSE()) -> 198 | Q19: =Q13+G19-K19+M19-O19 -> 0 | R19: =R13+H19-L19+N19-O19*VLOOKUP(F19,$X$2:$Y$7,2,FALSE()) -> 0
F20: C | G20: 12 | H20: =G20*VLOOKUP(F20,$X$2:$Y$7,2,FALSE()) -> 204 | J20: 2980 | K20: 12 | L20: =K20*VLOOKUP(F20,$X$2:$Y$7,2,FALSE()) -> 204 | Q20: =Q14+G20-K20+M20-O20 -> 0 | R20: =R14+H20-L20+N20-O20*VLOOKUP(F20,$X$2:$Y$7,2,FALSE()) -> 0
F21: M | G21: 110 | H21: =G21*VLOOKUP(F21,$X$2:$Y$7,2,FALSE()) -> 1870 | J21: 2980 | K21: 97 | L21: =K21*VLOOKUP(F21,$X$2:$Y$7,2,FALSE()) -> 1649 | Q21: =Q15+G21-K21+M21-O21 -> 42 | R21: =R15+H21-L21+N21-O21*VLOOKUP(F21,$X$2:$Y$7,2,FALSE()) -> 714
F22: Chancho | G22: 2 | H22: =G22*VLOOKUP(F22,$X$2:$Y$7,2,FALSE()) -> 190 | K22: 0 | L22: =K22*VLOOKUP(F22,$X$2:$Y$7,2,FALSE()) -> 0 | Q22: =Q16+G22-K22+M22-O22 -> 28 | R22: =R16+H22-L22+N22-O22*VLOOKUP(F22,$X$2:$Y$7,2,FALSE()) -> 2660
F23: Malogrado
A24: MAR 14-07 | B24: 40 | C24: 95 | D24: =B24*C24 -> 3800 | F24: A | G24: 45 | H24: =G24*VLOOKUP(F24,$X$2:$Y$7,2,FALSE()) -> 675 | I24: MAR 14-07 | J24: 2984 | K24: 67 | L24: =K24*VLOOKUP(F24,$X$2:$Y$7,2,FALSE()) -> 1005 | Q24: =Q18+G24-K24+M24-O24 -> 18 | R24: =R18+H24-L24+N24-O24*VLOOKUP(F24,$X$2:$Y$7,2,FALSE()) -> 270
F25: P | G25: 11 | H25: =G25*VLOOKUP(F25,$X$2:$Y$7,2,FALSE()) -> 198 | J25: 2984 | K25: 11 | L25: =K25*VLOOKUP(F25,$X$2:$Y$7,2,FALSE()) -> 198 | Q25: =Q19+G25-K25+M25-O25 -> 0 | R25: =R19+H25-L25+N25-O25*VLOOKUP(F25,$X$2:$Y$7,2,FALSE()) -> 0
F26: C | G26: 12 | H26: =G26*VLOOKUP(F26,$X$2:$Y$7,2,FALSE()) -> 204 | J26: 2984 | K26: 12 | L26: =K26*VLOOKUP(F26,$X$2:$Y$7,2,FALSE()) -> 204 | Q26: =Q20+G26-K26+M26-O26 -> 0 | R26: =R20+H26-L26+N26-O26*VLOOKUP(F26,$X$2:$Y$7,2,FALSE()) -> 0
F27: M | G27: 121 | H27: =G27*VLOOKUP(F27,$X$2:$Y$7,2,FALSE()) -> 2057 | J27: 2984 | K27: 116 | L27: =K27*VLOOKUP(F27,$X$2:$Y$7,2,FALSE()) -> 1972 | Q27: =Q21+G27-K27+M27-O27 -> 47 | R27: =R21+H27-L27+N27-O27*VLOOKUP(F27,$X$2:$Y$7,2,FALSE()) -> 799
F28: Chancho | G28: 7 | H28: =G28*VLOOKUP(F28,$X$2:$Y$7,2,FALSE()) -> 665 | K28: 0 | L28: =K28*VLOOKUP(F28,$X$2:$Y$7,2,FALSE()) -> 0 | Q28: =Q22+G28-K28+M28-O28 -> 35 | R28: =R22+H28-L28+N28-O28*VLOOKUP(F28,$X$2:$Y$7,2,FALSE()) -> 3325
F29: Malogrado
A30: MIE 15-07 | B30: 40 | C30: 95 | D30: =B30*C30 -> 3800 | F30: A | G30: 79 | H30: =G30*VLOOKUP(F30,$X$2:$Y$7,2,FALSE()) -> 1185 | I30: MIE 15-07 | J30: 2986 | K30: 67 | L30: =K30*VLOOKUP(F30,$X$2:$Y$7,2,FALSE()) -> 1005 | Q30: =Q24+G30-K30+M30-O30 -> 30 | R30: =R24+H30-L30+N30-O30*VLOOKUP(F30,$X$2:$Y$7,2,FALSE()) -> 450
F31: P | G31: 22 | H31: =G31*VLOOKUP(F31,$X$2:$Y$7,2,FALSE()) -> 396 | J31: 2986 | K31: 11 | L31: =K31*VLOOKUP(F31,$X$2:$Y$7,2,FALSE()) -> 198 | Q31: =Q25+G31-K31+M31-O31 -> 11 | R31: =R25+H31-L31+N31-O31*VLOOKUP(F31,$X$2:$Y$7,2,FALSE()) -> 198
F32: C | G32: 21 | H32: =G32*VLOOKUP(F32,$X$2:$Y$7,2,FALSE()) -> 357 | J32: 2986 | K32: 9 | L32: =K32*VLOOKUP(F32,$X$2:$Y$7,2,FALSE()) -> 153 | Q32: =Q26+G32-K32+M32-O32 -> 12 | R32: =R26+H32-L32+N32-O32*VLOOKUP(F32,$X$2:$Y$7,2,FALSE()) -> 204
F33: M | G33: 83 | H33: =G33*VLOOKUP(F33,$X$2:$Y$7,2,FALSE()) -> 1411 | J33: 2986 | K33: 95 | L33: =K33*VLOOKUP(F33,$X$2:$Y$7,2,FALSE()) -> 1615 | Q33: =Q27+G33-K33+M33-O33 -> 35 | R33: =R27+H33-L33+N33-O33*VLOOKUP(F33,$X$2:$Y$7,2,FALSE()) -> 595
F34: Chancho | G34: 5 | H34: =G34*VLOOKUP(F34,$X$2:$Y$7,2,FALSE()) -> 475 | J34: TCK002-724 | K34: 35 | L34: =K34*VLOOKUP(F34,$X$2:$Y$7,2,FALSE()) -> 3325 | Q34: =Q28+G34-K34+M34-O34 -> 5 | R34: =R28+H34-L34+N34-O34*VLOOKUP(F34,$X$2:$Y$7,2,FALSE()) -> 475
F35: Malogrado
A36: JUE 16-07 | B36: 40 | C36: 95 | D36: =B36*C36 -> 3800 | F36: A | G36: 68 | H36: =G36*VLOOKUP(F36,$X$2:$Y$7,2,FALSE()) -> 1020 | I36: JUE 16-07 | J36: 2992 | K36: 63 | L36: =K36*VLOOKUP(F36,$X$2:$Y$7,2,FALSE()) -> 945 | Q36: =Q30+G36-K36+M36-O36 -> 35 | R36: =R30+H36-L36+N36-O36*VLOOKUP(F36,$X$2:$Y$7,2,FALSE()) -> 525
F37: P | G37: 11 | H37: =G37*VLOOKUP(F37,$X$2:$Y$7,2,FALSE()) -> 198 | J37: 2992 | K37: 11 | L37: =K37*VLOOKUP(F37,$X$2:$Y$7,2,FALSE()) -> 198 | Q37: =Q31+G37-K37+M37-O37 -> 11 | R37: =R31+H37-L37+N37-O37*VLOOKUP(F37,$X$2:$Y$7,2,FALSE()) -> 198
F38: C | G38: 12 | H38: =G38*VLOOKUP(F38,$X$2:$Y$7,2,FALSE()) -> 204 | J38: 2992 | K38: 12 | L38: =K38*VLOOKUP(F38,$X$2:$Y$7,2,FALSE()) -> 204 | Q38: =Q32+G38-K38+M38-O38 -> 12 | R38: =R32+H38-L38+N38-O38*VLOOKUP(F38,$X$2:$Y$7,2,FALSE()) -> 204
F39: M | G39: 116 | H39: =G39*VLOOKUP(F39,$X$2:$Y$7,2,FALSE()) -> 1972 | J39: 2992 | K39: 115 | L39: =K39*VLOOKUP(F39,$X$2:$Y$7,2,FALSE()) -> 1955 | Q39: =Q33+G39-K39+M39-O39 -> 36 | R39: =R33+H39-L39+N39-O39*VLOOKUP(F39,$X$2:$Y$7,2,FALSE()) -> 612
F40: Chancho | G40: 4 | H40: =G40*VLOOKUP(F40,$X$2:$Y$7,2,FALSE()) -> 380 | K40: 0 | L40: =K40*VLOOKUP(F40,$X$2:$Y$7,2,FALSE()) -> 0 | Q40: =Q34+G40-K40+M40-O40 -> 9 | R40: =R34+H40-L40+N40-O40*VLOOKUP(F40,$X$2:$Y$7,2,FALSE()) -> 855
...

Sheet TOTALES
A1: AGRO PACAYALES · PLANTA CAMOTE 2026 | TOTALES — Entradas / Salidas y Rendimiento (kg)
A2: 100% automático: cualquier dato que agregues o corrijas en PROCESO (incluso en fechas pasadas) aparece aquí solo, sin filas vacías y sin regenerar nada. ENTRADAS: compras y reprocesos. SALIDAS: envíos, chancho del proceso y malogrado.
C4: ENTRADAS | D4: SALIDAS
A5: Fecha | B5: Detalle | C5: Ingresos Kg | D5: Salidas Kg | E5: N. Guía / Nota | F5: Stock Kg
A6: =IFERROR(INDEX(K$6:K$201,MATCH(ROW()-5,J$6:J$201,0)),"") -> SAB 11-07 | B6: =IFERROR(INDEX(L$6:L$201,MATCH(ROW()-5,J$6:J$201,0)),"") -> APERTURA (saldo semana anterior) | C6: =IFERROR(INDEX(M$6:M$201,MATCH(ROW()-5,J$6:J$201,0)),"") | D6: =IFERROR(INDEX(N$6:N$201,MATCH(ROW()-5,J$6:J$201,0)),"") | E6: =IFERROR(INDEX(O$6:O$201,MATCH(ROW()-5,J$6:J$201,0)),"") -> Solo camote A/P/C/M, sin sacos de chancho | F6: =IFERROR(INDEX(P$6:P$201,MATCH(ROW()-5,J$6:J$201,0)),"") -> 239 | J6: 1 | K6: =PROCESO!A6 -> SAB 11-07 | L6: APERTURA (saldo semana anterior) | M6: ="" | N6: ="" | O6: Solo camote A/P/C/M, sin sacos de chancho | P6: =SUM(PROCESO!R6:R9) -> 239
A7: =IFERROR(INDEX(K$6:K$201,MATCH(ROW()-5,J$6:J$201,0)),"") -> DOM 12-07 | B7: =IFERROR(INDEX(L$6:L$201,MATCH(ROW()-5,J$6:J$201,0)),"") -> INGRESO (compra) | C7: =IFERROR(INDEX(M$6:M$201,MATCH(ROW()-5,J$6:J$201,0)),"") -> 2850 | D7: =IFERROR(INDEX(N$6:N$201,MATCH(ROW()-5,J$6:J$201,0)),"") | E7: =IFERROR(INDEX(O$6:O$201,MATCH(ROW()-5,J$6:J$201,0)),"") -> 30 sacos x 95 kg | F7: =IFERROR(INDEX(P$6:P$201,MATCH(ROW()-5,J$6:J$201,0)),"") -> 3089 | J7: =IF(PROCESO!D12>0,COUNT(J$6:J6)+1,"") -> 2 | K7: =IF(PROCESO!D12>0,PROCESO!A12&IF(COUNTIF(PROCESO!$A$6:A11,PROCESO!A12)>0," (Ped."&(COUNTIF(PROCESO!$A$6:A11,PROCESO!A12)+1)&")",""),"") -> DOM 12-07 | L7: =IF(PROCESO!D12>0,"INGRESO (compra)","") -> INGRESO (compra) | M7: =IF(PROCESO!D12>0,PROCESO!D12,"") -> 2850 | N7: ="" | O7: =IF(PROCESO!D12>0,PROCESO!B12&" sacos x "&PROCESO!C12&" kg","") -> 30 sacos x 95 kg | P7: =P6+N(M7)-N(N7) -> 3089
A8: =IFERROR(INDEX(K$6:K$201,MATCH(ROW()-5,J$6:J$201,0)),"") -> DOM 12-07 | B8: =IFERROR(INDEX(L$6:L$201,MATCH(ROW()-5,J$6:J$201,0)),"") -> CHANCHO (proceso) | C8: =IFERROR(INDEX(M$6:M$201,MATCH(ROW()-5,J$6:J$201,0)),"") | D8: =IFERROR(INDEX(N$6:N$201,MATCH(ROW()-5,J$6:J$201,0)),"") -> 570 | E8: =IFERROR(INDEX(O$6:O$201,MATCH(ROW()-5,J$6:J$201,0)),"") -> 6 sacos x 95 kg | F8: =IFERROR(INDEX(P$6:P$201,MATCH(ROW()-5,J$6:J$201,0)),"") -> 2519 | J8: =IF(N(PROCESO!H16)>0,COUNT(J$6:J7)+1,"") -> 3 | K8: =IF(N(PROCESO!H16)>0,PROCESO!A12&IF(COUNTIF(PROCESO!$A$6:A11,PROCESO!A12)>0," (Ped."&(COUNTIF(PROCESO!$A$6:A11,PROCESO!A12)+1)&")",""),"") -> DOM 12-07 | L8: =IF(N(PROCESO!H16)>0,"CHANCHO (proceso)","") -> CHANCHO (proceso) | M8: ="" | N8: =IF(N(PROCESO!H16)>0,N(PROCESO!H16),"") -> 570 | O8: =IF(N(PROCESO!H16)>0,PROCESO!G16&" sacos x 95 kg","") -> 6 sacos x 95 kg | P8: =P7+N(M8)-N(N8) -> 2519
A9: =IFERROR(INDEX(K$6:K$201,MATCH(ROW()-5,J$6:J$201,0)),"") -> DOM 12-07 | B9: =IFERROR(INDEX(L$6:L$201,MATCH(ROW()-5,J$6:J$201,0)),"") -> ENVÍO Guía 2977 | C9: =IFERROR(INDEX(M$6:M$201,MATCH(ROW()-5,J$6:J$201,0)),"") | D9: =IFERROR(INDEX(N$6:N$201,MATCH(ROW()-5,J$6:J$201,0)),"") -> 2121 | E9: =IFERROR(INDEX(O$6:O$201,MATCH(ROW()-5,J$6:J$201,0)),"") -> G-2977 | F9: =IFERROR(INDEX(P$6:P$201,MATCH(ROW()-5,J$6:J$201,0)),"") -> 398 | J9: =IF(N(PROCESO!H17)>0,COUNT(J$6:J8)+1,"") | K9: =IF(N(PROCESO!H17)>0,PROCESO!A12&IF(COUNTIF(PROCESO!$A$6:A11,PROCESO!A12)>0," (Ped."&(COUNTIF(PROCESO!$A$6:A11,PROCESO!A12)+1)&")",""),"") | L9: =IF(N(PROCESO!H17)>0,"MALOGRADO","") | M9: ="" | N9: =IF(N(PROCESO!H17)>0,N(PROCESO!H17),"") | O9: ="" | P9: =P8+N(M9)-N(N9) -> 2519
A10: =IFERROR(INDEX(K$6:K$201,MATCH(ROW()-5,J$6:J$201,0)),"") -> LUN 13-07 | B10: =IFERROR(INDEX(L$6:L$201,MATCH(ROW()-5,J$6:J$201,0)),"") -> INGRESO (compra) | C10: =IFERROR(INDEX(M$6:M$201,MATCH(ROW()-5,J$6:J$201,0)),"") -> 3800 | D10: =IFERROR(INDEX(N$6:N$201,MATCH(ROW()-5,J$6:J$201,0)),"") | E10: =IFERROR(INDEX(O$6:O$201,MATCH(ROW()-5,J$6:J$201,0)),"") -> 40 sacos x 95 kg | F10: =IFERROR(INDEX(P$6:P$201,MATCH(ROW()-5,J$6:J$201,0)),"") -> 4198 | J10: =IF(IF(PROCESO!J12<>"",PROCESO!J12,IF(PROCESO!J13<>"",PROCESO!J13,IF(PROCESO!J14<>"",PROCESO!J14,IF(PROCESO!J15<>"",PROCESO!J15,""))))<>"",COUNT(J$6:J9)+1,"") -> 4 | K10: =IF(IF(PROCESO!J12<>"",PROCESO!J12,IF(PROCESO!J13<>"",PROCESO!J13,IF(PROCESO!J14<>"",PROCESO!J14,IF(PROCESO!J15<>"",PROCESO!J15,""))))<>"",PROCESO!A12&IF(COUNTIF(PROCESO!$A$6:A11,PROCESO!A12)>0," (Ped."&(COUNTIF(PROCESO!$A$6:A11,PROCESO!A12)+1)&")",""),"") -> DOM 12-07 | L10: =IF(IF(PROCESO!J12<>"",PROCESO!J12,IF(PROCESO!J13<>"",PROCESO!J13,IF(PROCESO!J14<>"",PROCESO!J14,IF(PROCESO!J15<>"",PROCESO!J15,""))))<>"","ENVÍO Guía "&IF(LEFT(IF(PROCESO!J12<>"",PROCESO!J12,IF(PROCESO!J13<>"",PROCESO!J13,IF(PROCESO!J14<>"",PROCESO!J14,IF(PROCESO!J15<>"",PROCESO!J15,"")))),2)="G-",MID(IF(PROCESO!J12<>"",PROCESO!J12,IF(PROCESO!J13<>"",PROCESO!J13,IF(PROCESO!J14<>"",PROCESO!J14,IF(PROCESO!J15<>"",PROCESO!J15,"")))),3,99),IF(PROCESO!J12<>"",PROCESO!J12,IF(PROCESO!J13<>"",PROCESO!J13,IF(PROCESO!J14<>"",PROCESO!J14,IF(PROCESO!J15<>"",PROCESO!J15,""))))),"") -> ENVÍO Guía 2977 | M10: ="" | N10: =IF(IF(PROCESO!J12<>"",PROCESO!J12,IF(PROCESO!J13<>"",PROCESO!J13,IF(PROCESO!J14<>"",PROCESO!J14,IF(PROCESO!J15<>"",PROCESO!J15,""))))<>"",SUMIF(PROCESO!J12:J15,IF(PROCESO!J12<>"",PROCESO!J12,IF(PROCESO!J13<>"",PROCESO!J13,IF(PROCESO!J14<>"",PROCESO!J14,IF(PROCESO!J15<>"",PROCESO!J15,"")))),PROCESO!L12:L15),"") -> 2121 | O10: =IF(IF(PROCESO!J12<>"",PROCESO!J12,IF(PROCESO!J13<>"",PROCESO!J13,IF(PROCESO!J14<>"",PROCESO!J14,IF(PROCESO!J15<>"",PROCESO!J15,""))))<>"","G-"&IF(LEFT(IF(PROCESO!J12<>"",PROCESO!J12,IF(PROCESO!J13<>"",PROCESO!J13,IF(PROCESO!J14<>"",PROCESO!J14,IF(PROCESO!J15<>"",PROCESO!J15,"")))),2)="G-",MID(IF(PROCESO!J12<>"",PROCESO!J12,IF(PROCESO!J13<>"",PROCESO!J13,IF(PROCESO!J14<>"",PROCESO!J14,IF(PROCESO!J15<>"",PROCESO!J15,"")))),3,99),IF(PROCESO!J12<>"",PROCESO!J12,IF(PROCESO!J13<>"",PROCESO!J13,IF(PROCESO!J14<>"",PROCESO!J14,IF(PROCESO!J15<>"",PROCESO!J15,""))))),"") -> G-2977 | P10: =P9+N(M10)-N(N10) -> 398
A11: =IFERROR(INDEX(K$6:K$201,MATCH(ROW()-5,J$6:J$201,0)),"") -> LUN 13-07 | B11: =IFERROR(INDEX(L$6:L$201,MATCH(ROW()-5,J$6:J$201,0)),"") -> CHANCHO (proceso) | C11: =IFERROR(INDEX(M$6:M$201,MATCH(ROW()-5,J$6:J$201,0)),"") | D11: =IFERROR(INDEX(N$6:N$201,MATCH(ROW()-5,J$6:J$201,0)),"") -> 190 | E11: =IFERROR(INDEX(O$6:O$201,MATCH(ROW()-5,J$6:J$201,0)),"") -> 2 sacos x 95 kg | F11: =IFERROR(INDEX(P$6:P$201,MATCH(ROW()-5,J$6:J$201,0)),"") -> 4008 | J11: =IF(OR(SUM(PROCESO!M12:M15)>0,SUM(PROCESO!N12:N15)>0),COUNT(J$6:J10)+1,"") | K11: =IF(OR(SUM(PROCESO!M12:M15)>0,SUM(PROCESO!N12:N15)>0),PROCESO!A12&IF(COUNTIF(PROCESO!$A$6:A11,PROCESO!A12)>0," (Ped."&(COUNTIF(PROCESO!$A$6:A11,PROCESO!A12)+1)&")",""),"") | L11: =IF(OR(SUM(PROCESO!M12:M15)>0,SUM(PROCESO!N12:N15)>0),"REPROCESO (devolución)","") | M11: =IF(OR(SUM(PROCESO!M12:M15)>0,SUM(PROCESO!N12:N15)>0),SUM(PROCESO!N12:N15),"") | N11: ="" | O11: =IF(OR(SUM(PROCESO!M12:M15)>0,SUM(PROCESO!N12:N15)>0),IF(SUM(PROCESO!M12:M15)>0,SUM(PROCESO!M12:M15)&" jabas devueltas · merma "&TEXT((PROCESO!M12*15+PROCESO!M13*18+PROCESO!M14*17+PROCESO!M15*17)-SUM(PROCESO!N12:N15),"+#,##0;-#,##0;0")&" kg",""),"") | P11: =P10+N(M11)-N(N11) -> 398
A12: =IFERROR(INDEX(K$6:K$201,MATCH(ROW()-5,J$6:J$201,0)),"") -> LUN 13-07 | B12: =IFERROR(INDEX(L$6:L$201,MATCH(ROW()-5,J$6:J$201,0)),"") -> ENVÍO Guía 2980 | C12: =IFERROR(INDEX(M$6:M$201,MATCH(ROW()-5,J$6:J$201,0)),"") | D12: =IFERROR(INDEX(N$6:N$201,MATCH(ROW()-5,J$6:J$201,0)),"") -> 3056 | E12: =IFERROR(INDEX(O$6:O$201,MATCH(ROW()-5,J$6:J$201,0)),"") -> G-2980 | F12: =IFERROR(INDEX(P$6:P$201,MATCH(ROW()-5,J$6:J$201,0)),"") -> 952 | J12: =IF(PROCESO!D18>0,COUNT(J$6:J11)+1,"") -> 5 | K12: =IF(PROCESO!D18>0,PROCESO!A18&IF(COUNTIF(PROCESO!$A$6:A17,PROCESO!A18)>0," (Ped."&(COUNTIF(PROCESO!$A$6:A17,PROCESO!A18)+1)&")",""),"") -> LUN 13-07 | L12: =IF(PROCESO!D18>0,"INGRESO (compra)","") -> INGRESO (compra) | M12: =IF(PROCESO!D18>0,PROCESO!D18,"") -> 3800 | N12: ="" | O12: =IF(PROCESO!D18>0,PROCESO!B18&" sacos x "&PROCESO!C18&" kg","") -> 40 sacos x 95 kg | P12: =P11+N(M12)-N(N12) -> 4198
A13: =IFERROR(INDEX(K$6:K$201,MATCH(ROW()-5,J$6:J$201,0)),"") -> MAR 14-07 | B13: =IFERROR(INDEX(L$6:L$201,MATCH(ROW()-5,J$6:J$201,0)),"") -> INGRESO (compra) | C13: =IFERROR(INDEX(M$6:M$201,MATCH(ROW()-5,J$6:J$201,0)),"") -> 3800 | D13: =IFERROR(INDEX(N$6:N$201,MATCH(ROW()-5,J$6:J$201,0)),"") | E13: =IFERROR(INDEX(O$6:O$201,MATCH(ROW()-5,J$6:J$201,0)),"") -> 40 sacos x 95 kg | F13: =IFERROR(INDEX(P$6:P$201,MATCH(ROW()-5,J$6:J$201,0)),"") -> 4752 | J13: =IF(N(PROCESO!H22)>0,COUNT(J$6:J12)+1,"") -> 6 | K13: =IF(N(PROCESO!H22)>0,PROCESO!A18&IF(COUNTIF(PROCESO!$A$6:A17,PROCESO!A18)>0," (Ped."&(COUNTIF(PROCESO!$A$6:A17,PROCESO!A18)+1)&")",""),"") -> LUN 13-07 | L13: =IF(N(PROCESO!H22)>0,"CHANCHO (proceso)","") -> CHANCHO (proceso) | M13: ="" | N13: =IF(N(PROCESO!H22)>0,N(PROCESO!H22),"") -> 190 | O13: =IF(N(PROCESO!H22)>0,PROCESO!G22&" sacos x 95 kg","") -> 2 sacos x 95 kg | P13: =P12+N(M13)-N(N13) -> 4008
A14: =IFERROR(INDEX(K$6:K$201,MATCH(ROW()-5,J$6:J$201,0)),"") -> MAR 14-07 | B14: =IFERROR(INDEX(L$6:L$201,MATCH(ROW()-5,J$6:J$201,0)),"") -> CHANCHO (proceso) | C14: =IFERROR(INDEX(M$6:M$201,MATCH(ROW()-5,J$6:J$201,0)),"") | D14: =IFERROR(INDEX(N$6:N$201,MATCH(ROW()-5,J$6:J$201,0)),"") -> 665 | E14: =IFERROR(INDEX(O$6:O$201,MATCH(ROW()-5,J$6:J$201,0)),"") -> 7 sacos x 95 kg | F14: =IFERROR(INDEX(P$6:P$201,MATCH(ROW()-5,J$6:J$201,0)),"") -> 4087 | J14: =IF(N(PROCESO!H23)>0,COUNT(J$6:J13)+1,"") | K14: =IF(N(PROCESO!H23)>0,PROCESO!A18&IF(COUNTIF(PROCESO!$A$6:A17,PROCESO!A18)>0," (Ped."&(COUNTIF(PROCESO!$A$6:A17,PROCESO!A18)+1)&")",""),"") | L14: =IF(N(PROCESO!H23)>0,"MALOGRADO","") | M14: ="" | N14: =IF(N(PROCESO!H23)>0,N(PROCESO!H23),"") | O14: ="" | P14: =P13+N(M14)-N(N14) -> 4008
A15: =IFERROR(INDEX(K$6:K$201,MATCH(ROW()-5,J$6:J$201,0)),"") -> MAR 14-07 | B15: =IFERROR(INDEX(L$6:L$201,MATCH(ROW()-5,J$6:J$201,0)),"") -> ENVÍO Guía 2984 | C15: =IFERROR(INDEX(M$6:M$201,MATCH(ROW()-5,J$6:J$201,0)),"") | D15: =IFERROR(INDEX(N$6:N$201,MATCH(ROW()-5,J$6:J$201,0)),"") -> 3379 | E15: =IFERROR(INDEX(O$6:O$201,MATCH(ROW()-5,J$6:J$201,0)),"") -> G-2984 | F15: =IFERROR(INDEX(P$6:P$201,MATCH(ROW()-5,J$6:J$201,0)),"") -> 708 | J15: =IF(IF(PROCESO!J18<>"",PROCESO!J18,IF(PROCESO!J19<>"",PROCESO!J19,IF(PROCESO!J20<>"",PROCESO!J20,IF(PROCESO!J21<>"",PROCESO!J21,""))))<>"",COUNT(J$6:J14)+1,"") -> 7 | K15: =IF(IF(PROCESO!J18<>"",PROCESO!J18,IF(PROCESO!J19<>"",PROCESO!J19,IF(PROCESO!J20<>"",PROCESO!J20,IF(PROCESO!J21<>"",PROCESO!J21,""))))<>"",PROCESO!A18&IF(COUNTIF(PROCESO!$A$6:A17,PROCESO!A18)>0," (Ped."&(COUNTIF(PROCESO!$A$6:A17,PROCESO!A18)+1)&")",""),"") -> LUN 13-07 | L15: =IF(IF(PROCESO!J18<>"",PROCESO!J18,IF(PROCESO!J19<>"",PROCESO!J19,IF(PROCESO!J20<>"",PROCESO!J20,IF(PROCESO!J21<>"",PROCESO!J21,""))))<>"","ENVÍO Guía "&IF(LEFT(IF(PROCESO!J18<>"",PROCESO!J18,IF(PROCESO!J19<>"",PROCESO!J19,IF(PROCESO!J20<>"",PROCESO!J20,IF(PROCESO!J21<>"",PROCESO!J21,"")))),2)="G-",MID(IF(PROCESO!J18<>"",PROCESO!J18,IF(PROCESO!J19<>"",PROCESO!J19,IF(PROCESO!J20<>"",PROCESO!J20,IF(PROCESO!J21<>"",PROCESO!J21,"")))),3,99),IF(PROCESO!J18<>"",PROCESO!J18,IF(PROCESO!J19<>"",PROCESO!J19,IF(PROCESO!J20<>"",PROCESO!J20,IF(PROCESO!J21<>"",PROCESO!J21,""))))),"") -> ENVÍO Guía 2980 | M15: ="" | N15: =IF(IF(PROCESO!J18<>"",PROCESO!J18,IF(PROCESO!J19<>"",PROCESO!J19,IF(PROCESO!J20<>"",PROCESO!J20,IF(PROCESO!J21<>"",PROCESO!J21,""))))<>"",SUMIF(PROCESO!J18:J21,IF(PROCESO!J18<>"",PROCESO!J18,IF(PROCESO!J19<>"",PROCESO!J19,IF(PROCESO!J20<>"",PROCESO!J20,IF(PROCESO!J21<>"",PROCESO!J21,"")))),PROCESO!L18:L21),"") -> 3056 | O15: =IF(IF(PROCESO!J18<>"",PROCESO!J18,IF(PROCESO!J19<>"",PROCESO!J19,IF(PROCESO!J20<>"",PROCESO!J20,IF(PROCESO!J21<>"",PROCESO!J21,""))))<>"","G-"&IF(LEFT(IF(PROCESO!J18<>"",PROCESO!J18,IF(PROCESO!J19<>"",PROCESO!J19,IF(PROCESO!J20<>"",PROCESO!J20,IF(PROCESO!J21<>"",PROCESO!J21,"")))),2)="G-",MID(IF(PROCESO!J18<>"",PROCESO!J18,IF(PROCESO!J19<>"",PROCESO!J19,IF(PROCESO!J20<>"",PROCESO!J20,IF(PROCESO!J21<>"",PROCESO!J21,"")))),3,99),IF(PROCESO!J18<>"",PROCESO!J18,IF(PROCESO!J19<>"",PROCESO!J19,IF(PROCESO!J20<>"",PROCESO!J20,IF(PROCESO!J21<>"",PROCESO!J21,""))))),"") -> G-2980 | P15: =P14+N(M15)-N(N15) -> 952
A16: =IFERROR(INDEX(K$6:K$201,MATCH(ROW()-5,J$6:J$201,0)),"") -> MIE 15-07 | B16: =IFERROR(INDEX(L$6:L$201,MATCH(ROW()-5,J$6:J$201,0)),"") -> INGRESO (compra) | C16: =IFERROR(INDEX(M$6:M$201,MATCH(ROW()-5,J$6:J$201,0)),"") -> 3800 | D16: =IFERROR(INDEX(N$6:N$201,MATCH(ROW()-5,J$6:J$201,0)),"") | E16: =IFERROR(INDEX(O$6:O$201,MATCH(ROW()-5,J$6:J$201,0)),"") -> 40 sacos x 95 kg | F16: =IFERROR(INDEX(P$6:P$201,MATCH(ROW()-5,J$6:J$201,0)),"") -> 4508 | J16: =IF(OR(SUM(PROCESO!M18:M21)>0,SUM(PROCESO!N18:N21)>0),COUNT(J$6:J15)+1,"") | K16: =IF(OR(SUM(PROCESO!M18:M21)>0,SUM(PROCESO!N18:N21)>0),PROCESO!A18&IF(COUNTIF(PROCESO!$A$6:A17,PROCESO!A18)>0," (Ped."&(COUNTIF(PROCESO!$A$6:A17,PROCESO!A18)+1)&")",""),"") | L16: =IF(OR(SUM(PROCESO!M18:M21)>0,SUM(PROCESO!N18:N21)>0),"REPROCESO (devolución)","") | M16: =IF(OR(SUM(PROCESO!M18:M21)>0,SUM(PROCESO!N18:N21)>0),SUM(PROCESO!N18:N21),"") | N16: ="" | O16: =IF(OR(SUM(PROCESO!M18:M21)>0,SUM(PROCESO!N18:N21)>0),IF(SUM(PROCESO!M18:M21)>0,SUM(PROCESO!M18:M21)&" jabas devueltas · merma "&TEXT((PROCESO!M18*15+PROCESO!M19*18+PROCESO!M20*17+PROCESO!M21*17)-SUM(PROCESO!N18:N21),"+#,##0;-#,##0;0")&" kg",""),"") | P16: =P15+N(M16)-N(N16) -> 952
A17: =IFERROR(INDEX(K$6:K$201,MATCH(ROW()-5,J$6:J$201,0)),"") -> MIE 15-07 | B17: =IFERROR(INDEX(L$6:L$201,MATCH(ROW()-5,J$6:J$201,0)),"") -> CHANCHO (proceso) | C17: =IFERROR(INDEX(M$6:M$201,MATCH(ROW()-5,J$6:J$201,0)),"") | D17: =IFERROR(INDEX(N$6:N$201,MATCH(ROW()-5,J$6:J$201,0)),"") -> 475 | E17: =IFERROR(INDEX(O$6:O$201,MATCH(ROW()-5,J$6:J$201,0)),"") -> 5 sacos x 95 kg | F17: =IFERROR(INDEX(P$6:P$201,MATCH(ROW()-5,J$6:J$201,0)),"") -> 4033 | J17: =IF(PROCESO!D24>0,COUNT(J$6:J16)+1,"") -> 8 | K17: =IF(PROCESO!D24>0,PROCESO!A24&IF(COUNTIF(PROCESO!$A$6:A23,PROCESO!A24)>0," (Ped."&(COUNTIF(PROCESO!$A$6:A23,PROCESO!A24)+1)&")",""),"") -> MAR 14-07 | L17: =IF(PROCESO!D24>0,"INGRESO (compra)","") -> INGRESO (compra) | M17: =IF(PROCESO!D24>0,PROCESO!D24,"") -> 3800 | N17: ="" | O17: =IF(PROCESO!D24>0,PROCESO!B24&" sacos x "&PROCESO!C24&" kg","") -> 40 sacos x 95 kg | P17: =P16+N(M17)-N(N17) -> 4752
A18: =IFERROR(INDEX(K$6:K$201,MATCH(ROW()-5,J$6:J$201,0)),"") -> MIE 15-07 | B18: =IFERROR(INDEX(L$6:L$201,MATCH(ROW()-5,J$6:J$201,0)),"") -> ENVÍO Guía 2986 | C18: =IFERROR(INDEX(M$6:M$201,MATCH(ROW()-5,J$6:J$201,0)),"") | D18: =IFERROR(INDEX(N$6:N$201,MATCH(ROW()-5,J$6:J$201,0)),"") -> 2971 | E18: =IFERROR(INDEX(O$6:O$201,MATCH(ROW()-5,J$6:J$201,0)),"") -> G-2986 | F18: =IFERROR(INDEX(P$6:P$201,MATCH(ROW()-5,J$6:J$201,0)),"") -> 1062 | J18: =IF(N(PROCESO!H28)>0,COUNT(J$6:J17)+1,"") -> 9 | K18: =IF(N(PROCESO!H28)>0,PROCESO!A24&IF(COUNTIF(PROCESO!$A$6:A23,PROCESO!A24)>0," (Ped."&(COUNTIF(PROCESO!$A$6:A23,PROCESO!A24)+1)&")",""),"") -> MAR 14-07 | L18: =IF(N(PROCESO!H28)>0,"CHANCHO (proceso)","") -> CHANCHO (proceso) | M18: ="" | N18: =IF(N(PROCESO!H28)>0,N(PROCESO!H28),"") -> 665 | O18: =IF(N(PROCESO!H28)>0,PROCESO!G28&" sacos x 95 kg","") -> 7 sacos x 95 kg | P18: =P17+N(M18)-N(N18) -> 4087
A19: =IFERROR(INDEX(K$6:K$201,MATCH(ROW()-5,J$6:J$201,0)),"") -> JUE 16-07 | B19: =IFERROR(INDEX(L$6:L$201,MATCH(ROW()-5,J$6:J$201,0)),"") -> INGRESO (compra) | C19: =IFERROR(INDEX(M$6:M$201,MATCH(ROW()-5,J$6:J$201,0)),"") -> 3800 | D19: =IFERROR(INDEX(N$6:N$201,MATCH(ROW()-5,J$6:J$201,0)),"") | E19: =IFERROR(INDEX(O$6:O$201,MATCH(ROW()-5,J$6:J$201,0)),"") -> 40 sacos x 95 kg | F19: =IFERROR(INDEX(P$6:P$201,MATCH(ROW()-5,J$6:J$201,0)),"") -> 4862 | J19: =IF(N(PROCESO!H29)>0,COUNT(J$6:J18)+1,"") | K19: =IF(N(PROCESO!H29)>0,PROCESO!A24&IF(COUNTIF(PROCESO!$A$6:A23,PROCESO!A24)>0," (Ped."&(COUNTIF(PROCESO!$A$6:A23,PROCESO!A24)+1)&")",""),"") | L19: =IF(N(PROCESO!H29)>0,"MALOGRADO","") | M19: ="" | N19: =IF(N(PROCESO!H29)>0,N(PROCESO!H29),"") | O19: ="" | P19: =P18+N(M19)-N(N19) -> 4087
A20: =IFERROR(INDEX(K$6:K$201,MATCH(ROW()-5,J$6:J$201,0)),"") -> JUE 16-07 | B20: =IFERROR(INDEX(L$6:L$201,MATCH(ROW()-5,J$6:J$201,0)),"") -> CHANCHO (proceso) | C20: =IFERROR(INDEX(M$6:M$201,MATCH(ROW()-5,J$6:J$201,0)),"") | D20: =IFERROR(INDEX(N$6:N$201,MATCH(ROW()-5,J$6:J$201,0)),"") -> 380 | E20: =IFERROR(INDEX(O$6:O$201,MATCH(ROW()-5,J$6:J$201,0)),"") -> 4 sacos x 95 kg | F20: =IFERROR(INDEX(P$6:P$201,MATCH(ROW()-5,J$6:J$201,0)),"") -> 4482 | J20: =IF(IF(PROCESO!J24<>"",PROCESO!J24,IF(PROCESO!J25<>"",PROCESO!J25,IF(PROCESO!J26<>"",PROCESO!J26,IF(PROCESO!J27<>"",PROCESO!J27,""))))<>"",COUNT(J$6:J19)+1,"") -> 10 | K20: =IF(IF(PROCESO!J24<>"",PROCESO!J24,IF(PROCESO!J25<>"",PROCESO!J25,IF(PROCESO!J26<>"",PROCESO!J26,IF(PROCESO!J27<>"",PROCESO!J27,""))))<>"",PROCESO!A24&IF(COUNTIF(PROCESO!$A$6:A23,PROCESO!A24)>0," (Ped."&(COUNTIF(PROCESO!$A$6:A23,PROCESO!A24)+1)&")",""),"") -> MAR 14-07 | L20: =IF(IF(PROCESO!J24<>"",PROCESO!J24,IF(PROCESO!J25<>"",PROCESO!J25,IF(PROCESO!J26<>"",PROCESO!J26,IF(PROCESO!J27<>"",PROCESO!J27,""))))<>"","ENVÍO Guía "&IF(LEFT(IF(PROCESO!J24<>"",PROCESO!J24,IF(PROCESO!J25<>"",PROCESO!J25,IF(PROCESO!J26<>"",PROCESO!J26,IF(PROCESO!J27<>"",PROCESO!J27,"")))),2)="G-",MID(IF(PROCESO!J24<>"",PROCESO!J24,IF(PROCESO!J25<>"",PROCESO!J25,IF(PROCESO!J26<>"",PROCESO!J26,IF(PROCESO!J27<>"",PROCESO!J27,"")))),3,99),IF(PROCESO!J24<>"",PROCESO!J24,IF(PROCESO!J25<>"",PROCESO!J25,IF(PROCESO!J26<>"",PROCESO!J26,IF(PROCESO!J27<>"",PROCESO!J27,""))))),"") -> ENVÍO Guía 2984 | M20: ="" | N20: =IF(IF(PROCESO!J24<>"",PROCESO!J24,IF(PROCESO!J25<>"",PROCESO!J25,IF(PROCESO!J26<>"",PROCESO!J26,IF(PROCESO!J27<>"",PROCESO!J27,""))))<>"",SUMIF(PROCESO!J24:J27,IF(PROCESO!J24<>"",PROCESO!J24,IF(PROCESO!J25<>"",PROCESO!J25,IF(PROCESO!J26<>"",PROCESO!J26,IF(PROCESO!J27<>"",PROCESO!J27,"")))),PROCESO!L24:L27),"") -> 3379 | O20: =IF(IF(PROCESO!J24<>"",PROCESO!J24,IF(PROCESO!J25<>"",PROCESO!J25,IF(PROCESO!J26<>"",PROCESO!J26,IF(PROCESO!J27<>"",PROCESO!J27,""))))<>"","G-"&IF(LEFT(IF(PROCESO!J24<>"",PROCESO!J24,IF(PROCESO!J25<>"",PROCESO!J25,IF(PROCESO!J26<>"",PROCESO!J26,IF(PROCESO!J27<>"",PROCESO!J27,"")))),2)="G-",MID(IF(PROCESO!J24<>"",PROCESO!J24,IF(PROCESO!J25<>"",PROCESO!J25,IF(PROCESO!J26<>"",PROCESO!J26,IF(PROCESO!J27<>"",PROCESO!J27,"")))),3,99),IF(PROCESO!J24<>"",PROCESO!J24,IF(PROCESO!J25<>"",PROCESO!J25,IF(PROCESO!J26<>"",PROCESO!J26,IF(PROCESO!J27<>"",PROCESO!J27,""))))),"") -> G-2984 | P20: =P19+N(M20)-N(N20) -> 708
A21: =IFERROR(INDEX(K$6:K$201,MATCH(ROW()-5,J$6:J$201,0)),"") -> JUE 16-07 | B21: =IFERROR(INDEX(L$6:L$201,MATCH(ROW()-5,J$6:J$201,0)),"") -> ENVÍO Guía 2992 | C21: =IFERROR(INDEX(M$6:M$201,MATCH(ROW()-5,J$6:J$201,0)),"") | D21: =IFERROR(INDEX(N$6:N$201,MATCH(ROW()-5,J$6:J$201,0)),"") -> 3302 | E21: =IFERROR(INDEX(O$6:O$201,MATCH(ROW()-5,J$6:J$201,0)),"") -> G-2992 | F21: =IFERROR(INDEX(P$6:P$201,MATCH(ROW()-5,J$6:J$201,0)),"") -> 1180 | J21: =IF(OR(SUM(PROCESO!M24:M27)>0,SUM(PROCESO!N24:N27)>0),COUNT(J$6:J20)+1,"") | K21: =IF(OR(SUM(PROCESO!M24:M27)>0,SUM(PROCESO!N24:N27)>0),PROCESO!A24&IF(COUNTIF(PROCESO!$A$6:A23,PROCESO!A24)>0," (Ped."&(COUNTIF(PROCESO!$A$6:A23,PROCESO!A24)+1)&")",""),"") | L21: =IF(OR(SUM(PROCESO!M24:M27)>0,SUM(PROCESO!N24:N27)>0),"REPROCESO (devolución)","") | M21: =IF(OR(SUM(PROCESO!M24:M27)>0,SUM(PROCESO!N24:N27)>0),SUM(PROCESO!N24:N27),"") | N21: ="" | O21: =IF(OR(SUM(PROCESO!M24:M27)>0,SUM(PROCESO!N24:N27)>0),IF(SUM(PROCESO!M24:M27)>0,SUM(PROCESO!M24:M27)&" jabas devueltas · merma "&TEXT((PROCESO!M24*15+PROCESO!M25*18+PROCESO!M26*17+PROCESO!M27*17)-SUM(PROCESO!N24:N27),"+#,##0;-#,##0;0")&" kg",""),"") | P21: =P20+N(M21)-N(N21) -> 708
A22: =IFERROR(INDEX(K$6:K$201,MATCH(ROW()-5,J$6:J$201,0)),"") -> VIE 17-07 | B22: =IFERROR(INDEX(L$6:L$201,MATCH(ROW()-5,J$6:J$201,0)),"") -> INGRESO (compra) | C22: =IFERROR(INDEX(M$6:M$201,MATCH(ROW()-5,J$6:J$201,0)),"") -> 5700 | D22: =IFERROR(INDEX(N$6:N$201,MATCH(ROW()-5,J$6:J$201,0)),"") | E22: =IFERROR(INDEX(O$6:O$201,MATCH(ROW()-5,J$6:J$201,0)),"") -> 60 sacos x 95 kg | F22: =IFERROR(INDEX(P$6:P$201,MATCH(ROW()-5,J$6:J$201,0)),"") -> 6880 | J22: =IF(PROCESO!D30>0,COUNT(J$6:J21)+1,"") -> 11 | K22: =IF(PROCESO!D30>0,PROCESO!A30&IF(COUNTIF(PROCESO!$A$6:A29,PROCESO!A30)>0," (Ped."&(COUNTIF(PROCESO!$A$6:A29,PROCESO!A30)+1)&")",""),"") -> MIE 15-07 | L22: =IF(PROCESO!D30>0,"INGRESO (compra)","") -> INGRESO (compra) | M22: =IF(PROCESO!D30>0,PROCESO!D30,"") -> 3800 | N22: ="" | O22: =IF(PROCESO!D30>0,PROCESO!B30&" sacos x "&PROCESO!C30&" kg","") -> 40 sacos x 95 kg | P22: =P21+N(M22)-N(N22) -> 4508
A23: =IFERROR(INDEX(K$6:K$201,MATCH(ROW()-5,J$6:J$201,0)),"") -> VIE 17-07 | B23: =IFERROR(INDEX(L$6:L$201,MATCH(ROW()-5,J$6:J$201,0)),"") -> CHANCHO (proceso) | C23: =IFERROR(INDEX(M$6:M$201,MATCH(ROW()-5,J$6:J$201,0)),"") | D23: =IFERROR(INDEX(N$6:N$201,MATCH(ROW()-5,J$6:J$201,0)),"") -> 950 | E23: =IFERROR(INDEX(O$6:O$201,MATCH(ROW()-5,J$6:J$201,0)),"") -> 10 sacos x 95 kg | F23: =IFERROR(INDEX(P$6:P$201,MATCH(ROW()-5,J$6:J$201,0)),"") -> 5930 | J23: =IF(N(PROCESO!H34)>0,COUNT(J$6:J22)+1,"") -> 12 | K23: =IF(N(PROCESO!H34)>0,PROCESO!A30&IF(COUNTIF(PROCESO!$A$6:A29,PROCESO!A30)>0," (Ped."&(COUNTIF(PROCESO!$A$6:A29,PROCESO!A30)+1)&")",""),"") -> MIE 15-07 | L23: =IF(N(PROCESO!H34)>0,"CHANCHO (proceso)","") -> CHANCHO (proceso) | M23: ="" | N23: =IF(N(PROCESO!H34)>0,N(PROCESO!H34),"") -> 475 | O23: =IF(N(PROCESO!H34)>0,PROCESO!G34&" sacos x 95 kg","") -> 5 sacos x 95 kg | P23: =P22+N(M23)-N(N23) -> 4033
A24: =IFERROR(INDEX(K$6:K$201,MATCH(ROW()-5,J$6:J$201,0)),"") -> VIE 17-07 | B24: =IFERROR(INDEX(L$6:L$201,MATCH(ROW()-5,J$6:J$201,0)),"") -> ENVÍO Guía 2994 | C24: =IFERROR(INDEX(M$6:M$201,MATCH(ROW()-5,J$6:J$201,0)),"") | D24: =IFERROR(INDEX(N$6:N$201,MATCH(ROW()-5,J$6:J$201,0)),"") -> 3413 | E24: =IFERROR(INDEX(O$6:O$201,MATCH(ROW()-5,J$6:J$201,0)),"") -> G-2994 | F24: =IFERROR(INDEX(P$6:P$201,MATCH(ROW()-5,J$6:J$201,0)),"") -> 2517 | J24: =IF(N(PROCESO!H35)>0,COUNT(J$6:J23)+1,"") | K24: =IF(N(PROCESO!H35)>0,PROCESO!A30&IF(COUNTIF(PROCESO!$A$6:A29,PROCESO!A30)>0," (Ped."&(COUNTIF(PROCESO!$A$6:A29,PROCESO!A30)+1)&")",""),"") | L24: =IF(N(PROCESO!H35)>0,"MALOGRADO","") | M24: ="" | N24: =IF(N(PROCESO!H35)>0,N(PROCESO!H35),"") | O24: ="" | P24: =P23+N(M24)-N(N24) -> 4033
A25: =IFERROR(INDEX(K$6:K$201,MATCH(ROW()-5,J$6:J$201,0)),"") -> VIE 17-07 (Ped.2) | B25: =IFERROR(INDEX(L$6:L$201,MATCH(ROW()-5,J$6:J$201,0)),"") -> INGRESO (compra) | C25: =IFERROR(INDEX(M$6:M$201,MATCH(ROW()-5,J$6:J$201,0)),"") -> 475 | D25: =IFERROR(INDEX(N$6:N$201,MATCH(ROW()-5,J$6:J$201,0)),"") | E25: =IFERROR(INDEX(O$6:O$201,MATCH(ROW()-5,J$6:J$201,0)),"") -> 5 sacos x 95 kg | F25: =IFERROR(INDEX(P$6:P$201,MATCH(ROW()-5,J$6:J$201,0)),"") -> 2992 | J25: =IF(IF(PROCESO!J30<>"",PROCESO!J30,IF(PROCESO!J31<>"",PROCESO!J31,IF(PROCESO!J32<>"",PROCESO!J32,IF(PROCESO!J33<>"",PROCESO!J33,""))))<>"",COUNT(J$6:J24)+1,"") -> 13 | K25: =IF(IF(PROCESO!J30<>"",PROCESO!J30,IF(PROCESO!J31<>"",PROCESO!J31,IF(PROCESO!J32<>"",PROCESO!J32,IF(PROCESO!J33<>"",PROCESO!J33,""))))<>"",PROCESO!A30&IF(COUNTIF(PROCESO!$A$6:A29,PROCESO!A30)>0," (Ped."&(COUNTIF(PROCESO!$A$6:A29,PROCESO!A30)+1)&")",""),"") -> MIE 15-07 | L25: =IF(IF(PROCESO!J30<>"",PROCESO!J30,IF(PROCESO!J31<>"",PROCESO!J31,IF(PROCESO!J32<>"",PROCESO!J32,IF(PROCESO!J33<>"",PROCESO!J33,""))))<>"","ENVÍO Guía "&IF(LEFT(IF(PROCESO!J30<>"",PROCESO!J30,IF(PROCESO!J31<>"",PROCESO!J31,IF(PROCESO!J32<>"",PROCESO!J32,IF(PROCESO!J33<>"",PROCESO!J33,"")))),2)="G-",MID(IF(PROCESO!J30<>"",PROCESO!J30,IF(PROCESO!J31<>"",PROCESO!J31,IF(PROCESO!J32<>"",PROCESO!J32,IF(PROCESO!J33<>"",PROCESO!J33,"")))),3,99),IF(PROCESO!J30<>"",PROCESO!J30,IF(PROCESO!J31<>"",PROCESO!J31,IF(PROCESO!J32<>"",PROCESO!J32,IF(PROCESO!J33<>"",PROCESO!J33,""))))),"") -> ENVÍO Guía 2986 | M25: ="" | N25: =IF(IF(PROCESO!J30<>"",PROCESO!J30,IF(PROCESO!J31<>"",PROCESO!J31,IF(PROCESO!J32<>"",PROCESO!J32,IF(PROCESO!J33<>"",PROCESO!J33,""))))<>"",SUMIF(PROCESO!J30:J33,IF(PROCESO!J30<>"",PROCESO!J30,IF(PROCESO!J31<>"",PROCESO!J31,IF(PROCESO!J32<>"",PROCESO!J32,IF(PROCESO!J33<>"",PROCESO!J33,"")))),PROCESO!L30:L33),"") -> 2971 | O25: =IF(IF(PROCESO!J30<>"",PROCESO!J30,IF(PROCESO!J31<>"",PROCESO!J31,IF(PROCESO!J32<>"",PROCESO!J32,IF(PROCESO!J33<>"",PROCESO!J33,""))))<>"","G-"&IF(LEFT(IF(PROCESO!J30<>"",PROCESO!J30,IF(PROCESO!J31<>"",PROCESO!J31,IF(PROCESO!J32<>"",PROCESO!J32,IF(PROCESO!J33<>"",PROCESO!J33,"")))),2)="G-",MID(IF(PROCESO!J30<>"",PROCESO!J30,IF(PROCESO!J31<>"",PROCESO!J31,IF(PROCESO!J32<>"",PROCESO!J32,IF(PROCESO!J33<>"",PROCESO!J33,"")))),3,99),IF(PROCESO!J30<>"",PROCESO!J30,IF(PROCESO!J31<>"",PROCESO!J31,IF(PROCESO!J32<>"",PROCESO!J32,IF(PROCESO!J33<>"",PROCESO!J33,""))))),"") -> G-2986 | P25: =P24+N(M25)-N(N25) -> 1062
A26: =IFERROR(INDEX(K$6:K$201,MATCH(ROW()-5,J$6:J$201,0)),"") -> VIE 17-07 (Ped.2) | B26: =IFERROR(INDEX(L$6:L$201,MATCH(ROW()-5,J$6:J$201,0)),"") -> CHANCHO (proceso) | C26: =IFERROR(INDEX(M$6:M$201,MATCH(ROW()-5,J$6:J$201,0)),"") | D26: =IFERROR(INDEX(N$6:N$201,MATCH(ROW()-5,J$6:J$201,0)),"") -> 95 | E26: =IFERROR(INDEX(O$6:O$201,MATCH(ROW()-5,J$6:J$201,0)),"") -> 1 sacos x 95 kg | F26: =IFERROR(INDEX(P$6:P$201,MATCH(ROW()-5,J$6:J$201,0)),"") -> 2897 | J26: =IF(OR(SUM(PROCESO!M30:M33)>0,SUM(PROCESO!N30:N33)>0),COUNT(J$6:J25)+1,"") | K26: =IF(OR(SUM(PROCESO!M30:M33)>0,SUM(PROCESO!N30:N33)>0),PROCESO!A30&IF(COUNTIF(PROCESO!$A$6:A29,PROCESO!A30)>0," (Ped."&(COUNTIF(PROCESO!$A$6:A29,PROCESO!A30)+1)&")",""),"") | L26: =IF(OR(SUM(PROCESO!M30:M33)>0,SUM(PROCESO!N30:N33)>0),"REPROCESO (devolución)","") | M26: =IF(OR(SUM(PROCESO!M30:M33)>0,SUM(PROCESO!N30:N33)>0),SUM(PROCESO!N30:N33),"") | N26: ="" | O26: =IF(OR(SUM(PROCESO!M30:M33)>0,SUM(PROCESO!N30:N33)>0),IF(SUM(PROCESO!M30:M33)>0,SUM(PROCESO!M30:M33)&" jabas devueltas · merma "&TEXT((PROCESO!M30*15+PROCESO!M31*18+PROCESO!M32*17+PROCESO!M33*17)-SUM(PROCESO!N30:N33),"+#,##0;-#,##0;0")&" kg",""),"") | P26: =P25+N(M26)-N(N26) -> 1062
A27: =IFERROR(INDEX(K$6:K$201,MATCH(ROW()-5,J$6:J$201,0)),"") -> SAB 18-07 | B27: =IFERROR(INDEX(L$6:L$201,MATCH(ROW()-5,J$6:J$201,0)),"") -> ENVÍO Guía 2996 | C27: =IFERROR(INDEX(M$6:M$201,MATCH(ROW()-5,J$6:J$201,0)),"") | D27: =IFERROR(INDEX(N$6:N$201,MATCH(ROW()-5,J$6:J$201,0)),"") -> 3168 | E27: =IFERROR(INDEX(O$6:O$201,MATCH(ROW()-5,J$6:J$201,0)),"") -> G-2996 | F27: =IFERROR(INDEX(P$6:P$201,MATCH(ROW()-5,J$6:J$201,0)),"") -> -271 | J27: =IF(PROCESO!D36>0,COUNT(J$6:J26)+1,"") -> 14 | K27: =IF(PROCESO!D36>0,PROCESO!A36&IF(COUNTIF(PROCESO!$A$6:A35,PROCESO!A36)>0," (Ped."&(COUNTIF(PROCESO!$A$6:A35,PROCESO!A36)+1)&")",""),"") -> JUE 16-07 | L27: =IF(PROCESO!D36>0,"INGRESO (compra)","") -> INGRESO (compra) | M27: =IF(PROCESO!D36>0,PROCESO!D36,"") -> 3800 | N27: ="" | O27: =IF(PROCESO!D36>0,PROCESO!B36&" sacos x "&PROCESO!C36&" kg","") -> 40 sacos x 95 kg | P27: =P26+N(M27)-N(N27) -> 4862
A28: =IFERROR(INDEX(K$6:K$201,MATCH(ROW()-5,J$6:J$201,0)),"") -> DOM 19-07 | B28: =IFERROR(INDEX(L$6:L$201,MATCH(ROW()-5,J$6:J$201,0)),"") -> INGRESO (compra) | C28: =IFERROR(INDEX(M$6:M$201,MATCH(ROW()-5,J$6:J$201,0)),"") -> 4750 | D28: =IFERROR(INDEX(N$6:N$201,MATCH(ROW()-5,J$6:J$201,0)),"") | E28: =IFERROR(INDEX(O$6:O$201,MATCH(ROW()-5,J$6:J$201,0)),"") -> 50 sacos x 95 kg | F28: =IFERROR(INDEX(P$6:P$201,MATCH(ROW()-5,J$6:J$201,0)),"") -> 4479 | J28: =IF(N(PROCESO!H40)>0,COUNT(J$6:J27)+1,"") -> 15 | K28: =IF(N(PROCESO!H40)>0,PROCESO!A36&IF(COUNTIF(PROCESO!$A$6:A35,PROCESO!A36)>0," (Ped."&(COUNTIF(PROCESO!$A$6:A35,PROCESO!A36)+1)&")",""),"") -> JUE 16-07 | L28: =IF(N(PROCESO!H40)>0,"CHANCHO (proceso)","") -> CHANCHO (proceso) | M28: ="" | N28: =IF(N(PROCESO!H40)>0,N(PROCESO!H40),"") -> 380 | O28: =IF(N(PROCESO!H40)>0,PROCESO!G40&" sacos x 95 kg","") -> 4 sacos x 95 kg | P28: =P27+N(M28)-N(N28) -> 4482
A29: =IFERROR(INDEX(K$6:K$201,MATCH(ROW()-5,J$6:J$201,0)),"") -> DOM 19-07 | B29: =IFERROR(INDEX(L$6:L$201,MATCH(ROW()-5,J$6:J$201,0)),"") -> CHANCHO (proceso) | C29: =IFERROR(INDEX(M$6:M$201,MATCH(ROW()-5,J$6:J$201,0)),"") | D29: =IFERROR(INDEX(N$6:N$201,MATCH(ROW()-5,J$6:J$201,0)),"") -> 1282.5 | E29: =IFERROR(INDEX(O$6:O$201,MATCH(ROW()-5,J$6:J$201,0)),"") -> 13.5 sacos x 95 kg | F29: =IFERROR(INDEX(P$6:P$201,MATCH(ROW()-5,J$6:J$201,0)),"") -> 3196.5 | J29: =IF(N(PROCESO!H41)>0,COUNT(J$6:J28)+1,"") | K29: =IF(N(PROCESO!H41)>0,PROCESO!A36&IF(COUNTIF(PROCESO!$A$6:A35,PROCESO!A36)>0," (Ped."&(COUNTIF(PROCESO!$A$6:A35,PROCESO!A36)+1)&")",""),"") | L29: =IF(N(PROCESO!H41)>0,"MALOGRADO","") | M29: ="" | N29: =IF(N(PROCESO!H41)>0,N(PROCESO!H41),"") | O29: ="" | P29: =P28+N(M29)-N(N29) -> 4482
A30: =IFERROR(INDEX(K$6:K$201,MATCH(ROW()-5,J$6:J$201,0)),"") -> DOM 19-07 | B30: =IFERROR(INDEX(L$6:L$201,MATCH(ROW()-5,J$6:J$201,0)),"") -> ENVÍO Guía 2998 | C30: =IFERROR(INDEX(M$6:M$201,MATCH(ROW()-5,J$6:J$201,0)),"") | D30: =IFERROR(INDEX(N$6:N$201,MATCH(ROW()-5,J$6:J$201,0)),"") -> 1883 | E30: =IFERROR(INDEX(O$6:O$201,MATCH(ROW()-5,J$6:J$201,0)),"") -> G-2998 | F30: =IFERROR(INDEX(P$6:P$201,MATCH(ROW()-5,J$6:J$201,0)),"") -> 1313.5 | J30: =IF(IF(PROCESO!J36<>"",PROCESO!J36,IF(PROCESO!J37<>"",PROCESO!J37,IF(PROCESO!J38<>"",PROCESO!J38,IF(PROCESO!J39<>"",PROCESO!J39,""))))<>"",COUNT(J$6:J29)+1,"") -> 16 | K30: =IF(IF(PROCESO!J36<>"",PROCESO!J36,IF(PROCESO!J37<>"",PROCESO!J37,IF(PROCESO!J38<>"",PROCESO!J38,IF(PROCESO!J39<>"",PROCESO!J39,""))))<>"",PROCESO!A36&IF(COUNTIF(PROCESO!$A$6:A35,PROCESO!A36)>0," (Ped."&(COUNTIF(PROCESO!$A$6:A35,PROCESO!A36)+1)&")",""),"") -> JUE 16-07 | L30: =IF(IF(PROCESO!J36<>"",PROCESO!J36,IF(PROCESO!J37<>"",PROCESO!J37,IF(PROCESO!J38<>"",PROCESO!J38,IF(PROCESO!J39<>"",PROCESO!J39,""))))<>"","ENVÍO Guía "&IF(LEFT(IF(PROCESO!J36<>"",PROCESO!J36,IF(PROCESO!J37<>"",PROCESO!J37,IF(PROCESO!J38<>"",PROCESO!J38,IF(PROCESO!J39<>"",PROCESO!J39,"")))),2)="G-",MID(IF(PROCESO!J36<>"",PROCESO!J36,IF(PROCESO!J37<>"",PROCESO!J37,IF(PROCESO!J38<>"",PROCESO!J38,IF(PROCESO!J39<>"",PROCESO!J39,"")))),3,99),IF(PROCESO!J36<>"",PROCESO!J36,IF(PROCESO!J37<>"",PROCESO!J37,IF(PROCESO!J38<>"",PROCESO!J38,IF(PROCESO!J39<>"",PROCESO!J39,""))))),"") -> ENVÍO Guía 2992 | M30: ="" | N30: =IF(IF(PROCESO!J36<>"",PROCESO!J36,IF(PROCESO!J37<>"",PROCESO!J37,IF(PROCESO!J38<>"",PROCESO!J38,IF(PROCESO!J39<>"",PROCESO!J39,""))))<>"",SUMIF(PROCESO!J36:J39,IF(PROCESO!J36<>"",PROCESO!J36,IF(PROCESO!J37<>"",PROCESO!J37,IF(PROCESO!J38<>"",PROCESO!J38,IF(PROCESO!J39<>"",PROCESO!J39,"")))),PROCESO!L36:L39),"") -> 3302 | O30: =IF(IF(PROCESO!J36<>"",PROCESO!J36,IF(PROCESO!J37<>"",PROCESO!J37,IF(PROCESO!J38<>"",PROCESO!J38,IF(PROCESO!J39<>"",PROCESO!J39,""))))<>"","G-"&IF(LEFT(IF(PROCESO!J36<>"",PROCESO!J36,IF(PROCESO!J37<>"",PROCESO!J37,IF(PROCESO!J38<>"",PROCESO!J38,IF(PROCESO!J39<>"",PROCESO!J39,"")))),2)="G-",MID(IF(PROCESO!J36<>"",PROCESO!J36,IF(PROCESO!J37<>"",PROCESO!J37,IF(PROCESO!J38<>"",PROCESO!J38,IF(PROCESO!J39<>"",PROCESO!J39,"")))),3,99),IF(PROCESO!J36<>"",PROCESO!J36,IF(PROCESO!J37<>"",PROCESO!J37,IF(PROCESO!J38<>"",PROCESO!J38,IF(PROCESO!J39<>"",PROCESO!J39,""))))),"") -> G-2992 | P30: =P29+N(M30)-N(N30) -> 1180
A31: =IFERROR(INDEX(K$6:K$201,MATCH(ROW()-5,J$6:J$201,0)),"") -> LUN 20-07 | B31: =IFERROR(INDEX(L$6:L$201,MATCH(ROW()-5,J$6:J$201,0)),"") -> INGRESO (compra) | C31: =IFERROR(INDEX(M$6:M$201,MATCH(ROW()-5,J$6:J$201,0)),"") -> 4560 | D31: =IFERROR(INDEX(N$6:N$201,MATCH(ROW()-5,J$6:J$201,0)),"") | E31: =IFERROR(INDEX(O$6:O$201,MATCH(ROW()-5,J$6:J$201,0)),"") -> 48 sacos x 95 kg | F31: =IFERROR(INDEX(P$6:P$201,MATCH(ROW()-5,J$6:J$201,0)),"") -> 5873.5 | J31: =IF(OR(SUM(PROCESO!M36:M39)>0,SUM(PROCESO!N36:N39)>0),COUNT(J$6:J30)+1,"") | K31: =IF(OR(SUM(PROCESO!M36:M39)>0,SUM(PROCESO!N36:N39)>0),PROCESO!A36&IF(COUNTIF(PROCESO!$A$6:A35,PROCESO!A36)>0," (Ped."&(COUNTIF(PROCESO!$A$6:A35,PROCESO!A36)+1)&")",""),"") | L31: =IF(OR(SUM(PROCESO!M36:M39)>0,SUM(PROCESO!N36:N39)>0),"REPROCESO (devolución)","") | M31: =IF(OR(SUM(PROCESO!M36:M39)>0,SUM(PROCESO!N36:N39)>0),SUM(PROCESO!N36:N39),"") | N31: ="" | O31: =IF(OR(SUM(PROCESO!M36:M39)>0,SUM(PROCESO!N36:N39)>0),IF(SUM(PROCESO!M36:M39)>0,SUM(PROCESO!M36:M39)&" jabas devueltas · merma "&TEXT((PROCESO!M36*15+PROCESO!M37*18+PROCESO!M38*17+PROCESO!M39*17)-SUM(PROCESO!N36:N39),"+#,##0;-#,##0;0")&" kg",""),"") | P31: =P30+N(M31)-N(N31) -> 1180
A32: =IFERROR(INDEX(K$6:K$201,MATCH(ROW()-5,J$6:J$201,0)),"") -> LUN 20-07 | B32: =IFERROR(INDEX(L$6:L$201,MATCH(ROW()-5,J$6:J$201,0)),"") -> CHANCHO (proceso) | C32: =IFERROR(INDEX(M$6:M$201,MATCH(ROW()-5,J$6:J$201,0)),"") | D32: =IFERROR(INDEX(N$6:N$201,MATCH(ROW()-5,J$6:J$201,0)),"") -> 617.5 | E32: =IFERROR(INDEX(O$6:O$201,MATCH(ROW()-5,J$6:J$201,0)),"") -> 6.5 sacos x 95 kg | F32: =IFERROR(INDEX(P$6:P$201,MATCH(ROW()-5,J$6:J$201,0)),"") -> 5256 | J32: =IF(PROCESO!D42>0,COUNT(J$6:J31)+1,"") -> 17 | K32: =IF(PROCESO!D42>0,PROCESO!A42&IF(COUNTIF(PROCESO!$A$6:A41,PROCESO!A42)>0," (Ped."&(COUNTIF(PROCESO!$A$6:A41,PROCESO!A42)+1)&")",""),"") -> VIE 17-07 | L32: =IF(PROCESO!D42>0,"INGRESO (compra)","") -> INGRESO (compra) | M32: =IF(PROCESO!D42>0,PROCESO!D42,"") -> 5700 | N32: ="" | O32: =IF(PROCESO!D42>0,PROCESO!B42&" sacos x "&PROCESO!C42&" kg","") -> 60 sacos x 95 kg | P32: =P31+N(M32)-N(N32) -> 6880
A33: =IFERROR(INDEX(K$6:K$201,MATCH(ROW()-5,J$6:J$201,0)),"") -> LUN 20-07 | B33: =IFERROR(INDEX(L$6:L$201,MATCH(ROW()-5,J$6:J$201,0)),"") -> ENVÍO Guía 3001 | C33: =IFERROR(INDEX(M$6:M$201,MATCH(ROW()-5,J$6:J$201,0)),"") | D33: =IFERROR(INDEX(N$6:N$201,MATCH(ROW()-5,J$6:J$201,0)),"") -> 3294 | E33: =IFERROR(INDEX(O$6:O$201,MATCH(ROW()-5,J$6:J$201,0)),"") -> G-3001 | F33: =IFERROR(INDEX(P$6:P$201,MATCH(ROW()-5,J$6:J$201,0)),"") -> 1962 | J33: =IF(N(PROCESO!H46)>0,COUNT(J$6:J32)+1,"") -> 18 | K33: =IF(N(PROCESO!H46)>0,PROCESO!A42&IF(COUNTIF(PROCESO!$A$6:A41,PROCESO!A42)>0," (Ped."&(COUNTIF(PROCESO!$A$6:A41,PROCESO!A42)+1)&")",""),"") -> VIE 17-07 | L33: =IF(N(PROCESO!H46)>0,"CHANCHO (proceso)","") -> CHANCHO (proceso) | M33: ="" | N33: =IF(N(PROCESO!H46)>0,N(PROCESO!H46),"") -> 950 | O33: =IF(N(PROCESO!H46)>0,PROCESO!G46&" sacos x 95 kg","") -> 10 sacos x 95 kg | P33: =P32+N(M33)-N(N33) -> 5930
A34: =IFERROR(INDEX(K$6:K$201,MATCH(ROW()-5,J$6:J$201,0)),"") -> LUN 20-07 (Ped.2) | B34: =IFERROR(INDEX(L$6:L$201,MATCH(ROW()-5,J$6:J$201,0)),"") -> INGRESO (compra) | C34: =IFERROR(INDEX(M$6:M$201,MATCH(ROW()-5,J$6:J$201,0)),"") -> 2090 | D34: =IFERROR(INDEX(N$6:N$201,MATCH(ROW()-5,J$6:J$201,0)),"") | E34: =IFERROR(INDEX(O$6:O$201,MATCH(ROW()-5,J$6:J$201,0)),"") -> 22 sacos x 95 kg | F34: =IFERROR(INDEX(P$6:P$201,MATCH(ROW()-5,J$6:J$201,0)),"") -> 4052 | J34: =IF(N(PROCESO!H47)>0,COUNT(J$6:J33)+1,"") | K34: =IF(N(PROCESO!H47)>0,PROCESO!A42&IF(COUNTIF(PROCESO!$A$6:A41,PROCESO!A42)>0," (Ped."&(COUNTIF(PROCESO!$A$6:A41,PROCESO!A42)+1)&")",""),"") | L34: =IF(N(PROCESO!H47)>0,"MALOGRADO","") | M34: ="" | N34: =IF(N(PROCESO!H47)>0,N(PROCESO!H47),"") | O34: ="" | P34: =P33+N(M34)-N(N34) -> 5930
A35: =IFERROR(INDEX(K$6:K$201,MATCH(ROW()-5,J$6:J$201,0)),"") -> LUN 20-07 (Ped.2) | B35: =IFERROR(INDEX(L$6:L$201,MATCH(ROW()-5,J$6:J$201,0)),"") -> CHANCHO (proceso) | C35: =IFERROR(INDEX(M$6:M$201,MATCH(ROW()-5,J$6:J$201,0)),"") | D35: =IFERROR(INDEX(N$6:N$201,MATCH(ROW()-5,J$6:J$201,0)),"") -> 285 | E35: =IFERROR(INDEX(O$6:O$201,MATCH(ROW()-5,J$6:J$201,0)),"") -> 3 sacos x 95 kg | F35: =IFERROR(INDEX(P$6:P$201,MATCH(ROW()-5,J$6:J$201,0)),"") -> 3767 | J35: =IF(IF(PROCESO!J42<>"",PROCESO!J42,IF(PROCESO!J43<>"",PROCESO!J43,IF(PROCESO!J44<>"",PROCESO!J44,IF(PROCESO!J45<>"",PROCESO!J45,""))))<>"",COUNT(J$6:J34)+1,"") -> 19 | K35: =IF(IF(PROCESO!J42<>"",PROCESO!J42,IF(PROCESO!J43<>"",PROCESO!J43,IF(PROCESO!J44<>"",PROCESO!J44,IF(PROCESO!J45<>"",PROCESO!J45,""))))<>"",PROCESO!A42&IF(COUNTIF(PROCESO!$A$6:A41,PROCESO!A42)>0," (Ped."&(COUNTIF(PROCESO!$A$6:A41,PROCESO!A42)+1)&")",""),"") -> VIE 17-07 | L35: =IF(IF(PROCESO!J42<>"",PROCESO!J42,IF(PROCESO!J43<>"",PROCESO!J43,IF(PROCESO!J44<>"",PROCESO!J44,IF(PROCESO!J45<>"",PROCESO!J45,""))))<>"","ENVÍO Guía "&IF(LEFT(IF(PROCESO!J42<>"",PROCESO!J42,IF(PROCESO!J43<>"",PROCESO!J43,IF(PROCESO!J44<>"",PROCESO!J44,IF(PROCESO!J45<>"",PROCESO!J45,"")))),2)="G-",MID(IF(PROCESO!J42<>"",PROCESO!J42,IF(PROCESO!J43<>"",PROCESO!J43,IF(PROCESO!J44<>"",PROCESO!J44,IF(PROCESO!J45<>"",PROCESO!J45,"")))),3,99),IF(PROCESO!J42<>"",PROCESO!J42,IF(PROCESO!J43<>"",PROCESO!J43,IF(PROCESO!J44<>"",PROCESO!J44,IF(PROCESO!J45<>"",PROCESO!J45,""))))),"") -> ENVÍO Guía 2994 | M35: ="" | N35: =IF(IF(PROCESO!J42<>"",PROCESO!J42,IF(PROCESO!J43<>"",PROCESO!J43,IF(PROCESO!J44<>"",PROCESO!J44,IF(PROCESO!J45<>"",PROCESO!J45,""))))<>"",SUMIF(PROCESO!J42:J45,IF(PROCESO!J42<>"",PROCESO!J42,IF(PROCESO!J43<>"",PROCESO!J43,IF(PROCESO!J44<>"",PROCESO!J44,IF(PROCESO!J45<>"",PROCESO!J45,"")))),PROCESO!L42:L45),"") -> 3413 | O35: =IF(IF(PROCESO!J42<>"",PROCESO!J42,IF(PROCESO!J43<>"",PROCESO!J43,IF(PROCESO!J44<>"",PROCESO!J44,IF(PROCESO!J45<>"",PROCESO!J45,""))))<>"","G-"&IF(LEFT(IF(PROCESO!J42<>"",PROCESO!J42,IF(PROCESO!J43<>"",PROCESO!J43,IF(PROCESO!J44<>"",PROCESO!J44,IF(PROCESO!J45<>"",PROCESO!J45,"")))),2)="G-",MID(IF(PROCESO!J42<>"",PROCESO!J42,IF(PROCESO!J43<>"",PROCESO!J43,IF(PROCESO!J44<>"",PROCESO!J44,IF(PROCESO!J45<>"",PROCESO!J45,"")))),3,99),IF(PROCESO!J42<>"",PROCESO!J42,IF(PROCESO!J43<>"",PROCESO!J43,IF(PROCESO!J44<>"",PROCESO!J44,IF(PROCESO!J45<>"",PROCESO!J45,""))))),"") -> G-2994 | P35: =P34+N(M35)-N(N35) -> 2517
A36: =IFERROR(INDEX(K$6:K$201,MATCH(ROW()-5,J$6:J$201,0)),"") -> MAR 21-07 | B36: =IFERROR(INDEX(L$6:L$201,MATCH(ROW()-5,J$6:J$201,0)),"") -> INGRESO (compra) | C36: =IFERROR(INDEX(M$6:M$201,MATCH(ROW()-5,J$6:J$201,0)),"") -> 6650 | D36: =IFERROR(INDEX(N$6:N$201,MATCH(ROW()-5,J$6:J$201,0)),"") | E36: =IFERROR(INDEX(O$6:O$201,MATCH(ROW()-5,J$6:J$201,0)),"") -> 70 sacos x 95 kg | F36: =IFERROR(INDEX(P$6:P$201,MATCH(ROW()-5,J$6:J$201,0)),"") -> 10417 | J36: =IF(OR(SUM(PROCESO!M42:M45)>0,SUM(PROCESO!N42:N45)>0),COUNT(J$6:J35)+1,"") | K36: =IF(OR(SUM(PROCESO!M42:M45)>0,SUM(PROCESO!N42:N45)>0),PROCESO!A42&IF(COUNTIF(PROCESO!$A$6:A41,PROCESO!A42)>0," (Ped."&(COUNTIF(PROCESO!$A$6:A41,PROCESO!A42)+1)&")",""),"") | L36: =IF(OR(SUM(PROCESO!M42:M45)>0,SUM(PROCESO!N42:N45)>0),"REPROCESO (devolución)","") | M36: =IF(OR(SUM(PROCESO!M42:M45)>0,SUM(PROCESO!N42:N45)>0),SUM(PROCESO!N42:N45),"") | N36: ="" | O36: =IF(OR(SUM(PROCESO!M42:M45)>0,SUM(PROCESO!N42:N45)>0),IF(SUM(PROCESO!M42:M45)>0,SUM(PROCESO!M42:M45)&" jabas devueltas · merma "&TEXT((PROCESO!M42*15+PROCESO!M43*18+PROCESO!M44*17+PROCESO!M45*17)-SUM(PROCESO!N42:N45),"+#,##0;-#,##0;0")&" kg",""),"") | P36: =P35+N(M36)-N(N36) -> 2517
A37: =IFERROR(INDEX(K$6:K$201,MATCH(ROW()-5,J$6:J$201,0)),"") -> MAR 21-07 | B37: =IFERROR(INDEX(L$6:L$201,MATCH(ROW()-5,J$6:J$201,0)),"") -> CHANCHO (proceso) | C37: =IFERROR(INDEX(M$6:M$201,MATCH(ROW()-5,J$6:J$201,0)),"") | D37: =IFERROR(INDEX(N$6:N$201,MATCH(ROW()-5,J$6:J$201,0)),"") -> 380 | E37: =IFERROR(INDEX(O$6:O$201,MATCH(ROW()-5,J$6:J$201,0)),"") -> 4 sacos x 95 kg | F37: =IFERROR(INDEX(P$6:P$201,MATCH(ROW()-5,J$6:J$201,0)),"") -> 10037 | J37: =IF(PROCESO!D48>0,COUNT(J$6:J36)+1,"") -> 20 | K37: =IF(PROCESO!D48>0,PROCESO!A48&IF(COUNTIF(PROCESO!$A$6:A47,PROCESO!A48)>0," (Ped."&(COUNTIF(PROCESO!$A$6:A47,PROCESO!A48)+1)&")",""),"") -> VIE 17-07 (Ped.2) | L37: =IF(PROCESO!D48>0,"INGRESO (compra)","") -> INGRESO (compra) | M37: =IF(PROCESO!D48>0,PROCESO!D48,"") -> 475 | N37: ="" | O37: =IF(PROCESO!D48>0,PROCESO!B48&" sacos x "&PROCESO!C48&" kg","") -> 5 sacos x 95 kg | P37: =P36+N(M37)-N(N37) -> 2992
A38: =IFERROR(INDEX(K$6:K$201,MATCH(ROW()-5,J$6:J$201,0)),"") -> MAR 21-07 | B38: =IFERROR(INDEX(L$6:L$201,MATCH(ROW()-5,J$6:J$201,0)),"") -> ENVÍO Guía 3004 | C38: =IFERROR(INDEX(M$6:M$201,MATCH(ROW()-5,J$6:J$201,0)),"") | D38: =IFERROR(INDEX(N$6:N$201,MATCH(ROW()-5,J$6:J$201,0)),"") -> 3260 | E38: =IFERROR(INDEX(O$6:O$201,MATCH(ROW()-5,J$6:J$201,0)),"") -> G-3004 | F38: =IFERROR(INDEX(P$6:P$201,MATCH(ROW()-5,J$6:J$201,0)),"") -> 6777 | J38: =IF(N(PROCESO!H52)>0,COUNT(J$6:J37)+1,"") -> 21 | K38: =IF(N(PROCESO!H52)>0,PROCESO!A48&IF(COUNTIF(PROCESO!$A$6:A47,PROCESO!A48)>0," (Ped."&(COUNTIF(PROCESO!$A$6:A47,PROCESO!A48)+1)&")",""),"") -> VIE 17-07 (Ped.2) | L38: =IF(N(PROCESO!H52)>0,"CHANCHO (proceso)","") -> CHANCHO (proceso) | M38: ="" | N38: =IF(N(PROCESO!H52)>0,N(PROCESO!H52),"") -> 95 | O38: =IF(N(PROCESO!H52)>0,PROCESO!G52&" sacos x 95 kg","") -> 1 sacos x 95 kg | P38: =P37+N(M38)-N(N38) -> 2897
A39: =IFERROR(INDEX(K$6:K$201,MATCH(ROW()-5,J$6:J$201,0)),"") -> MAR 21-07 | B39: =IFERROR(INDEX(L$6:L$201,MATCH(ROW()-5,J$6:J$201,0)),"") -> REPROCESO (devolución) | C39: =IFERROR(INDEX(M$6:M$201,MATCH(ROW()-5,J$6:J$201,0)),"") -> 17 | D39: =IFERROR(INDEX(N$6:N$201,MATCH(ROW()-5,J$6:J$201,0)),"") | E39: =IFERROR(INDEX(O$6:O$201,MATCH(ROW()-5,J$6:J$201,0)),"") -> 2 jabas devueltas · merma +15 kg | F39: =IFERROR(INDEX(P$6:P$201,MATCH(ROW()-5,J$6:J$201,0)),"") -> 6794 | J39: =IF(N(PROCESO!H53)>0,COUNT(J$6:J38)+1,"") | K39: =IF(N(PROCESO!H53)>0,PROCESO!A48&IF(COUNTIF(PROCESO!$A$6:A47,PROCESO!A48)>0," (Ped."&(COUNTIF(PROCESO!$A$6:A47,PROCESO!A48)+1)&")",""),"") | L39: =IF(N(PROCESO!H53)>0,"MALOGRADO","") | M39: ="" | N39: =IF(N(PROCESO!H53)>0,N(PROCESO!H53),"") | O39: ="" | P39: =P38+N(M39)-N(N39) -> 2897
A40: =IFERROR(INDEX(K$6:K$201,MATCH(ROW()-5,J$6:J$201,0)),"") -> MIE 22-07 | B40: =IFERROR(INDEX(L$6:L$201,MATCH(ROW()-5,J$6:J$201,0)),"") -> CHANCHO (proceso) | C40: =IFERROR(INDEX(M$6:M$201,MATCH(ROW()-5,J$6:J$201,0)),"") | D40: =IFERROR(INDEX(N$6:N$201,MATCH(ROW()-5,J$6:J$201,0)),"") -> 760 | E40: =IFERROR(INDEX(O$6:O$201,MATCH(ROW()-5,J$6:J$201,0)),"") -> 8 sacos x 95 kg | F40: =IFERROR(INDEX(P$6:P$201,MATCH(ROW()-5,J$6:J$201,0)),"") -> 6034 | J40: =IF(IF(PROCESO!J48<>"",PROCESO!J48,IF(PROCESO!J49<>"",PROCESO!J49,IF(PROCESO!J50<>"",PROCESO!J50,IF(PROCESO!J51<>"",PROCESO!J51,""))))<>"",COUNT(J$6:J39)+1,"") | K40: =IF(IF(PROCESO!J48<>"",PROCESO!J48,IF(PROCESO!J49<>"",PROCESO!J49,IF(PROCESO!J50<>"",PROCESO!J50,IF(PROCESO!J51<>"",PROCESO!J51,""))))<>"",PROCESO!A48&IF(COUNTIF(PROCESO!$A$6:A47,PROCESO!A48)>0," (Ped."&(COUNTIF(PROCESO!$A$6:A47,PROCESO!A48)+1)&")",""),"") | L40: =IF(IF(PROCESO!J48<>"",PROCESO!J48,IF(PROCESO!J49<>"",PROCESO!J49,IF(PROCESO!J50<>"",PROCESO!J50,IF(PROCESO!J51<>"",PROCESO!J51,""))))<>"","ENVÍO Guía "&IF(LEFT(IF(PROCESO!J48<>"",PROCESO!J48,IF(PROCESO!J49<>"",PROCESO!J49,IF(PROCESO!J50<>"",PROCESO!J50,IF(PROCESO!J51<>"",PROCESO!J51,"")))),2)="G-",MID(IF(PROCESO!J48<>"",PROCESO!J48,IF(PROCESO!J49<>"",PROCESO!J49,IF(PROCESO!J50<>"",PROCESO!J50,IF(PROCESO!J51<>"",PROCESO!J51,"")))),3,99),IF(PROCESO!J48<>"",PROCESO!J48,IF(PROCESO!J49<>"",PROCESO!J49,IF(PROCESO!J50<>"",PROCESO!J50,IF(PROCESO!J51<>"",PROCESO!J51,""))))),"") | M40: ="" | N40: =IF(IF(PROCESO!J48<>"",PROCESO!J48,IF(PROCESO!J49<>"",PROCESO!J49,IF(PROCESO!J50<>"",PROCESO!J50,IF(PROCESO!J51<>"",PROCESO!J51,""))))<>"",SUMIF(PROCESO!J48:J51,IF(PROCESO!J48<>"",PROCESO!J48,IF(PROCESO!J49<>"",PROCESO!J49,IF(PROCESO!J50<>"",PROCESO!J50,IF(PROCESO!J51<>"",PROCESO!J51,"")))),PROCESO!L48:L51),"") | O40: =IF(IF(PROCESO!J48<>"",PROCESO!J48,IF(PROCESO!J49<>"",PROCESO!J49,IF(PROCESO!J50<>"",PROCESO!J50,IF(PROCESO!J51<>"",PROCESO!J51,""))))<>"","G-"&IF(LEFT(IF(PROCESO!J48<>"",PROCESO!J48,IF(PROCESO!J49<>"",PROCESO!J49,IF(PROCESO!J50<>"",PROCESO!J50,IF(PROCESO!J51<>"",PROCESO!J51,"")))),2)="G-",MID(IF(PROCESO!J48<>"",PROCESO!J48,IF(PROCESO!J49<>"",PROCESO!J49,IF(PROCESO!J50<>"",PROCESO!J50,IF(PROCESO!J51<>"",PROCESO!J51,"")))),3,99),IF(PROCESO!J48<>"",PROCESO!J48,IF(PROCESO!J49<>"",PROCESO!J49,IF(PROCESO!J50<>"",PROCESO!J50,IF(PROCESO!J51<>"",PROCESO!J51,""))))),"") | P40: =P39+N(M40)-N(N40) -> 2897
A41: =IFERROR(INDEX(K$6:K$201,MATCH(ROW()-5,J$6:J$201,0)),"") -> MIE 22-07 | B41: =IFERROR(INDEX(L$6:L$201,MATCH(ROW()-5,J$6:J$201,0)),"") -> MALOGRADO | C41: =IFERROR(INDEX(M$6:M$201,MATCH(ROW()-5,J$6:J$201,0)),"") | D41: =IFERROR(INDEX(N$6:N$201,MATCH(ROW()-5,J$6:J$201,0)),"") -> 50 | E41: =IFERROR(INDEX(O$6:O$201,MATCH(ROW()-5,J$6:J$201,0)),"") | F41: =IFERROR(INDEX(P$6:P$201,MATCH(ROW()-5,J$6:J$201,0)),"") -> 5984 | J41: =IF(OR(SUM(PROCESO!M48:M51)>0,SUM(PROCESO!N48:N51)>0),COUNT(J$6:J40)+1,"") | K41: =IF(OR(SUM(PROCESO!M48:M51)>0,SUM(PROCESO!N48:N51)>0),PROCESO!A48&IF(COUNTIF(PROCESO!$A$6:A47,PROCESO!A48)>0," (Ped."&(COUNTIF(PROCESO!$A$6:A47,PROCESO!A48)+1)&")",""),"") | L41: =IF(OR(SUM(PROCESO!M48:M51)>0,SUM(PROCESO!N48:N51)>0),"REPROCESO (devolución)","") | M41: =IF(OR(SUM(PROCESO!M48:M51)>0,SUM(PROCESO!N48:N51)>0),SUM(PROCESO!N48:N51),"") | N41: ="" | O41: =IF(OR(SUM(PROCESO!M48:M51)>0,SUM(PROCESO!N48:N51)>0),IF(SUM(PROCESO!M48:M51)>0,SUM(PROCESO!M48:M51)&" jabas devueltas · merma "&TEXT((PROCESO!M48*15+PROCESO!M49*18+PROCESO!M50*17+PROCESO!M51*17)-SUM(PROCESO!N48:N51),"+#,##0;-#,##0;0")&" kg",""),"") | P41: =P40+N(M41)-N(N41) -> 2897
...
