Workbook

Sheet MOVIMIENTOS
A1: AGRO PACAYALES · PLANTA CAMOTE 2026 | MOVIMIENTOS — registra aquí un evento por fila
A2: Única hoja que llenas: escribe la fecha como 24-7 (saldrá "vie 24-07" solita) + Tipo (lista) + Calidad + Unidad (jabas/sacos/kg) + Cantidad → los Kg salen solos. Si registras en kg (muestras, malogrado, reproceso, otras salidas) los Kg = Cantidad. Guía/ticket y nota al final. KARDEX, SALDO DIARIO y RESUMEN se arman solos.
A4: Fecha | B4: Tipo | C4: Calidad | D4: Unidad | E4: Cantidad | F4: Kg | G4: N° Guía / Ticket | H4: Observación
A5: 46214 | B5: SALDO INICIAL | C5: A | D5: jabas | E5: 8 | F5: =IF($B5="","",IF($D5="kg",N($E5),IF($D5="sacos",N($E5)*95,IF($D5="jabas",N($E5)*IFERROR(VLOOKUP($C5,LISTAS!$A$2:$B$12,2,0),0),"")))) -> 120 | H5: Saldo semana anterior | I5: =N($F5) -> 120
A6: 46214 | B6: SALDO INICIAL | C6: M | D6: jabas | E6: 7 | F6: =IF($B6="","",IF($D6="kg",N($E6),IF($D6="sacos",N($E6)*95,IF($D6="jabas",N($E6)*IFERROR(VLOOKUP($C6,LISTAS!$A$2:$B$12,2,0),0),"")))) -> 119 | H6: Saldo semana anterior | I6: =N($F6) -> 119
A7: 46214 | B7: SALDO INICIAL | C7: Chancho | D7: sacos | E7: 20 | F7: =IF($B7="","",IF($D7="kg",N($E7),IF($D7="sacos",N($E7)*95,IF($D7="jabas",N($E7)*IFERROR(VLOOKUP($C7,LISTAS!$A$2:$B$12,2,0),0),"")))) -> 1900 | H7: Saldo semana anterior | I7: =N($F7) -> 1900
A8: 46215 | B8: COMPRA | C8: — | D8: sacos | E8: 30 | F8: =IF($B8="","",IF($D8="kg",N($E8),IF($D8="sacos",N($E8)*95,IF($D8="jabas",N($E8)*IFERROR(VLOOKUP($C8,LISTAS!$A$2:$B$12,2,0),0),"")))) -> 2850 | H8: peso aprox 95 kg/saco | I8: =N($F8) -> 2850
A9: 46215 | B9: PROCESO | C9: A | D9: jabas | E9: 59 | F9: =IF($B9="","",IF($D9="kg",N($E9),IF($D9="sacos",N($E9)*95,IF($D9="jabas",N($E9)*IFERROR(VLOOKUP($C9,LISTAS!$A$2:$B$12,2,0),0),"")))) -> 885 | I9: =N($F9) -> 885
A10: 46215 | B10: PROCESO | C10: P | D10: jabas | E10: 11 | F10: =IF($B10="","",IF($D10="kg",N($E10),IF($D10="sacos",N($E10)*95,IF($D10="jabas",N($E10)*IFERROR(VLOOKUP($C10,LISTAS!$A$2:$B$12,2,0),0),"")))) -> 198 | I10: =N($F10) -> 198
A11: 46215 | B11: PROCESO | C11: C | D11: jabas | E11: 12 | F11: =IF($B11="","",IF($D11="kg",N($E11),IF($D11="sacos",N($E11)*95,IF($D11="jabas",N($E11)*IFERROR(VLOOKUP($C11,LISTAS!$A$2:$B$12,2,0),0),"")))) -> 204 | I11: =N($F11) -> 204
A12: 46215 | B12: PROCESO | C12: M | D12: jabas | E12: 64 | F12: =IF($B12="","",IF($D12="kg",N($E12),IF($D12="sacos",N($E12)*95,IF($D12="jabas",N($E12)*IFERROR(VLOOKUP($C12,LISTAS!$A$2:$B$12,2,0),0),"")))) -> 1088 | I12: =N($F12) -> 1088
A13: 46215 | B13: PROCESO | C13: Chancho | D13: sacos | E13: 6 | F13: =IF($B13="","",IF($D13="kg",N($E13),IF($D13="sacos",N($E13)*95,IF($D13="jabas",N($E13)*IFERROR(VLOOKUP($C13,LISTAS!$A$2:$B$12,2,0),0),"")))) -> 570 | I13: =N($F13) -> 570
A14: 46215 | B14: ENVÍO A SUPESA | C14: A | D14: jabas | E14: 67 | F14: =IF($B14="","",IF($D14="kg",N($E14),IF($D14="sacos",N($E14)*95,IF($D14="jabas",N($E14)*IFERROR(VLOOKUP($C14,LISTAS!$A$2:$B$12,2,0),0),"")))) -> 1005 | G14: 2977 | I14: =N($F14) -> 1005
A15: 46215 | B15: ENVÍO A SUPESA | C15: P | D15: jabas | E15: 11 | F15: =IF($B15="","",IF($D15="kg",N($E15),IF($D15="sacos",N($E15)*95,IF($D15="jabas",N($E15)*IFERROR(VLOOKUP($C15,LISTAS!$A$2:$B$12,2,0),0),"")))) -> 198 | G15: 2977 | I15: =N($F15) -> 198
A16: 46215 | B16: ENVÍO A SUPESA | C16: C | D16: jabas | E16: 12 | F16: =IF($B16="","",IF($D16="kg",N($E16),IF($D16="sacos",N($E16)*95,IF($D16="jabas",N($E16)*IFERROR(VLOOKUP($C16,LISTAS!$A$2:$B$12,2,0),0),"")))) -> 204 | G16: 2977 | I16: =N($F16) -> 204
A17: 46215 | B17: ENVÍO A SUPESA | C17: M | D17: jabas | E17: 42 | F17: =IF($B17="","",IF($D17="kg",N($E17),IF($D17="sacos",N($E17)*95,IF($D17="jabas",N($E17)*IFERROR(VLOOKUP($C17,LISTAS!$A$2:$B$12,2,0),0),"")))) -> 714 | G17: 2977 | I17: =N($F17) -> 714
A18: 46216 | B18: COMPRA | C18: — | D18: sacos | E18: 40 | F18: =IF($B18="","",IF($D18="kg",N($E18),IF($D18="sacos",N($E18)*95,IF($D18="jabas",N($E18)*IFERROR(VLOOKUP($C18,LISTAS!$A$2:$B$12,2,0),0),"")))) -> 3800 | H18: peso aprox 95 kg/saco | I18: =N($F18) -> 3800
A19: 46216 | B19: PROCESO | C19: A | D19: jabas | E19: 107 | F19: =IF($B19="","",IF($D19="kg",N($E19),IF($D19="sacos",N($E19)*95,IF($D19="jabas",N($E19)*IFERROR(VLOOKUP($C19,LISTAS!$A$2:$B$12,2,0),0),"")))) -> 1605 | I19: =N($F19) -> 1605
A20: 46216 | B20: PROCESO | C20: P | D20: jabas | E20: 11 | F20: =IF($B20="","",IF($D20="kg",N($E20),IF($D20="sacos",N($E20)*95,IF($D20="jabas",N($E20)*IFERROR(VLOOKUP($C20,LISTAS!$A$2:$B$12,2,0),0),"")))) -> 198 | I20: =N($F20) -> 198
A21: 46216 | B21: PROCESO | C21: C | D21: jabas | E21: 12 | F21: =IF($B21="","",IF($D21="kg",N($E21),IF($D21="sacos",N($E21)*95,IF($D21="jabas",N($E21)*IFERROR(VLOOKUP($C21,LISTAS!$A$2:$B$12,2,0),0),"")))) -> 204 | I21: =N($F21) -> 204
A22: 46216 | B22: PROCESO | C22: M | D22: jabas | E22: 110 | F22: =IF($B22="","",IF($D22="kg",N($E22),IF($D22="sacos",N($E22)*95,IF($D22="jabas",N($E22)*IFERROR(VLOOKUP($C22,LISTAS!$A$2:$B$12,2,0),0),"")))) -> 1870 | I22: =N($F22) -> 1870
A23: 46216 | B23: PROCESO | C23: Chancho | D23: sacos | E23: 2 | F23: =IF($B23="","",IF($D23="kg",N($E23),IF($D23="sacos",N($E23)*95,IF($D23="jabas",N($E23)*IFERROR(VLOOKUP($C23,LISTAS!$A$2:$B$12,2,0),0),"")))) -> 190 | I23: =N($F23) -> 190
A24: 46216 | B24: ENVÍO A SUPESA | C24: A | D24: jabas | E24: 67 | F24: =IF($B24="","",IF($D24="kg",N($E24),IF($D24="sacos",N($E24)*95,IF($D24="jabas",N($E24)*IFERROR(VLOOKUP($C24,LISTAS!$A$2:$B$12,2,0),0),"")))) -> 1005 | G24: 2980 | I24: =N($F24) -> 1005
A25: 46216 | B25: ENVÍO A SUPESA | C25: P | D25: jabas | E25: 11 | F25: =IF($B25="","",IF($D25="kg",N($E25),IF($D25="sacos",N($E25)*95,IF($D25="jabas",N($E25)*IFERROR(VLOOKUP($C25,LISTAS!$A$2:$B$12,2,0),0),"")))) -> 198 | G25: 2980 | I25: =N($F25) -> 198
A26: 46216 | B26: ENVÍO A SUPESA | C26: C | D26: jabas | E26: 12 | F26: =IF($B26="","",IF($D26="kg",N($E26),IF($D26="sacos",N($E26)*95,IF($D26="jabas",N($E26)*IFERROR(VLOOKUP($C26,LISTAS!$A$2:$B$12,2,0),0),"")))) -> 204 | G26: 2980 | I26: =N($F26) -> 204
A27: 46216 | B27: ENVÍO A SUPESA | C27: M | D27: jabas | E27: 97 | F27: =IF($B27="","",IF($D27="kg",N($E27),IF($D27="sacos",N($E27)*95,IF($D27="jabas",N($E27)*IFERROR(VLOOKUP($C27,LISTAS!$A$2:$B$12,2,0),0),"")))) -> 1649 | G27: 2980 | I27: =N($F27) -> 1649
A28: 46217 | B28: COMPRA | C28: — | D28: sacos | E28: 40 | F28: =IF($B28="","",IF($D28="kg",N($E28),IF($D28="sacos",N($E28)*95,IF($D28="jabas",N($E28)*IFERROR(VLOOKUP($C28,LISTAS!$A$2:$B$12,2,0),0),"")))) -> 3800 | H28: peso aprox 95 kg/saco | I28: =N($F28) -> 3800
A29: 46217 | B29: PROCESO | C29: A | D29: jabas | E29: 45 | F29: =IF($B29="","",IF($D29="kg",N($E29),IF($D29="sacos",N($E29)*95,IF($D29="jabas",N($E29)*IFERROR(VLOOKUP($C29,LISTAS!$A$2:$B$12,2,0),0),"")))) -> 675 | I29: =N($F29) -> 675
A30: 46217 | B30: PROCESO | C30: P | D30: jabas | E30: 11 | F30: =IF($B30="","",IF($D30="kg",N($E30),IF($D30="sacos",N($E30)*95,IF($D30="jabas",N($E30)*IFERROR(VLOOKUP($C30,LISTAS!$A$2:$B$12,2,0),0),"")))) -> 198 | I30: =N($F30) -> 198
A31: 46217 | B31: PROCESO | C31: C | D31: jabas | E31: 12 | F31: =IF($B31="","",IF($D31="kg",N($E31),IF($D31="sacos",N($E31)*95,IF($D31="jabas",N($E31)*IFERROR(VLOOKUP($C31,LISTAS!$A$2:$B$12,2,0),0),"")))) -> 204 | I31: =N($F31) -> 204
A32: 46217 | B32: PROCESO | C32: M | D32: jabas | E32: 121 | F32: =IF($B32="","",IF($D32="kg",N($E32),IF($D32="sacos",N($E32)*95,IF($D32="jabas",N($E32)*IFERROR(VLOOKUP($C32,LISTAS!$A$2:$B$12,2,0),0),"")))) -> 2057 | I32: =N($F32) -> 2057
A33: 46217 | B33: PROCESO | C33: Chancho | D33: sacos | E33: 7 | F33: =IF($B33="","",IF($D33="kg",N($E33),IF($D33="sacos",N($E33)*95,IF($D33="jabas",N($E33)*IFERROR(VLOOKUP($C33,LISTAS!$A$2:$B$12,2,0),0),"")))) -> 665 | I33: =N($F33) -> 665
A34: 46217 | B34: ENVÍO A SUPESA | C34: A | D34: jabas | E34: 67 | F34: =IF($B34="","",IF($D34="kg",N($E34),IF($D34="sacos",N($E34)*95,IF($D34="jabas",N($E34)*IFERROR(VLOOKUP($C34,LISTAS!$A$2:$B$12,2,0),0),"")))) -> 1005 | G34: 2984 | I34: =N($F34) -> 1005
A35: 46217 | B35: ENVÍO A SUPESA | C35: P | D35: jabas | E35: 11 | F35: =IF($B35="","",IF($D35="kg",N($E35),IF($D35="sacos",N($E35)*95,IF($D35="jabas",N($E35)*IFERROR(VLOOKUP($C35,LISTAS!$A$2:$B$12,2,0),0),"")))) -> 198 | G35: 2984 | I35: =N($F35) -> 198
A36: 46217 | B36: ENVÍO A SUPESA | C36: C | D36: jabas | E36: 12 | F36: =IF($B36="","",IF($D36="kg",N($E36),IF($D36="sacos",N($E36)*95,IF($D36="jabas",N($E36)*IFERROR(VLOOKUP($C36,LISTAS!$A$2:$B$12,2,0),0),"")))) -> 204 | G36: 2984 | I36: =N($F36) -> 204
A37: 46217 | B37: ENVÍO A SUPESA | C37: M | D37: jabas | E37: 116 | F37: =IF($B37="","",IF($D37="kg",N($E37),IF($D37="sacos",N($E37)*95,IF($D37="jabas",N($E37)*IFERROR(VLOOKUP($C37,LISTAS!$A$2:$B$12,2,0),0),"")))) -> 1972 | G37: 2984 | I37: =N($F37) -> 1972
A38: 46218 | B38: COMPRA | C38: — | D38: sacos | E38: 40 | F38: =IF($B38="","",IF($D38="kg",N($E38),IF($D38="sacos",N($E38)*95,IF($D38="jabas",N($E38)*IFERROR(VLOOKUP($C38,LISTAS!$A$2:$B$12,2,0),0),"")))) -> 3800 | H38: peso aprox 95 kg/saco | I38: =N($F38) -> 3800
A39: 46218 | B39: PROCESO | C39: A | D39: jabas | E39: 79 | F39: =IF($B39="","",IF($D39="kg",N($E39),IF($D39="sacos",N($E39)*95,IF($D39="jabas",N($E39)*IFERROR(VLOOKUP($C39,LISTAS!$A$2:$B$12,2,0),0),"")))) -> 1185 | I39: =N($F39) -> 1185
A40: 46218 | B40: PROCESO | C40: P | D40: jabas | E40: 22 | F40: =IF($B40="","",IF($D40="kg",N($E40),IF($D40="sacos",N($E40)*95,IF($D40="jabas",N($E40)*IFERROR(VLOOKUP($C40,LISTAS!$A$2:$B$12,2,0),0),"")))) -> 396 | I40: =N($F40) -> 396
A41: 46218 | B41: PROCESO | C41: C | D41: jabas | E41: 21 | F41: =IF($B41="","",IF($D41="kg",N($E41),IF($D41="sacos",N($E41)*95,IF($D41="jabas",N($E41)*IFERROR(VLOOKUP($C41,LISTAS!$A$2:$B$12,2,0),0),"")))) -> 357 | I41: =N($F41) -> 357
...

Sheet KARDEX
A1: AGRO PACAYALES · PLANTA CAMOTE 2026 | KARDEX — Entradas / Salidas y Stock (kg)
A2: Automático desde MOVIMIENTOS. Entradas: saldo inicial, compras, reprocesos. Salidas: envíos, chancho del proceso, malogrado, trasiegos y otras salidas. Ventas de chancho y devoluciones aparecen como información.
C4: ENTRADAS | D4: SALIDAS
A5: Fecha | B5: Detalle | C5: Ingresos Kg | D5: Salidas Kg | E5: N. Guía / Nota | F5: Stock Kg
A6: =IFERROR(INDEX(K$6:K$401,MATCH(ROW()-5,J$6:J$401,0)),"") -> 46214 | B6: =IFERROR(INDEX(L$6:L$401,MATCH(ROW()-5,J$6:J$401,0)),"") -> APERTURA (A) | C6: =IFERROR(INDEX(M$6:M$401,MATCH(ROW()-5,J$6:J$401,0)),"") -> 120 | D6: =IFERROR(INDEX(N$6:N$401,MATCH(ROW()-5,J$6:J$401,0)),"") | E6: =IFERROR(INDEX(O$6:O$401,MATCH(ROW()-5,J$6:J$401,0)),"") -> 8 jabas | F6: =IFERROR(INDEX(P$6:P$401,MATCH(ROW()-5,J$6:J$401,0)),"") -> 120 | J6: =IF(AND(MOVIMIENTOS!$B5<>"",NOT(AND(MOVIMIENTOS!$B5="PROCESO",MOVIMIENTOS!$C5<>"Chancho")),NOT(AND(MOVIMIENTOS!$B5="SALDO INICIAL",MOVIMIENTOS!$C5="Chancho"))),COUNT(J$5:J5)+1,"") -> 1 | K6: =IF(AND(MOVIMIENTOS!$B5<>"",NOT(AND(MOVIMIENTOS!$B5="PROCESO",MOVIMIENTOS!$C5<>"Chancho")),NOT(AND(MOVIMIENTOS!$B5="SALDO INICIAL",MOVIMIENTOS!$C5="Chancho"))),MOVIMIENTOS!$A5,"") -> 46214 | L6: =IF(AND(MOVIMIENTOS!$B5<>"",NOT(AND(MOVIMIENTOS!$B5="PROCESO",MOVIMIENTOS!$C5<>"Chancho")),NOT(AND(MOVIMIENTOS!$B5="SALDO INICIAL",MOVIMIENTOS!$C5="Chancho"))),IF(MOVIMIENTOS!$B5="SALDO INICIAL","APERTURA ("&MOVIMIENTOS!$C5&")",IF(MOVIMIENTOS!$B5="COMPRA","INGRESO (compra)",IF(MOVIMIENTOS!$B5="PROCESO","CHANCHO (proceso)",IF(MOVIMIENTOS!$B5="ENVÍO A SUPESA","ENVÍO SUPESA cal. "&MOVIMIENTOS!$C5,IF(MOVIMIENTOS!$B5="VENTA CHANCHO","VENTA CHANCHO",IF(MOVIMIENTOS!$B5="DEVOLUCIÓN","DEVOLUCIÓN cal. "&MOVIMIENTOS!$C5,IF(MOVIMIENTOS!$B5="TRASIEGO","TRASIEGO cal. "&MOVIMIENTOS!$C5,IF(MOVIMIENTOS!$B5="REGALO","REGALO "&MOVIMIENTOS!$C5,IF(MOVIMIENTOS!$B5="VENTA","VENTA "&MOVIMIENTOS!$C5,IF(MOVIMIENTOS!$B5="AJUSTE","AJUSTE inventario ("&MOVIMIENTOS!$C5&")",MOVIMIENTOS!$B5)))))))))),"") -> APERTURA (A) | M6: =IF(AND(AND(MOVIMIENTOS!$B5<>"",NOT(AND(MOVIMIENTOS!$B5="PROCESO",MOVIMIENTOS!$C5<>"Chancho")),NOT(AND(MOVIMIENTOS!$B5="SALDO INICIAL",MOVIMIENTOS!$C5="Chancho"))),OR(MOVIMIENTOS!$B5="SALDO INICIAL",MOVIMIENTOS!$B5="COMPRA",MOVIMIENTOS!$B5="REPROCESO",AND(MOVIMIENTOS!$B5="AJUSTE",MOVIMIENTOS!$C5<>"Chancho",N(MOVIMIENTOS!$F5)>=0))),N(MOVIMIENTOS!$F5),"") -> 120 | N6: =IF(AND(AND(MOVIMIENTOS!$B5<>"",NOT(AND(MOVIMIENTOS!$B5="PROCESO",MOVIMIENTOS!$C5<>"Chancho")),NOT(AND(MOVIMIENTOS!$B5="SALDO INICIAL",MOVIMIENTOS!$C5="Chancho"))),OR(MOVIMIENTOS!$B5="ENVÍO A SUPESA",MOVIMIENTOS!$B5="MALOGRADO",MOVIMIENTOS!$B5="OTRA SALIDA",MOVIMIENTOS!$B5="TRASIEGO",AND(MOVIMIENTOS!$B5="PROCESO",MOVIMIENTOS!$C5="Chancho"),AND(MOVIMIENTOS!$B5="REGALO",MOVIMIENTOS!$C5<>"Chancho"),AND(MOVIMIENTOS!$B5="VENTA",MOVIMIENTOS!$C5<>"Chancho"),AND(MOVIMIENTOS!$B5="AJUSTE",MOVIMIENTOS!$C5<>"Chancho",N(MOVIMIENTOS!$F5)<0))),IF(MOVIMIENTOS!$B5="AJUSTE",-N(MOVIMIENTOS!$F5),N(MOVIMIENTOS!$F5)),"") | O6: =IF(AND(MOVIMIENTOS!$B5<>"",NOT(AND(MOVIMIENTOS!$B5="PROCESO",MOVIMIENTOS!$C5<>"Chancho")),NOT(AND(MOVIMIENTOS!$B5="SALDO INICIAL",MOVIMIENTOS!$C5="Chancho"))),TRIM(IF(MOVIMIENTOS!$G5<>"",IF(MOVIMIENTOS!$B5="ENVÍO A SUPESA","G-"&MOVIMIENTOS!$G5,MOVIMIENTOS!$G5)&" ","")&IF(N(MOVIMIENTOS!$E5)>0,MOVIMIENTOS!$E5&" "&MOVIMIENTOS!$D5,"")),"") -> 8 jabas | P6: =N(P5)+N(M6)-N(N6) -> 120
A7: =IFERROR(INDEX(K$6:K$401,MATCH(ROW()-5,J$6:J$401,0)),"") -> 46214 | B7: =IFERROR(INDEX(L$6:L$401,MATCH(ROW()-5,J$6:J$401,0)),"") -> APERTURA (M) | C7: =IFERROR(INDEX(M$6:M$401,MATCH(ROW()-5,J$6:J$401,0)),"") -> 119 | D7: =IFERROR(INDEX(N$6:N$401,MATCH(ROW()-5,J$6:J$401,0)),"") | E7: =IFERROR(INDEX(O$6:O$401,MATCH(ROW()-5,J$6:J$401,0)),"") -> 7 jabas | F7: =IFERROR(INDEX(P$6:P$401,MATCH(ROW()-5,J$6:J$401,0)),"") -> 239 | J7: =IF(AND(MOVIMIENTOS!$B6<>"",NOT(AND(MOVIMIENTOS!$B6="PROCESO",MOVIMIENTOS!$C6<>"Chancho")),NOT(AND(MOVIMIENTOS!$B6="SALDO INICIAL",MOVIMIENTOS!$C6="Chancho"))),COUNT(J$5:J6)+1,"") -> 2 | K7: =IF(AND(MOVIMIENTOS!$B6<>"",NOT(AND(MOVIMIENTOS!$B6="PROCESO",MOVIMIENTOS!$C6<>"Chancho")),NOT(AND(MOVIMIENTOS!$B6="SALDO INICIAL",MOVIMIENTOS!$C6="Chancho"))),MOVIMIENTOS!$A6,"") -> 46214 | L7: =IF(AND(MOVIMIENTOS!$B6<>"",NOT(AND(MOVIMIENTOS!$B6="PROCESO",MOVIMIENTOS!$C6<>"Chancho")),NOT(AND(MOVIMIENTOS!$B6="SALDO INICIAL",MOVIMIENTOS!$C6="Chancho"))),IF(MOVIMIENTOS!$B6="SALDO INICIAL","APERTURA ("&MOVIMIENTOS!$C6&")",IF(MOVIMIENTOS!$B6="COMPRA","INGRESO (compra)",IF(MOVIMIENTOS!$B6="PROCESO","CHANCHO (proceso)",IF(MOVIMIENTOS!$B6="ENVÍO A SUPESA","ENVÍO SUPESA cal. "&MOVIMIENTOS!$C6,IF(MOVIMIENTOS!$B6="VENTA CHANCHO","VENTA CHANCHO",IF(MOVIMIENTOS!$B6="DEVOLUCIÓN","DEVOLUCIÓN cal. "&MOVIMIENTOS!$C6,IF(MOVIMIENTOS!$B6="TRASIEGO","TRASIEGO cal. "&MOVIMIENTOS!$C6,IF(MOVIMIENTOS!$B6="REGALO","REGALO "&MOVIMIENTOS!$C6,IF(MOVIMIENTOS!$B6="VENTA","VENTA "&MOVIMIENTOS!$C6,IF(MOVIMIENTOS!$B6="AJUSTE","AJUSTE inventario ("&MOVIMIENTOS!$C6&")",MOVIMIENTOS!$B6)))))))))),"") -> APERTURA (M) | M7: =IF(AND(AND(MOVIMIENTOS!$B6<>"",NOT(AND(MOVIMIENTOS!$B6="PROCESO",MOVIMIENTOS!$C6<>"Chancho")),NOT(AND(MOVIMIENTOS!$B6="SALDO INICIAL",MOVIMIENTOS!$C6="Chancho"))),OR(MOVIMIENTOS!$B6="SALDO INICIAL",MOVIMIENTOS!$B6="COMPRA",MOVIMIENTOS!$B6="REPROCESO",AND(MOVIMIENTOS!$B6="AJUSTE",MOVIMIENTOS!$C6<>"Chancho",N(MOVIMIENTOS!$F6)>=0))),N(MOVIMIENTOS!$F6),"") -> 119 | N7: =IF(AND(AND(MOVIMIENTOS!$B6<>"",NOT(AND(MOVIMIENTOS!$B6="PROCESO",MOVIMIENTOS!$C6<>"Chancho")),NOT(AND(MOVIMIENTOS!$B6="SALDO INICIAL",MOVIMIENTOS!$C6="Chancho"))),OR(MOVIMIENTOS!$B6="ENVÍO A SUPESA",MOVIMIENTOS!$B6="MALOGRADO",MOVIMIENTOS!$B6="OTRA SALIDA",MOVIMIENTOS!$B6="TRASIEGO",AND(MOVIMIENTOS!$B6="PROCESO",MOVIMIENTOS!$C6="Chancho"),AND(MOVIMIENTOS!$B6="REGALO",MOVIMIENTOS!$C6<>"Chancho"),AND(MOVIMIENTOS!$B6="VENTA",MOVIMIENTOS!$C6<>"Chancho"),AND(MOVIMIENTOS!$B6="AJUSTE",MOVIMIENTOS!$C6<>"Chancho",N(MOVIMIENTOS!$F6)<0))),IF(MOVIMIENTOS!$B6="AJUSTE",-N(MOVIMIENTOS!$F6),N(MOVIMIENTOS!$F6)),"") | O7: =IF(AND(MOVIMIENTOS!$B6<>"",NOT(AND(MOVIMIENTOS!$B6="PROCESO",MOVIMIENTOS!$C6<>"Chancho")),NOT(AND(MOVIMIENTOS!$B6="SALDO INICIAL",MOVIMIENTOS!$C6="Chancho"))),TRIM(IF(MOVIMIENTOS!$G6<>"",IF(MOVIMIENTOS!$B6="ENVÍO A SUPESA","G-"&MOVIMIENTOS!$G6,MOVIMIENTOS!$G6)&" ","")&IF(N(MOVIMIENTOS!$E6)>0,MOVIMIENTOS!$E6&" "&MOVIMIENTOS!$D6,"")),"") -> 7 jabas | P7: =N(P6)+N(M7)-N(N7) -> 239
A8: =IFERROR(INDEX(K$6:K$401,MATCH(ROW()-5,J$6:J$401,0)),"") -> 46215 | B8: =IFERROR(INDEX(L$6:L$401,MATCH(ROW()-5,J$6:J$401,0)),"") -> INGRESO (compra) | C8: =IFERROR(INDEX(M$6:M$401,MATCH(ROW()-5,J$6:J$401,0)),"") -> 2850 | D8: =IFERROR(INDEX(N$6:N$401,MATCH(ROW()-5,J$6:J$401,0)),"") | E8: =IFERROR(INDEX(O$6:O$401,MATCH(ROW()-5,J$6:J$401,0)),"") -> 30 sacos | F8: =IFERROR(INDEX(P$6:P$401,MATCH(ROW()-5,J$6:J$401,0)),"") -> 3089 | J8: =IF(AND(MOVIMIENTOS!$B7<>"",NOT(AND(MOVIMIENTOS!$B7="PROCESO",MOVIMIENTOS!$C7<>"Chancho")),NOT(AND(MOVIMIENTOS!$B7="SALDO INICIAL",MOVIMIENTOS!$C7="Chancho"))),COUNT(J$5:J7)+1,"") | K8: =IF(AND(MOVIMIENTOS!$B7<>"",NOT(AND(MOVIMIENTOS!$B7="PROCESO",MOVIMIENTOS!$C7<>"Chancho")),NOT(AND(MOVIMIENTOS!$B7="SALDO INICIAL",MOVIMIENTOS!$C7="Chancho"))),MOVIMIENTOS!$A7,"") | L8: =IF(AND(MOVIMIENTOS!$B7<>"",NOT(AND(MOVIMIENTOS!$B7="PROCESO",MOVIMIENTOS!$C7<>"Chancho")),NOT(AND(MOVIMIENTOS!$B7="SALDO INICIAL",MOVIMIENTOS!$C7="Chancho"))),IF(MOVIMIENTOS!$B7="SALDO INICIAL","APERTURA ("&MOVIMIENTOS!$C7&")",IF(MOVIMIENTOS!$B7="COMPRA","INGRESO (compra)",IF(MOVIMIENTOS!$B7="PROCESO","CHANCHO (proceso)",IF(MOVIMIENTOS!$B7="ENVÍO A SUPESA","ENVÍO SUPESA cal. "&MOVIMIENTOS!$C7,IF(MOVIMIENTOS!$B7="VENTA CHANCHO","VENTA CHANCHO",IF(MOVIMIENTOS!$B7="DEVOLUCIÓN","DEVOLUCIÓN cal. "&MOVIMIENTOS!$C7,IF(MOVIMIENTOS!$B7="TRASIEGO","TRASIEGO cal. "&MOVIMIENTOS!$C7,IF(MOVIMIENTOS!$B7="REGALO","REGALO "&MOVIMIENTOS!$C7,IF(MOVIMIENTOS!$B7="VENTA","VENTA "&MOVIMIENTOS!$C7,IF(MOVIMIENTOS!$B7="AJUSTE","AJUSTE inventario ("&MOVIMIENTOS!$C7&")",MOVIMIENTOS!$B7)))))))))),"") | M8: =IF(AND(AND(MOVIMIENTOS!$B7<>"",NOT(AND(MOVIMIENTOS!$B7="PROCESO",MOVIMIENTOS!$C7<>"Chancho")),NOT(AND(MOVIMIENTOS!$B7="SALDO INICIAL",MOVIMIENTOS!$C7="Chancho"))),OR(MOVIMIENTOS!$B7="SALDO INICIAL",MOVIMIENTOS!$B7="COMPRA",MOVIMIENTOS!$B7="REPROCESO",AND(MOVIMIENTOS!$B7="AJUSTE",MOVIMIENTOS!$C7<>"Chancho",N(MOVIMIENTOS!$F7)>=0))),N(MOVIMIENTOS!$F7),"") | N8: =IF(AND(AND(MOVIMIENTOS!$B7<>"",NOT(AND(MOVIMIENTOS!$B7="PROCESO",MOVIMIENTOS!$C7<>"Chancho")),NOT(AND(MOVIMIENTOS!$B7="SALDO INICIAL",MOVIMIENTOS!$C7="Chancho"))),OR(MOVIMIENTOS!$B7="ENVÍO A SUPESA",MOVIMIENTOS!$B7="MALOGRADO",MOVIMIENTOS!$B7="OTRA SALIDA",MOVIMIENTOS!$B7="TRASIEGO",AND(MOVIMIENTOS!$B7="PROCESO",MOVIMIENTOS!$C7="Chancho"),AND(MOVIMIENTOS!$B7="REGALO",MOVIMIENTOS!$C7<>"Chancho"),AND(MOVIMIENTOS!$B7="VENTA",MOVIMIENTOS!$C7<>"Chancho"),AND(MOVIMIENTOS!$B7="AJUSTE",MOVIMIENTOS!$C7<>"Chancho",N(MOVIMIENTOS!$F7)<0))),IF(MOVIMIENTOS!$B7="AJUSTE",-N(MOVIMIENTOS!$F7),N(MOVIMIENTOS!$F7)),"") | O8: =IF(AND(MOVIMIENTOS!$B7<>"",NOT(AND(MOVIMIENTOS!$B7="PROCESO",MOVIMIENTOS!$C7<>"Chancho")),NOT(AND(MOVIMIENTOS!$B7="SALDO INICIAL",MOVIMIENTOS!$C7="Chancho"))),TRIM(IF(MOVIMIENTOS!$G7<>"",IF(MOVIMIENTOS!$B7="ENVÍO A SUPESA","G-"&MOVIMIENTOS!$G7,MOVIMIENTOS!$G7)&" ","")&IF(N(MOVIMIENTOS!$E7)>0,MOVIMIENTOS!$E7&" "&MOVIMIENTOS!$D7,"")),"") | P8: =N(P7)+N(M8)-N(N8) -> 239
A9: =IFERROR(INDEX(K$6:K$401,MATCH(ROW()-5,J$6:J$401,0)),"") -> 46215 | B9: =IFERROR(INDEX(L$6:L$401,MATCH(ROW()-5,J$6:J$401,0)),"") -> CHANCHO (proceso) | C9: =IFERROR(INDEX(M$6:M$401,MATCH(ROW()-5,J$6:J$401,0)),"") | D9: =IFERROR(INDEX(N$6:N$401,MATCH(ROW()-5,J$6:J$401,0)),"") -> 570 | E9: =IFERROR(INDEX(O$6:O$401,MATCH(ROW()-5,J$6:J$401,0)),"") -> 6 sacos | F9: =IFERROR(INDEX(P$6:P$401,MATCH(ROW()-5,J$6:J$401,0)),"") -> 2519 | J9: =IF(AND(MOVIMIENTOS!$B8<>"",NOT(AND(MOVIMIENTOS!$B8="PROCESO",MOVIMIENTOS!$C8<>"Chancho")),NOT(AND(MOVIMIENTOS!$B8="SALDO INICIAL",MOVIMIENTOS!$C8="Chancho"))),COUNT(J$5:J8)+1,"") -> 3 | K9: =IF(AND(MOVIMIENTOS!$B8<>"",NOT(AND(MOVIMIENTOS!$B8="PROCESO",MOVIMIENTOS!$C8<>"Chancho")),NOT(AND(MOVIMIENTOS!$B8="SALDO INICIAL",MOVIMIENTOS!$C8="Chancho"))),MOVIMIENTOS!$A8,"") -> 46215 | L9: =IF(AND(MOVIMIENTOS!$B8<>"",NOT(AND(MOVIMIENTOS!$B8="PROCESO",MOVIMIENTOS!$C8<>"Chancho")),NOT(AND(MOVIMIENTOS!$B8="SALDO INICIAL",MOVIMIENTOS!$C8="Chancho"))),IF(MOVIMIENTOS!$B8="SALDO INICIAL","APERTURA ("&MOVIMIENTOS!$C8&")",IF(MOVIMIENTOS!$B8="COMPRA","INGRESO (compra)",IF(MOVIMIENTOS!$B8="PROCESO","CHANCHO (proceso)",IF(MOVIMIENTOS!$B8="ENVÍO A SUPESA","ENVÍO SUPESA cal. "&MOVIMIENTOS!$C8,IF(MOVIMIENTOS!$B8="VENTA CHANCHO","VENTA CHANCHO",IF(MOVIMIENTOS!$B8="DEVOLUCIÓN","DEVOLUCIÓN cal. "&MOVIMIENTOS!$C8,IF(MOVIMIENTOS!$B8="TRASIEGO","TRASIEGO cal. "&MOVIMIENTOS!$C8,IF(MOVIMIENTOS!$B8="REGALO","REGALO "&MOVIMIENTOS!$C8,IF(MOVIMIENTOS!$B8="VENTA","VENTA "&MOVIMIENTOS!$C8,IF(MOVIMIENTOS!$B8="AJUSTE","AJUSTE inventario ("&MOVIMIENTOS!$C8&")",MOVIMIENTOS!$B8)))))))))),"") -> INGRESO (compra) | M9: =IF(AND(AND(MOVIMIENTOS!$B8<>"",NOT(AND(MOVIMIENTOS!$B8="PROCESO",MOVIMIENTOS!$C8<>"Chancho")),NOT(AND(MOVIMIENTOS!$B8="SALDO INICIAL",MOVIMIENTOS!$C8="Chancho"))),OR(MOVIMIENTOS!$B8="SALDO INICIAL",MOVIMIENTOS!$B8="COMPRA",MOVIMIENTOS!$B8="REPROCESO",AND(MOVIMIENTOS!$B8="AJUSTE",MOVIMIENTOS!$C8<>"Chancho",N(MOVIMIENTOS!$F8)>=0))),N(MOVIMIENTOS!$F8),"") -> 2850 | N9: =IF(AND(AND(MOVIMIENTOS!$B8<>"",NOT(AND(MOVIMIENTOS!$B8="PROCESO",MOVIMIENTOS!$C8<>"Chancho")),NOT(AND(MOVIMIENTOS!$B8="SALDO INICIAL",MOVIMIENTOS!$C8="Chancho"))),OR(MOVIMIENTOS!$B8="ENVÍO A SUPESA",MOVIMIENTOS!$B8="MALOGRADO",MOVIMIENTOS!$B8="OTRA SALIDA",MOVIMIENTOS!$B8="TRASIEGO",AND(MOVIMIENTOS!$B8="PROCESO",MOVIMIENTOS!$C8="Chancho"),AND(MOVIMIENTOS!$B8="REGALO",MOVIMIENTOS!$C8<>"Chancho"),AND(MOVIMIENTOS!$B8="VENTA",MOVIMIENTOS!$C8<>"Chancho"),AND(MOVIMIENTOS!$B8="AJUSTE",MOVIMIENTOS!$C8<>"Chancho",N(MOVIMIENTOS!$F8)<0))),IF(MOVIMIENTOS!$B8="AJUSTE",-N(MOVIMIENTOS!$F8),N(MOVIMIENTOS!$F8)),"") | O9: =IF(AND(MOVIMIENTOS!$B8<>"",NOT(AND(MOVIMIENTOS!$B8="PROCESO",MOVIMIENTOS!$C8<>"Chancho")),NOT(AND(MOVIMIENTOS!$B8="SALDO INICIAL",MOVIMIENTOS!$C8="Chancho"))),TRIM(IF(MOVIMIENTOS!$G8<>"",IF(MOVIMIENTOS!$B8="ENVÍO A SUPESA","G-"&MOVIMIENTOS!$G8,MOVIMIENTOS!$G8)&" ","")&IF(N(MOVIMIENTOS!$E8)>0,MOVIMIENTOS!$E8&" "&MOVIMIENTOS!$D8,"")),"") -> 30 sacos | P9: =N(P8)+N(M9)-N(N9) -> 3089
A10: =IFERROR(INDEX(K$6:K$401,MATCH(ROW()-5,J$6:J$401,0)),"") -> 46215 | B10: =IFERROR(INDEX(L$6:L$401,MATCH(ROW()-5,J$6:J$401,0)),"") -> ENVÍO SUPESA cal. A | C10: =IFERROR(INDEX(M$6:M$401,MATCH(ROW()-5,J$6:J$401,0)),"") | D10: =IFERROR(INDEX(N$6:N$401,MATCH(ROW()-5,J$6:J$401,0)),"") -> 1005 | E10: =IFERROR(INDEX(O$6:O$401,MATCH(ROW()-5,J$6:J$401,0)),"") -> G-2977 67 jabas | F10: =IFERROR(INDEX(P$6:P$401,MATCH(ROW()-5,J$6:J$401,0)),"") -> 1514 | J10: =IF(AND(MOVIMIENTOS!$B9<>"",NOT(AND(MOVIMIENTOS!$B9="PROCESO",MOVIMIENTOS!$C9<>"Chancho")),NOT(AND(MOVIMIENTOS!$B9="SALDO INICIAL",MOVIMIENTOS!$C9="Chancho"))),COUNT(J$5:J9)+1,"") | K10: =IF(AND(MOVIMIENTOS!$B9<>"",NOT(AND(MOVIMIENTOS!$B9="PROCESO",MOVIMIENTOS!$C9<>"Chancho")),NOT(AND(MOVIMIENTOS!$B9="SALDO INICIAL",MOVIMIENTOS!$C9="Chancho"))),MOVIMIENTOS!$A9,"") | L10: =IF(AND(MOVIMIENTOS!$B9<>"",NOT(AND(MOVIMIENTOS!$B9="PROCESO",MOVIMIENTOS!$C9<>"Chancho")),NOT(AND(MOVIMIENTOS!$B9="SALDO INICIAL",MOVIMIENTOS!$C9="Chancho"))),IF(MOVIMIENTOS!$B9="SALDO INICIAL","APERTURA ("&MOVIMIENTOS!$C9&")",IF(MOVIMIENTOS!$B9="COMPRA","INGRESO (compra)",IF(MOVIMIENTOS!$B9="PROCESO","CHANCHO (proceso)",IF(MOVIMIENTOS!$B9="ENVÍO A SUPESA","ENVÍO SUPESA cal. "&MOVIMIENTOS!$C9,IF(MOVIMIENTOS!$B9="VENTA CHANCHO","VENTA CHANCHO",IF(MOVIMIENTOS!$B9="DEVOLUCIÓN","DEVOLUCIÓN cal. "&MOVIMIENTOS!$C9,IF(MOVIMIENTOS!$B9="TRASIEGO","TRASIEGO cal. "&MOVIMIENTOS!$C9,IF(MOVIMIENTOS!$B9="REGALO","REGALO "&MOVIMIENTOS!$C9,IF(MOVIMIENTOS!$B9="VENTA","VENTA "&MOVIMIENTOS!$C9,IF(MOVIMIENTOS!$B9="AJUSTE","AJUSTE inventario ("&MOVIMIENTOS!$C9&")",MOVIMIENTOS!$B9)))))))))),"") | M10: =IF(AND(AND(MOVIMIENTOS!$B9<>"",NOT(AND(MOVIMIENTOS!$B9="PROCESO",MOVIMIENTOS!$C9<>"Chancho")),NOT(AND(MOVIMIENTOS!$B9="SALDO INICIAL",MOVIMIENTOS!$C9="Chancho"))),OR(MOVIMIENTOS!$B9="SALDO INICIAL",MOVIMIENTOS!$B9="COMPRA",MOVIMIENTOS!$B9="REPROCESO",AND(MOVIMIENTOS!$B9="AJUSTE",MOVIMIENTOS!$C9<>"Chancho",N(MOVIMIENTOS!$F9)>=0))),N(MOVIMIENTOS!$F9),"") | N10: =IF(AND(AND(MOVIMIENTOS!$B9<>"",NOT(AND(MOVIMIENTOS!$B9="PROCESO",MOVIMIENTOS!$C9<>"Chancho")),NOT(AND(MOVIMIENTOS!$B9="SALDO INICIAL",MOVIMIENTOS!$C9="Chancho"))),OR(MOVIMIENTOS!$B9="ENVÍO A SUPESA",MOVIMIENTOS!$B9="MALOGRADO",MOVIMIENTOS!$B9="OTRA SALIDA",MOVIMIENTOS!$B9="TRASIEGO",AND(MOVIMIENTOS!$B9="PROCESO",MOVIMIENTOS!$C9="Chancho"),AND(MOVIMIENTOS!$B9="REGALO",MOVIMIENTOS!$C9<>"Chancho"),AND(MOVIMIENTOS!$B9="VENTA",MOVIMIENTOS!$C9<>"Chancho"),AND(MOVIMIENTOS!$B9="AJUSTE",MOVIMIENTOS!$C9<>"Chancho",N(MOVIMIENTOS!$F9)<0))),IF(MOVIMIENTOS!$B9="AJUSTE",-N(MOVIMIENTOS!$F9),N(MOVIMIENTOS!$F9)),"") | O10: =IF(AND(MOVIMIENTOS!$B9<>"",NOT(AND(MOVIMIENTOS!$B9="PROCESO",MOVIMIENTOS!$C9<>"Chancho")),NOT(AND(MOVIMIENTOS!$B9="SALDO INICIAL",MOVIMIENTOS!$C9="Chancho"))),TRIM(IF(MOVIMIENTOS!$G9<>"",IF(MOVIMIENTOS!$B9="ENVÍO A SUPESA","G-"&MOVIMIENTOS!$G9,MOVIMIENTOS!$G9)&" ","")&IF(N(MOVIMIENTOS!$E9)>0,MOVIMIENTOS!$E9&" "&MOVIMIENTOS!$D9,"")),"") | P10: =N(P9)+N(M10)-N(N10) -> 3089
A11: =IFERROR(INDEX(K$6:K$401,MATCH(ROW()-5,J$6:J$401,0)),"") -> 46215 | B11: =IFERROR(INDEX(L$6:L$401,MATCH(ROW()-5,J$6:J$401,0)),"") -> ENVÍO SUPESA cal. P | C11: =IFERROR(INDEX(M$6:M$401,MATCH(ROW()-5,J$6:J$401,0)),"") | D11: =IFERROR(INDEX(N$6:N$401,MATCH(ROW()-5,J$6:J$401,0)),"") -> 198 | E11: =IFERROR(INDEX(O$6:O$401,MATCH(ROW()-5,J$6:J$401,0)),"") -> G-2977 11 jabas | F11: =IFERROR(INDEX(P$6:P$401,MATCH(ROW()-5,J$6:J$401,0)),"") -> 1316 | J11: =IF(AND(MOVIMIENTOS!$B10<>"",NOT(AND(MOVIMIENTOS!$B10="PROCESO",MOVIMIENTOS!$C10<>"Chancho")),NOT(AND(MOVIMIENTOS!$B10="SALDO INICIAL",MOVIMIENTOS!$C10="Chancho"))),COUNT(J$5:J10)+1,"") | K11: =IF(AND(MOVIMIENTOS!$B10<>"",NOT(AND(MOVIMIENTOS!$B10="PROCESO",MOVIMIENTOS!$C10<>"Chancho")),NOT(AND(MOVIMIENTOS!$B10="SALDO INICIAL",MOVIMIENTOS!$C10="Chancho"))),MOVIMIENTOS!$A10,"") | L11: =IF(AND(MOVIMIENTOS!$B10<>"",NOT(AND(MOVIMIENTOS!$B10="PROCESO",MOVIMIENTOS!$C10<>"Chancho")),NOT(AND(MOVIMIENTOS!$B10="SALDO INICIAL",MOVIMIENTOS!$C10="Chancho"))),IF(MOVIMIENTOS!$B10="SALDO INICIAL","APERTURA ("&MOVIMIENTOS!$C10&")",IF(MOVIMIENTOS!$B10="COMPRA","INGRESO (compra)",IF(MOVIMIENTOS!$B10="PROCESO","CHANCHO (proceso)",IF(MOVIMIENTOS!$B10="ENVÍO A SUPESA","ENVÍO SUPESA cal. "&MOVIMIENTOS!$C10,IF(MOVIMIENTOS!$B10="VENTA CHANCHO","VENTA CHANCHO",IF(MOVIMIENTOS!$B10="DEVOLUCIÓN","DEVOLUCIÓN cal. "&MOVIMIENTOS!$C10,IF(MOVIMIENTOS!$B10="TRASIEGO","TRASIEGO cal. "&MOVIMIENTOS!$C10,IF(MOVIMIENTOS!$B10="REGALO","REGALO "&MOVIMIENTOS!$C10,IF(MOVIMIENTOS!$B10="VENTA","VENTA "&MOVIMIENTOS!$C10,IF(MOVIMIENTOS!$B10="AJUSTE","AJUSTE inventario ("&MOVIMIENTOS!$C10&")",MOVIMIENTOS!$B10)))))))))),"") | M11: =IF(AND(AND(MOVIMIENTOS!$B10<>"",NOT(AND(MOVIMIENTOS!$B10="PROCESO",MOVIMIENTOS!$C10<>"Chancho")),NOT(AND(MOVIMIENTOS!$B10="SALDO INICIAL",MOVIMIENTOS!$C10="Chancho"))),OR(MOVIMIENTOS!$B10="SALDO INICIAL",MOVIMIENTOS!$B10="COMPRA",MOVIMIENTOS!$B10="REPROCESO",AND(MOVIMIENTOS!$B10="AJUSTE",MOVIMIENTOS!$C10<>"Chancho",N(MOVIMIENTOS!$F10)>=0))),N(MOVIMIENTOS!$F10),"") | N11: =IF(AND(AND(MOVIMIENTOS!$B10<>"",NOT(AND(MOVIMIENTOS!$B10="PROCESO",MOVIMIENTOS!$C10<>"Chancho")),NOT(AND(MOVIMIENTOS!$B10="SALDO INICIAL",MOVIMIENTOS!$C10="Chancho"))),OR(MOVIMIENTOS!$B10="ENVÍO A SUPESA",MOVIMIENTOS!$B10="MALOGRADO",MOVIMIENTOS!$B10="OTRA SALIDA",MOVIMIENTOS!$B10="TRASIEGO",AND(MOVIMIENTOS!$B10="PROCESO",MOVIMIENTOS!$C10="Chancho"),AND(MOVIMIENTOS!$B10="REGALO",MOVIMIENTOS!$C10<>"Chancho"),AND(MOVIMIENTOS!$B10="VENTA",MOVIMIENTOS!$C10<>"Chancho"),AND(MOVIMIENTOS!$B10="AJUSTE",MOVIMIENTOS!$C10<>"Chancho",N(MOVIMIENTOS!$F10)<0))),IF(MOVIMIENTOS!$B10="AJUSTE",-N(MOVIMIENTOS!$F10),N(MOVIMIENTOS!$F10)),"") | O11: =IF(AND(MOVIMIENTOS!$B10<>"",NOT(AND(MOVIMIENTOS!$B10="PROCESO",MOVIMIENTOS!$C10<>"Chancho")),NOT(AND(MOVIMIENTOS!$B10="SALDO INICIAL",MOVIMIENTOS!$C10="Chancho"))),TRIM(IF(MOVIMIENTOS!$G10<>"",IF(MOVIMIENTOS!$B10="ENVÍO A SUPESA","G-"&MOVIMIENTOS!$G10,MOVIMIENTOS!$G10)&" ","")&IF(N(MOVIMIENTOS!$E10)>0,MOVIMIENTOS!$E10&" "&MOVIMIENTOS!$D10,"")),"") | P11: =N(P10)+N(M11)-N(N11) -> 3089
A12: =IFERROR(INDEX(K$6:K$401,MATCH(ROW()-5,J$6:J$401,0)),"") -> 46215 | B12: =IFERROR(INDEX(L$6:L$401,MATCH(ROW()-5,J$6:J$401,0)),"") -> ENVÍO SUPESA cal. C | C12: =IFERROR(INDEX(M$6:M$401,MATCH(ROW()-5,J$6:J$401,0)),"") | D12: =IFERROR(INDEX(N$6:N$401,MATCH(ROW()-5,J$6:J$401,0)),"") -> 204 | E12: =IFERROR(INDEX(O$6:O$401,MATCH(ROW()-5,J$6:J$401,0)),"") -> G-2977 12 jabas | F12: =IFERROR(INDEX(P$6:P$401,MATCH(ROW()-5,J$6:J$401,0)),"") -> 1112 | J12: =IF(AND(MOVIMIENTOS!$B11<>"",NOT(AND(MOVIMIENTOS!$B11="PROCESO",MOVIMIENTOS!$C11<>"Chancho")),NOT(AND(MOVIMIENTOS!$B11="SALDO INICIAL",MOVIMIENTOS!$C11="Chancho"))),COUNT(J$5:J11)+1,"") | K12: =IF(AND(MOVIMIENTOS!$B11<>"",NOT(AND(MOVIMIENTOS!$B11="PROCESO",MOVIMIENTOS!$C11<>"Chancho")),NOT(AND(MOVIMIENTOS!$B11="SALDO INICIAL",MOVIMIENTOS!$C11="Chancho"))),MOVIMIENTOS!$A11,"") | L12: =IF(AND(MOVIMIENTOS!$B11<>"",NOT(AND(MOVIMIENTOS!$B11="PROCESO",MOVIMIENTOS!$C11<>"Chancho")),NOT(AND(MOVIMIENTOS!$B11="SALDO INICIAL",MOVIMIENTOS!$C11="Chancho"))),IF(MOVIMIENTOS!$B11="SALDO INICIAL","APERTURA ("&MOVIMIENTOS!$C11&")",IF(MOVIMIENTOS!$B11="COMPRA","INGRESO (compra)",IF(MOVIMIENTOS!$B11="PROCESO","CHANCHO (proceso)",IF(MOVIMIENTOS!$B11="ENVÍO A SUPESA","ENVÍO SUPESA cal. "&MOVIMIENTOS!$C11,IF(MOVIMIENTOS!$B11="VENTA CHANCHO","VENTA CHANCHO",IF(MOVIMIENTOS!$B11="DEVOLUCIÓN","DEVOLUCIÓN cal. "&MOVIMIENTOS!$C11,IF(MOVIMIENTOS!$B11="TRASIEGO","TRASIEGO cal. "&MOVIMIENTOS!$C11,IF(MOVIMIENTOS!$B11="REGALO","REGALO "&MOVIMIENTOS!$C11,IF(MOVIMIENTOS!$B11="VENTA","VENTA "&MOVIMIENTOS!$C11,IF(MOVIMIENTOS!$B11="AJUSTE","AJUSTE inventario ("&MOVIMIENTOS!$C11&")",MOVIMIENTOS!$B11)))))))))),"") | M12: =IF(AND(AND(MOVIMIENTOS!$B11<>"",NOT(AND(MOVIMIENTOS!$B11="PROCESO",MOVIMIENTOS!$C11<>"Chancho")),NOT(AND(MOVIMIENTOS!$B11="SALDO INICIAL",MOVIMIENTOS!$C11="Chancho"))),OR(MOVIMIENTOS!$B11="SALDO INICIAL",MOVIMIENTOS!$B11="COMPRA",MOVIMIENTOS!$B11="REPROCESO",AND(MOVIMIENTOS!$B11="AJUSTE",MOVIMIENTOS!$C11<>"Chancho",N(MOVIMIENTOS!$F11)>=0))),N(MOVIMIENTOS!$F11),"") | N12: =IF(AND(AND(MOVIMIENTOS!$B11<>"",NOT(AND(MOVIMIENTOS!$B11="PROCESO",MOVIMIENTOS!$C11<>"Chancho")),NOT(AND(MOVIMIENTOS!$B11="SALDO INICIAL",MOVIMIENTOS!$C11="Chancho"))),OR(MOVIMIENTOS!$B11="ENVÍO A SUPESA",MOVIMIENTOS!$B11="MALOGRADO",MOVIMIENTOS!$B11="OTRA SALIDA",MOVIMIENTOS!$B11="TRASIEGO",AND(MOVIMIENTOS!$B11="PROCESO",MOVIMIENTOS!$C11="Chancho"),AND(MOVIMIENTOS!$B11="REGALO",MOVIMIENTOS!$C11<>"Chancho"),AND(MOVIMIENTOS!$B11="VENTA",MOVIMIENTOS!$C11<>"Chancho"),AND(MOVIMIENTOS!$B11="AJUSTE",MOVIMIENTOS!$C11<>"Chancho",N(MOVIMIENTOS!$F11)<0))),IF(MOVIMIENTOS!$B11="AJUSTE",-N(MOVIMIENTOS!$F11),N(MOVIMIENTOS!$F11)),"") | O12: =IF(AND(MOVIMIENTOS!$B11<>"",NOT(AND(MOVIMIENTOS!$B11="PROCESO",MOVIMIENTOS!$C11<>"Chancho")),NOT(AND(MOVIMIENTOS!$B11="SALDO INICIAL",MOVIMIENTOS!$C11="Chancho"))),TRIM(IF(MOVIMIENTOS!$G11<>"",IF(MOVIMIENTOS!$B11="ENVÍO A SUPESA","G-"&MOVIMIENTOS!$G11,MOVIMIENTOS!$G11)&" ","")&IF(N(MOVIMIENTOS!$E11)>0,MOVIMIENTOS!$E11&" "&MOVIMIENTOS!$D11,"")),"") | P12: =N(P11)+N(M12)-N(N12) -> 3089
A13: =IFERROR(INDEX(K$6:K$401,MATCH(ROW()-5,J$6:J$401,0)),"") -> 46215 | B13: =IFERROR(INDEX(L$6:L$401,MATCH(ROW()-5,J$6:J$401,0)),"") -> ENVÍO SUPESA cal. M | C13: =IFERROR(INDEX(M$6:M$401,MATCH(ROW()-5,J$6:J$401,0)),"") | D13: =IFERROR(INDEX(N$6:N$401,MATCH(ROW()-5,J$6:J$401,0)),"") -> 714 | E13: =IFERROR(INDEX(O$6:O$401,MATCH(ROW()-5,J$6:J$401,0)),"") -> G-2977 42 jabas | F13: =IFERROR(INDEX(P$6:P$401,MATCH(ROW()-5,J$6:J$401,0)),"") -> 398 | J13: =IF(AND(MOVIMIENTOS!$B12<>"",NOT(AND(MOVIMIENTOS!$B12="PROCESO",MOVIMIENTOS!$C12<>"Chancho")),NOT(AND(MOVIMIENTOS!$B12="SALDO INICIAL",MOVIMIENTOS!$C12="Chancho"))),COUNT(J$5:J12)+1,"") | K13: =IF(AND(MOVIMIENTOS!$B12<>"",NOT(AND(MOVIMIENTOS!$B12="PROCESO",MOVIMIENTOS!$C12<>"Chancho")),NOT(AND(MOVIMIENTOS!$B12="SALDO INICIAL",MOVIMIENTOS!$C12="Chancho"))),MOVIMIENTOS!$A12,"") | L13: =IF(AND(MOVIMIENTOS!$B12<>"",NOT(AND(MOVIMIENTOS!$B12="PROCESO",MOVIMIENTOS!$C12<>"Chancho")),NOT(AND(MOVIMIENTOS!$B12="SALDO INICIAL",MOVIMIENTOS!$C12="Chancho"))),IF(MOVIMIENTOS!$B12="SALDO INICIAL","APERTURA ("&MOVIMIENTOS!$C12&")",IF(MOVIMIENTOS!$B12="COMPRA","INGRESO (compra)",IF(MOVIMIENTOS!$B12="PROCESO","CHANCHO (proceso)",IF(MOVIMIENTOS!$B12="ENVÍO A SUPESA","ENVÍO SUPESA cal. "&MOVIMIENTOS!$C12,IF(MOVIMIENTOS!$B12="VENTA CHANCHO","VENTA CHANCHO",IF(MOVIMIENTOS!$B12="DEVOLUCIÓN","DEVOLUCIÓN cal. "&MOVIMIENTOS!$C12,IF(MOVIMIENTOS!$B12="TRASIEGO","TRASIEGO cal. "&MOVIMIENTOS!$C12,IF(MOVIMIENTOS!$B12="REGALO","REGALO "&MOVIMIENTOS!$C12,IF(MOVIMIENTOS!$B12="VENTA","VENTA "&MOVIMIENTOS!$C12,IF(MOVIMIENTOS!$B12="AJUSTE","AJUSTE inventario ("&MOVIMIENTOS!$C12&")",MOVIMIENTOS!$B12)))))))))),"") | M13: =IF(AND(AND(MOVIMIENTOS!$B12<>"",NOT(AND(MOVIMIENTOS!$B12="PROCESO",MOVIMIENTOS!$C12<>"Chancho")),NOT(AND(MOVIMIENTOS!$B12="SALDO INICIAL",MOVIMIENTOS!$C12="Chancho"))),OR(MOVIMIENTOS!$B12="SALDO INICIAL",MOVIMIENTOS!$B12="COMPRA",MOVIMIENTOS!$B12="REPROCESO",AND(MOVIMIENTOS!$B12="AJUSTE",MOVIMIENTOS!$C12<>"Chancho",N(MOVIMIENTOS!$F12)>=0))),N(MOVIMIENTOS!$F12),"") | N13: =IF(AND(AND(MOVIMIENTOS!$B12<>"",NOT(AND(MOVIMIENTOS!$B12="PROCESO",MOVIMIENTOS!$C12<>"Chancho")),NOT(AND(MOVIMIENTOS!$B12="SALDO INICIAL",MOVIMIENTOS!$C12="Chancho"))),OR(MOVIMIENTOS!$B12="ENVÍO A SUPESA",MOVIMIENTOS!$B12="MALOGRADO",MOVIMIENTOS!$B12="OTRA SALIDA",MOVIMIENTOS!$B12="TRASIEGO",AND(MOVIMIENTOS!$B12="PROCESO",MOVIMIENTOS!$C12="Chancho"),AND(MOVIMIENTOS!$B12="REGALO",MOVIMIENTOS!$C12<>"Chancho"),AND(MOVIMIENTOS!$B12="VENTA",MOVIMIENTOS!$C12<>"Chancho"),AND(MOVIMIENTOS!$B12="AJUSTE",MOVIMIENTOS!$C12<>"Chancho",N(MOVIMIENTOS!$F12)<0))),IF(MOVIMIENTOS!$B12="AJUSTE",-N(MOVIMIENTOS!$F12),N(MOVIMIENTOS!$F12)),"") | O13: =IF(AND(MOVIMIENTOS!$B12<>"",NOT(AND(MOVIMIENTOS!$B12="PROCESO",MOVIMIENTOS!$C12<>"Chancho")),NOT(AND(MOVIMIENTOS!$B12="SALDO INICIAL",MOVIMIENTOS!$C12="Chancho"))),TRIM(IF(MOVIMIENTOS!$G12<>"",IF(MOVIMIENTOS!$B12="ENVÍO A SUPESA","G-"&MOVIMIENTOS!$G12,MOVIMIENTOS!$G12)&" ","")&IF(N(MOVIMIENTOS!$E12)>0,MOVIMIENTOS!$E12&" "&MOVIMIENTOS!$D12,"")),"") | P13: =N(P12)+N(M13)-N(N13) -> 3089
A14: =IFERROR(INDEX(K$6:K$401,MATCH(ROW()-5,J$6:J$401,0)),"") -> 46216 | B14: =IFERROR(INDEX(L$6:L$401,MATCH(ROW()-5,J$6:J$401,0)),"") -> INGRESO (compra) | C14: =IFERROR(INDEX(M$6:M$401,MATCH(ROW()-5,J$6:J$401,0)),"") -> 3800 | D14: =IFERROR(INDEX(N$6:N$401,MATCH(ROW()-5,J$6:J$401,0)),"") | E14: =IFERROR(INDEX(O$6:O$401,MATCH(ROW()-5,J$6:J$401,0)),"") -> 40 sacos | F14: =IFERROR(INDEX(P$6:P$401,MATCH(ROW()-5,J$6:J$401,0)),"") -> 4198 | J14: =IF(AND(MOVIMIENTOS!$B13<>"",NOT(AND(MOVIMIENTOS!$B13="PROCESO",MOVIMIENTOS!$C13<>"Chancho")),NOT(AND(MOVIMIENTOS!$B13="SALDO INICIAL",MOVIMIENTOS!$C13="Chancho"))),COUNT(J$5:J13)+1,"") -> 4 | K14: =IF(AND(MOVIMIENTOS!$B13<>"",NOT(AND(MOVIMIENTOS!$B13="PROCESO",MOVIMIENTOS!$C13<>"Chancho")),NOT(AND(MOVIMIENTOS!$B13="SALDO INICIAL",MOVIMIENTOS!$C13="Chancho"))),MOVIMIENTOS!$A13,"") -> 46215 | L14: =IF(AND(MOVIMIENTOS!$B13<>"",NOT(AND(MOVIMIENTOS!$B13="PROCESO",MOVIMIENTOS!$C13<>"Chancho")),NOT(AND(MOVIMIENTOS!$B13="SALDO INICIAL",MOVIMIENTOS!$C13="Chancho"))),IF(MOVIMIENTOS!$B13="SALDO INICIAL","APERTURA ("&MOVIMIENTOS!$C13&")",IF(MOVIMIENTOS!$B13="COMPRA","INGRESO (compra)",IF(MOVIMIENTOS!$B13="PROCESO","CHANCHO (proceso)",IF(MOVIMIENTOS!$B13="ENVÍO A SUPESA","ENVÍO SUPESA cal. "&MOVIMIENTOS!$C13,IF(MOVIMIENTOS!$B13="VENTA CHANCHO","VENTA CHANCHO",IF(MOVIMIENTOS!$B13="DEVOLUCIÓN","DEVOLUCIÓN cal. "&MOVIMIENTOS!$C13,IF(MOVIMIENTOS!$B13="TRASIEGO","TRASIEGO cal. "&MOVIMIENTOS!$C13,IF(MOVIMIENTOS!$B13="REGALO","REGALO "&MOVIMIENTOS!$C13,IF(MOVIMIENTOS!$B13="VENTA","VENTA "&MOVIMIENTOS!$C13,IF(MOVIMIENTOS!$B13="AJUSTE","AJUSTE inventario ("&MOVIMIENTOS!$C13&")",MOVIMIENTOS!$B13)))))))))),"") -> CHANCHO (proceso) | M14: =IF(AND(AND(MOVIMIENTOS!$B13<>"",NOT(AND(MOVIMIENTOS!$B13="PROCESO",MOVIMIENTOS!$C13<>"Chancho")),NOT(AND(MOVIMIENTOS!$B13="SALDO INICIAL",MOVIMIENTOS!$C13="Chancho"))),OR(MOVIMIENTOS!$B13="SALDO INICIAL",MOVIMIENTOS!$B13="COMPRA",MOVIMIENTOS!$B13="REPROCESO",AND(MOVIMIENTOS!$B13="AJUSTE",MOVIMIENTOS!$C13<>"Chancho",N(MOVIMIENTOS!$F13)>=0))),N(MOVIMIENTOS!$F13),"") | N14: =IF(AND(AND(MOVIMIENTOS!$B13<>"",NOT(AND(MOVIMIENTOS!$B13="PROCESO",MOVIMIENTOS!$C13<>"Chancho")),NOT(AND(MOVIMIENTOS!$B13="SALDO INICIAL",MOVIMIENTOS!$C13="Chancho"))),OR(MOVIMIENTOS!$B13="ENVÍO A SUPESA",MOVIMIENTOS!$B13="MALOGRADO",MOVIMIENTOS!$B13="OTRA SALIDA",MOVIMIENTOS!$B13="TRASIEGO",AND(MOVIMIENTOS!$B13="PROCESO",MOVIMIENTOS!$C13="Chancho"),AND(MOVIMIENTOS!$B13="REGALO",MOVIMIENTOS!$C13<>"Chancho"),AND(MOVIMIENTOS!$B13="VENTA",MOVIMIENTOS!$C13<>"Chancho"),AND(MOVIMIENTOS!$B13="AJUSTE",MOVIMIENTOS!$C13<>"Chancho",N(MOVIMIENTOS!$F13)<0))),IF(MOVIMIENTOS!$B13="AJUSTE",-N(MOVIMIENTOS!$F13),N(MOVIMIENTOS!$F13)),"") -> 570 | O14: =IF(AND(MOVIMIENTOS!$B13<>"",NOT(AND(MOVIMIENTOS!$B13="PROCESO",MOVIMIENTOS!$C13<>"Chancho")),NOT(AND(MOVIMIENTOS!$B13="SALDO INICIAL",MOVIMIENTOS!$C13="Chancho"))),TRIM(IF(MOVIMIENTOS!$G13<>"",IF(MOVIMIENTOS!$B13="ENVÍO A SUPESA","G-"&MOVIMIENTOS!$G13,MOVIMIENTOS!$G13)&" ","")&IF(N(MOVIMIENTOS!$E13)>0,MOVIMIENTOS!$E13&" "&MOVIMIENTOS!$D13,"")),"") -> 6 sacos | P14: =N(P13)+N(M14)-N(N14) -> 2519
A15: =IFERROR(INDEX(K$6:K$401,MATCH(ROW()-5,J$6:J$401,0)),"") -> 46216 | B15: =IFERROR(INDEX(L$6:L$401,MATCH(ROW()-5,J$6:J$401,0)),"") -> CHANCHO (proceso) | C15: =IFERROR(INDEX(M$6:M$401,MATCH(ROW()-5,J$6:J$401,0)),"") | D15: =IFERROR(INDEX(N$6:N$401,MATCH(ROW()-5,J$6:J$401,0)),"") -> 190 | E15: =IFERROR(INDEX(O$6:O$401,MATCH(ROW()-5,J$6:J$401,0)),"") -> 2 sacos | F15: =IFERROR(INDEX(P$6:P$401,MATCH(ROW()-5,J$6:J$401,0)),"") -> 4008 | J15: =IF(AND(MOVIMIENTOS!$B14<>"",NOT(AND(MOVIMIENTOS!$B14="PROCESO",MOVIMIENTOS!$C14<>"Chancho")),NOT(AND(MOVIMIENTOS!$B14="SALDO INICIAL",MOVIMIENTOS!$C14="Chancho"))),COUNT(J$5:J14)+1,"") -> 5 | K15: =IF(AND(MOVIMIENTOS!$B14<>"",NOT(AND(MOVIMIENTOS!$B14="PROCESO",MOVIMIENTOS!$C14<>"Chancho")),NOT(AND(MOVIMIENTOS!$B14="SALDO INICIAL",MOVIMIENTOS!$C14="Chancho"))),MOVIMIENTOS!$A14,"") -> 46215 | L15: =IF(AND(MOVIMIENTOS!$B14<>"",NOT(AND(MOVIMIENTOS!$B14="PROCESO",MOVIMIENTOS!$C14<>"Chancho")),NOT(AND(MOVIMIENTOS!$B14="SALDO INICIAL",MOVIMIENTOS!$C14="Chancho"))),IF(MOVIMIENTOS!$B14="SALDO INICIAL","APERTURA ("&MOVIMIENTOS!$C14&")",IF(MOVIMIENTOS!$B14="COMPRA","INGRESO (compra)",IF(MOVIMIENTOS!$B14="PROCESO","CHANCHO (proceso)",IF(MOVIMIENTOS!$B14="ENVÍO A SUPESA","ENVÍO SUPESA cal. "&MOVIMIENTOS!$C14,IF(MOVIMIENTOS!$B14="VENTA CHANCHO","VENTA CHANCHO",IF(MOVIMIENTOS!$B14="DEVOLUCIÓN","DEVOLUCIÓN cal. "&MOVIMIENTOS!$C14,IF(MOVIMIENTOS!$B14="TRASIEGO","TRASIEGO cal. "&MOVIMIENTOS!$C14,IF(MOVIMIENTOS!$B14="REGALO","REGALO "&MOVIMIENTOS!$C14,IF(MOVIMIENTOS!$B14="VENTA","VENTA "&MOVIMIENTOS!$C14,IF(MOVIMIENTOS!$B14="AJUSTE","AJUSTE inventario ("&MOVIMIENTOS!$C14&")",MOVIMIENTOS!$B14)))))))))),"") -> ENVÍO SUPESA cal. A | M15: =IF(AND(AND(MOVIMIENTOS!$B14<>"",NOT(AND(MOVIMIENTOS!$B14="PROCESO",MOVIMIENTOS!$C14<>"Chancho")),NOT(AND(MOVIMIENTOS!$B14="SALDO INICIAL",MOVIMIENTOS!$C14="Chancho"))),OR(MOVIMIENTOS!$B14="SALDO INICIAL",MOVIMIENTOS!$B14="COMPRA",MOVIMIENTOS!$B14="REPROCESO",AND(MOVIMIENTOS!$B14="AJUSTE",MOVIMIENTOS!$C14<>"Chancho",N(MOVIMIENTOS!$F14)>=0))),N(MOVIMIENTOS!$F14),"") | N15: =IF(AND(AND(MOVIMIENTOS!$B14<>"",NOT(AND(MOVIMIENTOS!$B14="PROCESO",MOVIMIENTOS!$C14<>"Chancho")),NOT(AND(MOVIMIENTOS!$B14="SALDO INICIAL",MOVIMIENTOS!$C14="Chancho"))),OR(MOVIMIENTOS!$B14="ENVÍO A SUPESA",MOVIMIENTOS!$B14="MALOGRADO",MOVIMIENTOS!$B14="OTRA SALIDA",MOVIMIENTOS!$B14="TRASIEGO",AND(MOVIMIENTOS!$B14="PROCESO",MOVIMIENTOS!$C14="Chancho"),AND(MOVIMIENTOS!$B14="REGALO",MOVIMIENTOS!$C14<>"Chancho"),AND(MOVIMIENTOS!$B14="VENTA",MOVIMIENTOS!$C14<>"Chancho"),AND(MOVIMIENTOS!$B14="AJUSTE",MOVIMIENTOS!$C14<>"Chancho",N(MOVIMIENTOS!$F14)<0))),IF(MOVIMIENTOS!$B14="AJUSTE",-N(MOVIMIENTOS!$F14),N(MOVIMIENTOS!$F14)),"") -> 1005 | O15: =IF(AND(MOVIMIENTOS!$B14<>"",NOT(AND(MOVIMIENTOS!$B14="PROCESO",MOVIMIENTOS!$C14<>"Chancho")),NOT(AND(MOVIMIENTOS!$B14="SALDO INICIAL",MOVIMIENTOS!$C14="Chancho"))),TRIM(IF(MOVIMIENTOS!$G14<>"",IF(MOVIMIENTOS!$B14="ENVÍO A SUPESA","G-"&MOVIMIENTOS!$G14,MOVIMIENTOS!$G14)&" ","")&IF(N(MOVIMIENTOS!$E14)>0,MOVIMIENTOS!$E14&" "&MOVIMIENTOS!$D14,"")),"") -> G-2977 67 jabas | P15: =N(P14)+N(M15)-N(N15) -> 1514
A16: =IFERROR(INDEX(K$6:K$401,MATCH(ROW()-5,J$6:J$401,0)),"") -> 46216 | B16: =IFERROR(INDEX(L$6:L$401,MATCH(ROW()-5,J$6:J$401,0)),"") -> ENVÍO SUPESA cal. A | C16: =IFERROR(INDEX(M$6:M$401,MATCH(ROW()-5,J$6:J$401,0)),"") | D16: =IFERROR(INDEX(N$6:N$401,MATCH(ROW()-5,J$6:J$401,0)),"") -> 1005 | E16: =IFERROR(INDEX(O$6:O$401,MATCH(ROW()-5,J$6:J$401,0)),"") -> G-2980 67 jabas | F16: =IFERROR(INDEX(P$6:P$401,MATCH(ROW()-5,J$6:J$401,0)),"") -> 3003 | J16: =IF(AND(MOVIMIENTOS!$B15<>"",NOT(AND(MOVIMIENTOS!$B15="PROCESO",MOVIMIENTOS!$C15<>"Chancho")),NOT(AND(MOVIMIENTOS!$B15="SALDO INICIAL",MOVIMIENTOS!$C15="Chancho"))),COUNT(J$5:J15)+1,"") -> 6 | K16: =IF(AND(MOVIMIENTOS!$B15<>"",NOT(AND(MOVIMIENTOS!$B15="PROCESO",MOVIMIENTOS!$C15<>"Chancho")),NOT(AND(MOVIMIENTOS!$B15="SALDO INICIAL",MOVIMIENTOS!$C15="Chancho"))),MOVIMIENTOS!$A15,"") -> 46215 | L16: =IF(AND(MOVIMIENTOS!$B15<>"",NOT(AND(MOVIMIENTOS!$B15="PROCESO",MOVIMIENTOS!$C15<>"Chancho")),NOT(AND(MOVIMIENTOS!$B15="SALDO INICIAL",MOVIMIENTOS!$C15="Chancho"))),IF(MOVIMIENTOS!$B15="SALDO INICIAL","APERTURA ("&MOVIMIENTOS!$C15&")",IF(MOVIMIENTOS!$B15="COMPRA","INGRESO (compra)",IF(MOVIMIENTOS!$B15="PROCESO","CHANCHO (proceso)",IF(MOVIMIENTOS!$B15="ENVÍO A SUPESA","ENVÍO SUPESA cal. "&MOVIMIENTOS!$C15,IF(MOVIMIENTOS!$B15="VENTA CHANCHO","VENTA CHANCHO",IF(MOVIMIENTOS!$B15="DEVOLUCIÓN","DEVOLUCIÓN cal. "&MOVIMIENTOS!$C15,IF(MOVIMIENTOS!$B15="TRASIEGO","TRASIEGO cal. "&MOVIMIENTOS!$C15,IF(MOVIMIENTOS!$B15="REGALO","REGALO "&MOVIMIENTOS!$C15,IF(MOVIMIENTOS!$B15="VENTA","VENTA "&MOVIMIENTOS!$C15,IF(MOVIMIENTOS!$B15="AJUSTE","AJUSTE inventario ("&MOVIMIENTOS!$C15&")",MOVIMIENTOS!$B15)))))))))),"") -> ENVÍO SUPESA cal. P | M16: =IF(AND(AND(MOVIMIENTOS!$B15<>"",NOT(AND(MOVIMIENTOS!$B15="PROCESO",MOVIMIENTOS!$C15<>"Chancho")),NOT(AND(MOVIMIENTOS!$B15="SALDO INICIAL",MOVIMIENTOS!$C15="Chancho"))),OR(MOVIMIENTOS!$B15="SALDO INICIAL",MOVIMIENTOS!$B15="COMPRA",MOVIMIENTOS!$B15="REPROCESO",AND(MOVIMIENTOS!$B15="AJUSTE",MOVIMIENTOS!$C15<>"Chancho",N(MOVIMIENTOS!$F15)>=0))),N(MOVIMIENTOS!$F15),"") | N16: =IF(AND(AND(MOVIMIENTOS!$B15<>"",NOT(AND(MOVIMIENTOS!$B15="PROCESO",MOVIMIENTOS!$C15<>"Chancho")),NOT(AND(MOVIMIENTOS!$B15="SALDO INICIAL",MOVIMIENTOS!$C15="Chancho"))),OR(MOVIMIENTOS!$B15="ENVÍO A SUPESA",MOVIMIENTOS!$B15="MALOGRADO",MOVIMIENTOS!$B15="OTRA SALIDA",MOVIMIENTOS!$B15="TRASIEGO",AND(MOVIMIENTOS!$B15="PROCESO",MOVIMIENTOS!$C15="Chancho"),AND(MOVIMIENTOS!$B15="REGALO",MOVIMIENTOS!$C15<>"Chancho"),AND(MOVIMIENTOS!$B15="VENTA",MOVIMIENTOS!$C15<>"Chancho"),AND(MOVIMIENTOS!$B15="AJUSTE",MOVIMIENTOS!$C15<>"Chancho",N(MOVIMIENTOS!$F15)<0))),IF(MOVIMIENTOS!$B15="AJUSTE",-N(MOVIMIENTOS!$F15),N(MOVIMIENTOS!$F15)),"") -> 198 | O16: =IF(AND(MOVIMIENTOS!$B15<>"",NOT(AND(MOVIMIENTOS!$B15="PROCESO",MOVIMIENTOS!$C15<>"Chancho")),NOT(AND(MOVIMIENTOS!$B15="SALDO INICIAL",MOVIMIENTOS!$C15="Chancho"))),TRIM(IF(MOVIMIENTOS!$G15<>"",IF(MOVIMIENTOS!$B15="ENVÍO A SUPESA","G-"&MOVIMIENTOS!$G15,MOVIMIENTOS!$G15)&" ","")&IF(N(MOVIMIENTOS!$E15)>0,MOVIMIENTOS!$E15&" "&MOVIMIENTOS!$D15,"")),"") -> G-2977 11 jabas | P16: =N(P15)+N(M16)-N(N16) -> 1316
A17: =IFERROR(INDEX(K$6:K$401,MATCH(ROW()-5,J$6:J$401,0)),"") -> 46216 | B17: =IFERROR(INDEX(L$6:L$401,MATCH(ROW()-5,J$6:J$401,0)),"") -> ENVÍO SUPESA cal. P | C17: =IFERROR(INDEX(M$6:M$401,MATCH(ROW()-5,J$6:J$401,0)),"") | D17: =IFERROR(INDEX(N$6:N$401,MATCH(ROW()-5,J$6:J$401,0)),"") -> 198 | E17: =IFERROR(INDEX(O$6:O$401,MATCH(ROW()-5,J$6:J$401,0)),"") -> G-2980 11 jabas | F17: =IFERROR(INDEX(P$6:P$401,MATCH(ROW()-5,J$6:J$401,0)),"") -> 2805 | J17: =IF(AND(MOVIMIENTOS!$B16<>"",NOT(AND(MOVIMIENTOS!$B16="PROCESO",MOVIMIENTOS!$C16<>"Chancho")),NOT(AND(MOVIMIENTOS!$B16="SALDO INICIAL",MOVIMIENTOS!$C16="Chancho"))),COUNT(J$5:J16)+1,"") -> 7 | K17: =IF(AND(MOVIMIENTOS!$B16<>"",NOT(AND(MOVIMIENTOS!$B16="PROCESO",MOVIMIENTOS!$C16<>"Chancho")),NOT(AND(MOVIMIENTOS!$B16="SALDO INICIAL",MOVIMIENTOS!$C16="Chancho"))),MOVIMIENTOS!$A16,"") -> 46215 | L17: =IF(AND(MOVIMIENTOS!$B16<>"",NOT(AND(MOVIMIENTOS!$B16="PROCESO",MOVIMIENTOS!$C16<>"Chancho")),NOT(AND(MOVIMIENTOS!$B16="SALDO INICIAL",MOVIMIENTOS!$C16="Chancho"))),IF(MOVIMIENTOS!$B16="SALDO INICIAL","APERTURA ("&MOVIMIENTOS!$C16&")",IF(MOVIMIENTOS!$B16="COMPRA","INGRESO (compra)",IF(MOVIMIENTOS!$B16="PROCESO","CHANCHO (proceso)",IF(MOVIMIENTOS!$B16="ENVÍO A SUPESA","ENVÍO SUPESA cal. "&MOVIMIENTOS!$C16,IF(MOVIMIENTOS!$B16="VENTA CHANCHO","VENTA CHANCHO",IF(MOVIMIENTOS!$B16="DEVOLUCIÓN","DEVOLUCIÓN cal. "&MOVIMIENTOS!$C16,IF(MOVIMIENTOS!$B16="TRASIEGO","TRASIEGO cal. "&MOVIMIENTOS!$C16,IF(MOVIMIENTOS!$B16="REGALO","REGALO "&MOVIMIENTOS!$C16,IF(MOVIMIENTOS!$B16="VENTA","VENTA "&MOVIMIENTOS!$C16,IF(MOVIMIENTOS!$B16="AJUSTE","AJUSTE inventario ("&MOVIMIENTOS!$C16&")",MOVIMIENTOS!$B16)))))))))),"") -> ENVÍO SUPESA cal. C | M17: =IF(AND(AND(MOVIMIENTOS!$B16<>"",NOT(AND(MOVIMIENTOS!$B16="PROCESO",MOVIMIENTOS!$C16<>"Chancho")),NOT(AND(MOVIMIENTOS!$B16="SALDO INICIAL",MOVIMIENTOS!$C16="Chancho"))),OR(MOVIMIENTOS!$B16="SALDO INICIAL",MOVIMIENTOS!$B16="COMPRA",MOVIMIENTOS!$B16="REPROCESO",AND(MOVIMIENTOS!$B16="AJUSTE",MOVIMIENTOS!$C16<>"Chancho",N(MOVIMIENTOS!$F16)>=0))),N(MOVIMIENTOS!$F16),"") | N17: =IF(AND(AND(MOVIMIENTOS!$B16<>"",NOT(AND(MOVIMIENTOS!$B16="PROCESO",MOVIMIENTOS!$C16<>"Chancho")),NOT(AND(MOVIMIENTOS!$B16="SALDO INICIAL",MOVIMIENTOS!$C16="Chancho"))),OR(MOVIMIENTOS!$B16="ENVÍO A SUPESA",MOVIMIENTOS!$B16="MALOGRADO",MOVIMIENTOS!$B16="OTRA SALIDA",MOVIMIENTOS!$B16="TRASIEGO",AND(MOVIMIENTOS!$B16="PROCESO",MOVIMIENTOS!$C16="Chancho"),AND(MOVIMIENTOS!$B16="REGALO",MOVIMIENTOS!$C16<>"Chancho"),AND(MOVIMIENTOS!$B16="VENTA",MOVIMIENTOS!$C16<>"Chancho"),AND(MOVIMIENTOS!$B16="AJUSTE",MOVIMIENTOS!$C16<>"Chancho",N(MOVIMIENTOS!$F16)<0))),IF(MOVIMIENTOS!$B16="AJUSTE",-N(MOVIMIENTOS!$F16),N(MOVIMIENTOS!$F16)),"") -> 204 | O17: =IF(AND(MOVIMIENTOS!$B16<>"",NOT(AND(MOVIMIENTOS!$B16="PROCESO",MOVIMIENTOS!$C16<>"Chancho")),NOT(AND(MOVIMIENTOS!$B16="SALDO INICIAL",MOVIMIENTOS!$C16="Chancho"))),TRIM(IF(MOVIMIENTOS!$G16<>"",IF(MOVIMIENTOS!$B16="ENVÍO A SUPESA","G-"&MOVIMIENTOS!$G16,MOVIMIENTOS!$G16)&" ","")&IF(N(MOVIMIENTOS!$E16)>0,MOVIMIENTOS!$E16&" "&MOVIMIENTOS!$D16,"")),"") -> G-2977 12 jabas | P17: =N(P16)+N(M17)-N(N17) -> 1112
... A401: =IFERROR(INDEX(K$6:K$401,MATCH(ROW()-5,J$6:J$401,0)),"") | B401: =IFERROR(INDEX(L$6:L$401,MATCH(ROW()-5,J$6:J$401,0)),"") | C401: =IFERROR(INDEX(M$6:M$401,MATCH(ROW()-5,J$6:J$401,0)),"") | D401: =IFERROR(INDEX(N$6:N$401,MATCH(ROW()-5,J$6:J$401,0)),"") | E401: =IFERROR(INDEX(O$6:O$401,MATCH(ROW()-5,J$6:J$401,0)),"") | F401: =IFERROR(INDEX(P$6:P$401,MATCH(ROW()-5,J$6:J$401,0)),"") | J401: =IF(AND(MOVIMIENTOS!$B400<>"",NOT(AND(MOVIMIENTOS!$B400="PROCESO",MOVIMIENTOS!$C400<>"Chancho")),NOT(AND(MOVIMIENTOS!$B400="SALDO INICIAL",MOVIMIENTOS!$C400="Chancho"))),COUNT(J$5:J400)+1,"") | K401: =IF(AND(MOVIMIENTOS!$B400<>"",NOT(AND(MOVIMIENTOS!$B400="PROCESO",MOVIMIENTOS!$C400<>"Chancho")),NOT(AND(MOVIMIENTOS!$B400="SALDO INICIAL",MOVIMIENTOS!$C400="Chancho"))),MOVIMIENTOS!$A400,"") | L401: =IF(AND(MOVIMIENTOS!$B400<>"",NOT(AND(MOVIMIENTOS!$B400="PROCESO",MOVIMIENTOS!$C400<>"Chancho")),NOT(AND(MOVIMIENTOS!$B400="SALDO INICIAL",MOVIMIENTOS!$C400="Chancho"))),IF(MOVIMIENTOS!$B400="SALDO INICIAL","APERTURA ("&MOVIMIENTOS!$C400&")",IF(MOVIMIENTOS!$B400="COMPRA","INGRESO (compra)",IF(MOVIMIENTOS!$B400="PROCESO","CHANCHO (proceso)",IF(MOVIMIENTOS!$B400="ENVÍO A SUPESA","ENVÍO SUPESA cal. "&MOVIMIENTOS!$C400,IF(MOVIMIENTOS!$B400="VENTA CHANCHO","VENTA CHANCHO",IF(MOVIMIENTOS!$B400="DEVOLUCIÓN","DEVOLUCIÓN cal. "&MOVIMIENTOS!$C400,IF(MOVIMIENTOS!$B400="TRASIEGO","TRASIEGO cal. "&MOVIMIENTOS!$C400,IF(MOVIMIENTOS!$B400="REGALO","REGALO "&MOVIMIENTOS!$C400,IF(MOVIMIENTOS!$B400="VENTA","VENTA "&MOVIMIENTOS!$C400,IF(MOVIMIENTOS!$B400="AJUSTE","AJUSTE inventario ("&MOVIMIENTOS!$C400&")",MOVIMIENTOS!$B400)))))))))),"") | M401: =IF(AND(AND(MOVIMIENTOS!$B400<>"",NOT(AND(MOVIMIENTOS!$B400="PROCESO",MOVIMIENTOS!$C400<>"Chancho")),NOT(AND(MOVIMIENTOS!$B400="SALDO INICIAL",MOVIMIENTOS!$C400="Chancho"))),OR(MOVIMIENTOS!$B400="SALDO INICIAL",MOVIMIENTOS!$B400="COMPRA",MOVIMIENTOS!$B400="REPROCESO",AND(MOVIMIENTOS!$B400="AJUSTE",MOVIMIENTOS!$C400<>"Chancho",N(MOVIMIENTOS!$F400)>=0))),N(MOVIMIENTOS!$F400),"") | N401: =IF(AND(AND(MOVIMIENTOS!$B400<>"",NOT(AND(MOVIMIENTOS!$B400="PROCESO",MOVIMIENTOS!$C400<>"Chancho")),NOT(AND(MOVIMIENTOS!$B400="SALDO INICIAL",MOVIMIENTOS!$C400="Chancho"))),OR(MOVIMIENTOS!$B400="ENVÍO A SUPESA",MOVIMIENTOS!$B400="MALOGRADO",MOVIMIENTOS!$B400="OTRA SALIDA",MOVIMIENTOS!$B400="TRASIEGO",AND(MOVIMIENTOS!$B400="PROCESO",MOVIMIENTOS!$C400="Chancho"),AND(MOVIMIENTOS!$B400="REGALO",MOVIMIENTOS!$C400<>"Chancho"),AND(MOVIMIENTOS!$B400="VENTA",MOVIMIENTOS!$C400<>"Chancho"),AND(MOVIMIENTOS!$B400="AJUSTE",MOVIMIENTOS!$C400<>"Chancho",N(MOVIMIENTOS!$F400)<0))),IF(MOVIMIENTOS!$B400="AJUSTE",-N(MOVIMIENTOS!$F400),N(MOVIMIENTOS!$F400)),"") | O401: =IF(AND(MOVIMIENTOS!$B400<>"",NOT(AND(MOVIMIENTOS!$B400="PROCESO",MOVIMIENTOS!$C400<>"Chancho")),NOT(AND(MOVIMIENTOS!$B400="SALDO INICIAL",MOVIMIENTOS!$C400="Chancho"))),TRIM(IF(MOVIMIENTOS!$G400<>"",IF(MOVIMIENTOS!$B400="ENVÍO A SUPESA","G-"&MOVIMIENTOS!$G400,MOVIMIENTOS!$G400)&" ","")&IF(N(MOVIMIENTOS!$E400)>0,MOVIMIENTOS!$E400&" "&MOVIMIENTOS!$D400,"")),"") | P401: =N(P400)+N(M401)-N(N401) -> 6138.5

Sheet SALDO DIARIO
A1: AGRO PACAYALES · PLANTA CAMOTE 2026 | SALDO DIARIO — lo que queda en almacén al cierre de cada día
A2: Automático. Cada fila = cierre del día: jabas por calidad para contar el almacén, sacos de chancho y kg del kardex. La última fila con datos es tu stock de HOY: con eso sabes si te alcanza para el envío de mañana.
A4: Fecha | B4: A (jabas) | C4: P (jabas) | D4: C (jabas) | E4: M (jabas) | F4: Chancho (sacos) | G4: TOTAL jabas | H4: Stock Kg
A5: =IFERROR(INDEX(K$5:K$400,MATCH(ROW()-4,J$5:J$400,0)),"") -> 46214 | B5: =IF($A5="","",SUMPRODUCT((MOVIMIENTOS!$B$5:$B$400="SALDO INICIAL")*(MOVIMIENTOS!$C$5:$C$400="A")*(MOVIMIENTOS!$D$5:$D$400="jabas")*(ROW(MOVIMIENTOS!$B$5:$B$400)<=$L5)*MOVIMIENTOS!$E$5:$E$400)+SUMPRODUCT((MOVIMIENTOS!$B$5:$B$400="PROCESO")*(MOVIMIENTOS!$C$5:$C$400="A")*(MOVIMIENTOS!$D$5:$D$400="jabas")*(ROW(MOVIMIENTOS!$B$5:$B$400)<=$L5)*MOVIMIENTOS!$E$5:$E$400)-SUMPRODUCT((MOVIMIENTOS!$B$5:$B$400="ENVÍO A SUPESA")*(MOVIMIENTOS!$C$5:$C$400="A")*(MOVIMIENTOS!$D$5:$D$400="jabas")*(ROW(MOVIMIENTOS!$B$5:$B$400)<=$L5)*MOVIMIENTOS!$E$5:$E$400)+SUMPRODUCT((MOVIMIENTOS!$B$5:$B$400="DEVOLUCIÓN")*(MOVIMIENTOS!$C$5:$C$400="A")*(MOVIMIENTOS!$D$5:$D$400="jabas")*(ROW(MOVIMIENTOS!$B$5:$B$400)<=$L5)*MOVIMIENTOS!$E$5:$E$400)-SUMPRODUCT((MOVIMIENTOS!$B$5:$B$400="TRASIEGO")*(MOVIMIENTOS!$C$5:$C$400="A")*(MOVIMIENTOS!$D$5:$D$400="jabas")*(ROW(MOVIMIENTOS!$B$5:$B$400)<=$L5)*MOVIMIENTOS!$E$5:$E$400)-SUMPRODUCT((MOVIMIENTOS!$B$5:$B$400="REGALO")*(MOVIMIENTOS!$C$5:$C$400="A")*(MOVIMIENTOS!$D$5:$D$400="jabas")*(ROW(MOVIMIENTOS!$B$5:$B$400)<=$L5)*MOVIMIENTOS!$E$5:$E$400)-SUMPRODUCT((MOVIMIENTOS!$B$5:$B$400="VENTA")*(MOVIMIENTOS!$C$5:$C$400="A")*(MOVIMIENTOS!$D$5:$D$400="jabas")*(ROW(MOVIMIENTOS!$B$5:$B$400)<=$L5)*MOVIMIENTOS!$E$5:$E$400)+SUMPRODUCT((MOVIMIENTOS!$B$5:$B$400="AJUSTE")*(MOVIMIENTOS!$C$5:$C$400="A")*(MOVIMIENTOS!$D$5:$D$400="jabas")*(ROW(MOVIMIENTOS!$B$5:$B$400)<=$L5)*MOVIMIENTOS!$E$5:$E$400)) -> 8 | C5: =IF($A5="","",SUMPRODUCT((MOVIMIENTOS!$B$5:$B$400="SALDO INICIAL")*(MOVIMIENTOS!$C$5:$C$400="P")*(MOVIMIENTOS!$D$5:$D$400="jabas")*(ROW(MOVIMIENTOS!$B$5:$B$400)<=$L5)*MOVIMIENTOS!$E$5:$E$400)+SUMPRODUCT((MOVIMIENTOS!$B$5:$B$400="PROCESO")*(MOVIMIENTOS!$C$5:$C$400="P")*(MOVIMIENTOS!$D$5:$D$400="jabas")*(ROW(MOVIMIENTOS!$B$5:$B$400)<=$L5)*MOVIMIENTOS!$E$5:$E$400)-SUMPRODUCT((MOVIMIENTOS!$B$5:$B$400="ENVÍO A SUPESA")*(MOVIMIENTOS!$C$5:$C$400="P")*(MOVIMIENTOS!$D$5:$D$400="jabas")*(ROW(MOVIMIENTOS!$B$5:$B$400)<=$L5)*MOVIMIENTOS!$E$5:$E$400)+SUMPRODUCT((MOVIMIENTOS!$B$5:$B$400="DEVOLUCIÓN")*(MOVIMIENTOS!$C$5:$C$400="P")*(MOVIMIENTOS!$D$5:$D$400="jabas")*(ROW(MOVIMIENTOS!$B$5:$B$400)<=$L5)*MOVIMIENTOS!$E$5:$E$400)-SUMPRODUCT((MOVIMIENTOS!$B$5:$B$400="TRASIEGO")*(MOVIMIENTOS!$C$5:$C$400="P")*(MOVIMIENTOS!$D$5:$D$400="jabas")*(ROW(MOVIMIENTOS!$B$5:$B$400)<=$L5)*MOVIMIENTOS!$E$5:$E$400)-SUMPRODUCT((MOVIMIENTOS!$B$5:$B$400="REGALO")*(MOVIMIENTOS!$C$5:$C$400="P")*(MOVIMIENTOS!$D$5:$D$400="jabas")*(ROW(MOVIMIENTOS!$B$5:$B$400)<=$L5)*MOVIMIENTOS!$E$5:$E$400)-SUMPRODUCT((MOVIMIENTOS!$B$5:$B$400="VENTA")*(MOVIMIENTOS!$C$5:$C$400="P")*(MOVIMIENTOS!$D$5:$D$400="jabas")*(ROW(MOVIMIENTOS!$B$5:$B$400)<=$L5)*MOVIMIENTOS!$E$5:$E$400)+SUMPRODUCT((MOVIMIENTOS!$B$5:$B$400="AJUSTE")*(MOVIMIENTOS!$C$5:$C$400="P")*(MOVIMIENTOS!$D$5:$D$400="jabas")*(ROW(MOVIMIENTOS!$B$5:$B$400)<=$L5)*MOVIMIENTOS!$E$5:$E$400)) -> 0 | D5: =IF($A5="","",SUMPRODUCT((MOVIMIENTOS!$B$5:$B$400="SALDO INICIAL")*(MOVIMIENTOS!$C$5:$C$400="C")*(MOVIMIENTOS!$D$5:$D$400="jabas")*(ROW(MOVIMIENTOS!$B$5:$B$400)<=$L5)*MOVIMIENTOS!$E$5:$E$400)+SUMPRODUCT((MOVIMIENTOS!$B$5:$B$400="PROCESO")*(MOVIMIENTOS!$C$5:$C$400="C")*(MOVIMIENTOS!$D$5:$D$400="jabas")*(ROW(MOVIMIENTOS!$B$5:$B$400)<=$L5)*MOVIMIENTOS!$E$5:$E$400)-SUMPRODUCT((MOVIMIENTOS!$B$5:$B$400="ENVÍO A SUPESA")*(MOVIMIENTOS!$C$5:$C$400="C")*(MOVIMIENTOS!$D$5:$D$400="jabas")*(ROW(MOVIMIENTOS!$B$5:$B$400)<=$L5)*MOVIMIENTOS!$E$5:$E$400)+SUMPRODUCT((MOVIMIENTOS!$B$5:$B$400="DEVOLUCIÓN")*(MOVIMIENTOS!$C$5:$C$400="C")*(MOVIMIENTOS!$D$5:$D$400="jabas")*(ROW(MOVIMIENTOS!$B$5:$B$400)<=$L5)*MOVIMIENTOS!$E$5:$E$400)-SUMPRODUCT((MOVIMIENTOS!$B$5:$B$400="TRASIEGO")*(MOVIMIENTOS!$C$5:$C$400="C")*(MOVIMIENTOS!$D$5:$D$400="jabas")*(ROW(MOVIMIENTOS!$B$5:$B$400)<=$L5)*MOVIMIENTOS!$E$5:$E$400)-SUMPRODUCT((MOVIMIENTOS!$B$5:$B$400="REGALO")*(MOVIMIENTOS!$C$5:$C$400="C")*(MOVIMIENTOS!$D$5:$D$400="jabas")*(ROW(MOVIMIENTOS!$B$5:$B$400)<=$L5)*MOVIMIENTOS!$E$5:$E$400)-SUMPRODUCT((MOVIMIENTOS!$B$5:$B$400="VENTA")*(MOVIMIENTOS!$C$5:$C$400="C")*(MOVIMIENTOS!$D$5:$D$400="jabas")*(ROW(MOVIMIENTOS!$B$5:$B$400)<=$L5)*MOVIMIENTOS!$E$5:$E$400)+SUMPRODUCT((MOVIMIENTOS!$B$5:$B$400="AJUSTE")*(MOVIMIENTOS!$C$5:$C$400="C")*(MOVIMIENTOS!$D$5:$D$400="jabas")*(ROW(MOVIMIENTOS!$B$5:$B$400)<=$L5)*MOVIMIENTOS!$E$5:$E$400)) -> 0 | E5: =IF($A5="","",SUMPRODUCT((MOVIMIENTOS!$B$5:$B$400="SALDO INICIAL")*(MOVIMIENTOS!$C$5:$C$400="M")*(MOVIMIENTOS!$D$5:$D$400="jabas")*(ROW(MOVIMIENTOS!$B$5:$B$400)<=$L5)*MOVIMIENTOS!$E$5:$E$400)+SUMPRODUCT((MOVIMIENTOS!$B$5:$B$400="PROCESO")*(MOVIMIENTOS!$C$5:$C$400="M")*(MOVIMIENTOS!$D$5:$D$400="jabas")*(ROW(MOVIMIENTOS!$B$5:$B$400)<=$L5)*MOVIMIENTOS!$E$5:$E$400)-SUMPRODUCT((MOVIMIENTOS!$B$5:$B$400="ENVÍO A SUPESA")*(MOVIMIENTOS!$C$5:$C$400="M")*(MOVIMIENTOS!$D$5:$D$400="jabas")*(ROW(MOVIMIENTOS!$B$5:$B$400)<=$L5)*MOVIMIENTOS!$E$5:$E$400)+SUMPRODUCT((MOVIMIENTOS!$B$5:$B$400="DEVOLUCIÓN")*(MOVIMIENTOS!$C$5:$C$400="M")*(MOVIMIENTOS!$D$5:$D$400="jabas")*(ROW(MOVIMIENTOS!$B$5:$B$400)<=$L5)*MOVIMIENTOS!$E$5:$E$400)-SUMPRODUCT((MOVIMIENTOS!$B$5:$B$400="TRASIEGO")*(MOVIMIENTOS!$C$5:$C$400="M")*(MOVIMIENTOS!$D$5:$D$400="jabas")*(ROW(MOVIMIENTOS!$B$5:$B$400)<=$L5)*MOVIMIENTOS!$E$5:$E$400)-SUMPRODUCT((MOVIMIENTOS!$B$5:$B$400="REGALO")*(MOVIMIENTOS!$C$5:$C$400="M")*(MOVIMIENTOS!$D$5:$D$400="jabas")*(ROW(MOVIMIENTOS!$B$5:$B$400)<=$L5)*MOVIMIENTOS!$E$5:$E$400)-SUMPRODUCT((MOVIMIENTOS!$B$5:$B$400="VENTA")*(MOVIMIENTOS!$C$5:$C$400="M")*(MOVIMIENTOS!$D$5:$D$400="jabas")*(ROW(MOVIMIENTOS!$B$5:$B$400)<=$L5)*MOVIMIENTOS!$E$5:$E$400)+SUMPRODUCT((MOVIMIENTOS!$B$5:$B$400="AJUSTE")*(MOVIMIENTOS!$C$5:$C$400="M")*(MOVIMIENTOS!$D$5:$D$400="jabas")*(ROW(MOVIMIENTOS!$B$5:$B$400)<=$L5)*MOVIMIENTOS!$E$5:$E$400)) -> 7 | F5: =IF($A5="","",SUMPRODUCT((MOVIMIENTOS!$B$5:$B$400="SALDO INICIAL")*(MOVIMIENTOS!$C$5:$C$400="Chancho")*(MOVIMIENTOS!$D$5:$D$400="sacos")*(ROW(MOVIMIENTOS!$B$5:$B$400)<=$L5)*MOVIMIENTOS!$E$5:$E$400)+SUMPRODUCT((MOVIMIENTOS!$B$5:$B$400="PROCESO")*(MOVIMIENTOS!$C$5:$C$400="Chancho")*(MOVIMIENTOS!$D$5:$D$400="sacos")*(ROW(MOVIMIENTOS!$B$5:$B$400)<=$L5)*MOVIMIENTOS!$E$5:$E$400)-SUMPRODUCT((MOVIMIENTOS!$B$5:$B$400="VENTA CHANCHO")*(MOVIMIENTOS!$C$5:$C$400="Chancho")*(MOVIMIENTOS!$D$5:$D$400="sacos")*(ROW(MOVIMIENTOS!$B$5:$B$400)<=$L5)*MOVIMIENTOS!$E$5:$E$400)-SUMPRODUCT((MOVIMIENTOS!$B$5:$B$400="REGALO")*(MOVIMIENTOS!$C$5:$C$400="Chancho")*(MOVIMIENTOS!$D$5:$D$400="sacos")*(ROW(MOVIMIENTOS!$B$5:$B$400)<=$L5)*MOVIMIENTOS!$E$5:$E$400)-SUMPRODUCT((MOVIMIENTOS!$B$5:$B$400="VENTA")*(MOVIMIENTOS!$C$5:$C$400="Chancho")*(MOVIMIENTOS!$D$5:$D$400="sacos")*(ROW(MOVIMIENTOS!$B$5:$B$400)<=$L5)*MOVIMIENTOS!$E$5:$E$400)+SUMPRODUCT((MOVIMIENTOS!$B$5:$B$400="AJUSTE")*(MOVIMIENTOS!$C$5:$C$400="Chancho")*(MOVIMIENTOS!$D$5:$D$400="sacos")*(ROW(MOVIMIENTOS!$B$5:$B$400)<=$L5)*MOVIMIENTOS!$E$5:$E$400)) -> 20 | G5: =IF($A5="","",SUM(B5:E5)) -> 15 | H5: =IF($A5="","",SUMPRODUCT((((MOVIMIENTOS!$B$5:$B$400="SALDO INICIAL")*(MOVIMIENTOS!$C$5:$C$400<>"Chancho"))+(MOVIMIENTOS!$B$5:$B$400="COMPRA")+(MOVIMIENTOS!$B$5:$B$400="REPROCESO")+((MOVIMIENTOS!$B$5:$B$400="AJUSTE")*(MOVIMIENTOS!$C$5:$C$400<>"Chancho")))*(ROW(MOVIMIENTOS!$B$5:$B$400)<=$L5)*MOVIMIENTOS!$I$5:$I$400)-SUMPRODUCT(((MOVIMIENTOS!$B$5:$B$400="ENVÍO A SUPESA")+(MOVIMIENTOS!$B$5:$B$400="MALOGRADO")+(MOVIMIENTOS!$B$5:$B$400="OTRA SALIDA")+(MOVIMIENTOS!$B$5:$B$400="TRASIEGO")+((MOVIMIENTOS!$B$5:$B$400="PROCESO")*(MOVIMIENTOS!$C$5:$C$400="Chancho"))+((MOVIMIENTOS!$B$5:$B$400="REGALO")*(MOVIMIENTOS!$C$5:$C$400<>"Chancho"))+((MOVIMIENTOS!$B$5:$B$400="VENTA")*(MOVIMIENTOS!$C$5:$C$400<>"Chancho")))*(ROW(MOVIMIENTOS!$B$5:$B$400)<=$L5)*MOVIMIENTOS!$I$5:$I$400)) -> 239 | J5: =IF(MOVIMIENTOS!$A$5<>"",1,"") -> 1 | K5: =MOVIMIENTOS!$A5 -> 46214 | L5: =IF($A5="","",SUMPRODUCT(MAX((MOVIMIENTOS!$A$5:$A$400=$A5)*ROW(MOVIMIENTOS!$A$5:$A$400)))) -> 7
