Workbook

Sheet MOVIMIENTOS
A1: AGRO PACAYALES · PLANTA CAMOTE 2026 | MOVIMIENTOS — registra aquí un evento por fila
A2: Única hoja que llenas: escribe la fecha como 24-7 (saldrá "vie 24-07" solita) + Tipo (lista) + Calidad + Unidad (jabas/sacos/kg) + Cantidad → los Kg salen solos. Si registras en kg (muestras, malogrado, reproceso, otras salidas) los Kg = Cantidad. Guía/ticket y nota al final. KARDEX, SALDO DIARIO y RESUMEN se arman solos.
A4: Fecha | B4: Tipo | C4: Calidad | D4: Unidad | E4: Cantidad | F4: Kg | G4: N° Guía / Ticket | H4: Observación
A5: 46214 | B5: AJUSTE | C5: A | D5: jabas | E5: 2 | F5: =IF($B5="","",IF($D5="kg",N($E5),IF($D5="sacos",N($E5)*97,IF($D5="jabas",N($E5)*IFERROR(VLOOKUP($C5,LISTAS!$A$2:$B$12,2,0),0),"")))) -> 30 | I5: =N($F5) -> 30
A6: 46214 | B6: AJUSTE | C6: M | D6: jabas | E6: 1 | F6: =IF($B6="","",IF($D6="kg",N($E6),IF($D6="sacos",N($E6)*97,IF($D6="jabas",N($E6)*IFERROR(VLOOKUP($C6,LISTAS!$A$2:$B$12,2,0),0),"")))) -> 17 | I6: =N($F6) -> 17
A7: 46214 | B7: SALDO INICIAL | C7: M | D7: jabas | E7: 7 | F7: =IF($B7="","",IF($D7="kg",N($E7),IF($D7="sacos",N($E7)*97,IF($D7="jabas",N($E7)*IFERROR(VLOOKUP($C7,LISTAS!$A$2:$B$12,2,0),0),"")))) -> 119 | I7: =N($F7) -> 119
A8: 46214 | B8: SALDO INICIAL | C8: Chancho | D8: sacos | E8: 20 | F8: =IF($B8="","",IF($D8="kg",N($E8),IF($D8="sacos",N($E8)*97,IF($D8="jabas",N($E8)*IFERROR(VLOOKUP($C8,LISTAS!$A$2:$B$12,2,0),0),"")))) -> 1940 | I8: =N($F8) -> 1940
A9: 46215 | B9: COMPRA | C9: — | D9: sacos | E9: 30 | F9: =IF($B9="","",IF($D9="kg",N($E9),IF($D9="sacos",N($E9)*97,IF($D9="jabas",N($E9)*IFERROR(VLOOKUP($C9,LISTAS!$A$2:$B$12,2,0),0),"")))) -> 2910 | H9: peso aprox 95 kg/saco | I9: =N($F9) -> 2910
A10: 46215 | B10: PROCESO | C10: A | D10: jabas | E10: 59 | F10: =IF($B10="","",IF($D10="kg",N($E10),IF($D10="sacos",N($E10)*97,IF($D10="jabas",N($E10)*IFERROR(VLOOKUP($C10,LISTAS!$A$2:$B$12,2,0),0),"")))) -> 885 | I10: =N($F10) -> 885
A11: 46215 | B11: PROCESO | C11: P | D11: jabas | E11: 11 | F11: =IF($B11="","",IF($D11="kg",N($E11),IF($D11="sacos",N($E11)*97,IF($D11="jabas",N($E11)*IFERROR(VLOOKUP($C11,LISTAS!$A$2:$B$12,2,0),0),"")))) -> 198 | I11: =N($F11) -> 198
A12: 46215 | B12: PROCESO | C12: C | D12: jabas | E12: 12 | F12: =IF($B12="","",IF($D12="kg",N($E12),IF($D12="sacos",N($E12)*97,IF($D12="jabas",N($E12)*IFERROR(VLOOKUP($C12,LISTAS!$A$2:$B$12,2,0),0),"")))) -> 204 | I12: =N($F12) -> 204
A13: 46215 | B13: PROCESO | C13: M | D13: jabas | E13: 64 | F13: =IF($B13="","",IF($D13="kg",N($E13),IF($D13="sacos",N($E13)*97,IF($D13="jabas",N($E13)*IFERROR(VLOOKUP($C13,LISTAS!$A$2:$B$12,2,0),0),"")))) -> 1088 | I13: =N($F13) -> 1088
A14: 46215 | B14: PROCESO | C14: Chancho | D14: sacos | E14: 6 | F14: =IF($B14="","",IF($D14="kg",N($E14),IF($D14="sacos",N($E14)*97,IF($D14="jabas",N($E14)*IFERROR(VLOOKUP($C14,LISTAS!$A$2:$B$12,2,0),0),"")))) -> 582 | I14: =N($F14) -> 582
A15: 46215 | B15: ENVÍO A SUPESA | C15: A | D15: jabas | E15: 67 | F15: =IF($B15="","",IF($D15="kg",N($E15),IF($D15="sacos",N($E15)*97,IF($D15="jabas",N($E15)*IFERROR(VLOOKUP($C15,LISTAS!$A$2:$B$12,2,0),0),"")))) -> 1005 | G15: 2977 | I15: =N($F15) -> 1005
A16: 46215 | B16: ENVÍO A SUPESA | C16: P | D16: jabas | E16: 11 | F16: =IF($B16="","",IF($D16="kg",N($E16),IF($D16="sacos",N($E16)*97,IF($D16="jabas",N($E16)*IFERROR(VLOOKUP($C16,LISTAS!$A$2:$B$12,2,0),0),"")))) -> 198 | G16: 2977 | I16: =N($F16) -> 198
A17: 46215 | B17: ENVÍO A SUPESA | C17: C | D17: jabas | E17: 12 | F17: =IF($B17="","",IF($D17="kg",N($E17),IF($D17="sacos",N($E17)*97,IF($D17="jabas",N($E17)*IFERROR(VLOOKUP($C17,LISTAS!$A$2:$B$12,2,0),0),"")))) -> 204 | G17: 2977 | I17: =N($F17) -> 204
A18: 46215 | B18: ENVÍO A SUPESA | C18: M | D18: jabas | E18: 42 | F18: =IF($B18="","",IF($D18="kg",N($E18),IF($D18="sacos",N($E18)*97,IF($D18="jabas",N($E18)*IFERROR(VLOOKUP($C18,LISTAS!$A$2:$B$12,2,0),0),"")))) -> 714 | G18: 2977 | I18: =N($F18) -> 714
A19: 46216 | B19: COMPRA | C19: — | D19: sacos | E19: 40 | F19: =IF($B19="","",IF($D19="kg",N($E19),IF($D19="sacos",N($E19)*97,IF($D19="jabas",N($E19)*IFERROR(VLOOKUP($C19,LISTAS!$A$2:$B$12,2,0),0),"")))) -> 3880 | H19: peso aprox 95 kg/saco | I19: =N($F19) -> 3880
A20: 46216 | B20: PROCESO | C20: A | D20: jabas | E20: 107 | F20: =IF($B20="","",IF($D20="kg",N($E20),IF($D20="sacos",N($E20)*97,IF($D20="jabas",N($E20)*IFERROR(VLOOKUP($C20,LISTAS!$A$2:$B$12,2,0),0),"")))) -> 1605 | I20: =N($F20) -> 1605
A21: 46216 | B21: PROCESO | C21: P | D21: jabas | E21: 11 | F21: =IF($B21="","",IF($D21="kg",N($E21),IF($D21="sacos",N($E21)*97,IF($D21="jabas",N($E21)*IFERROR(VLOOKUP($C21,LISTAS!$A$2:$B$12,2,0),0),"")))) -> 198 | I21: =N($F21) -> 198
A22: 46216 | B22: PROCESO | C22: C | D22: jabas | E22: 12 | F22: =IF($B22="","",IF($D22="kg",N($E22),IF($D22="sacos",N($E22)*97,IF($D22="jabas",N($E22)*IFERROR(VLOOKUP($C22,LISTAS!$A$2:$B$12,2,0),0),"")))) -> 204 | I22: =N($F22) -> 204
A23: 46216 | B23: PROCESO | C23: M | D23: jabas | E23: 110 | F23: =IF($B23="","",IF($D23="kg",N($E23),IF($D23="sacos",N($E23)*97,IF($D23="jabas",N($E23)*IFERROR(VLOOKUP($C23,LISTAS!$A$2:$B$12,2,0),0),"")))) -> 1870 | I23: =N($F23) -> 1870
A24: 46216 | B24: PROCESO | C24: Chancho | D24: sacos | E24: 2 | F24: =IF($B24="","",IF($D24="kg",N($E24),IF($D24="sacos",N($E24)*97,IF($D24="jabas",N($E24)*IFERROR(VLOOKUP($C24,LISTAS!$A$2:$B$12,2,0),0),"")))) -> 194 | I24: =N($F24) -> 194
A25: 46216 | B25: ENVÍO A SUPESA | C25: A | D25: jabas | E25: 67 | F25: =IF($B25="","",IF($D25="kg",N($E25),IF($D25="sacos",N($E25)*97,IF($D25="jabas",N($E25)*IFERROR(VLOOKUP($C25,LISTAS!$A$2:$B$12,2,0),0),"")))) -> 1005 | G25: 2980 | I25: =N($F25) -> 1005
A26: 46216 | B26: ENVÍO A SUPESA | C26: P | D26: jabas | E26: 11 | F26: =IF($B26="","",IF($D26="kg",N($E26),IF($D26="sacos",N($E26)*97,IF($D26="jabas",N($E26)*IFERROR(VLOOKUP($C26,LISTAS!$A$2:$B$12,2,0),0),"")))) -> 198 | G26: 2980 | I26: =N($F26) -> 198
A27: 46216 | B27: ENVÍO A SUPESA | C27: C | D27: jabas | E27: 12 | F27: =IF($B27="","",IF($D27="kg",N($E27),IF($D27="sacos",N($E27)*97,IF($D27="jabas",N($E27)*IFERROR(VLOOKUP($C27,LISTAS!$A$2:$B$12,2,0),0),"")))) -> 204 | G27: 2980 | I27: =N($F27) -> 204
A28: 46216 | B28: ENVÍO A SUPESA | C28: M | D28: jabas | E28: 97 | F28: =IF($B28="","",IF($D28="kg",N($E28),IF($D28="sacos",N($E28)*97,IF($D28="jabas",N($E28)*IFERROR(VLOOKUP($C28,LISTAS!$A$2:$B$12,2,0),0),"")))) -> 1649 | G28: 2980 | I28: =N($F28) -> 1649
A29: 46217 | B29: COMPRA | C29: — | D29: sacos | E29: 40 | F29: =IF($B29="","",IF($D29="kg",N($E29),IF($D29="sacos",N($E29)*97,IF($D29="jabas",N($E29)*IFERROR(VLOOKUP($C29,LISTAS!$A$2:$B$12,2,0),0),"")))) -> 3880 | H29: peso aprox 95 kg/saco | I29: =N($F29) -> 3880
A30: 46217 | B30: PROCESO | C30: A | D30: jabas | E30: 45 | F30: =IF($B30="","",IF($D30="kg",N($E30),IF($D30="sacos",N($E30)*97,IF($D30="jabas",N($E30)*IFERROR(VLOOKUP($C30,LISTAS!$A$2:$B$12,2,0),0),"")))) -> 675 | I30: =N($F30) -> 675
A31: 46217 | B31: PROCESO | C31: P | D31: jabas | E31: 11 | F31: =IF($B31="","",IF($D31="kg",N($E31),IF($D31="sacos",N($E31)*97,IF($D31="jabas",N($E31)*IFERROR(VLOOKUP($C31,LISTAS!$A$2:$B$12,2,0),0),"")))) -> 198 | I31: =N($F31) -> 198
A32: 46217 | B32: PROCESO | C32: C | D32: jabas | E32: 12 | F32: =IF($B32="","",IF($D32="kg",N($E32),IF($D32="sacos",N($E32)*97,IF($D32="jabas",N($E32)*IFERROR(VLOOKUP($C32,LISTAS!$A$2:$B$12,2,0),0),"")))) -> 204 | I32: =N($F32) -> 204
A33: 46217 | B33: PROCESO | C33: M | D33: jabas | E33: 121 | F33: =IF($B33="","",IF($D33="kg",N($E33),IF($D33="sacos",N($E33)*97,IF($D33="jabas",N($E33)*IFERROR(VLOOKUP($C33,LISTAS!$A$2:$B$12,2,0),0),"")))) -> 2057 | I33: =N($F33) -> 2057
A34: 46217 | B34: PROCESO | C34: Chancho | D34: sacos | E34: 7 | F34: =IF($B34="","",IF($D34="kg",N($E34),IF($D34="sacos",N($E34)*97,IF($D34="jabas",N($E34)*IFERROR(VLOOKUP($C34,LISTAS!$A$2:$B$12,2,0),0),"")))) -> 679 | I34: =N($F34) -> 679
A35: 46217 | B35: ENVÍO A SUPESA | C35: A | D35: jabas | E35: 67 | F35: =IF($B35="","",IF($D35="kg",N($E35),IF($D35="sacos",N($E35)*97,IF($D35="jabas",N($E35)*IFERROR(VLOOKUP($C35,LISTAS!$A$2:$B$12,2,0),0),"")))) -> 1005 | G35: 2984 | I35: =N($F35) -> 1005
A36: 46217 | B36: ENVÍO A SUPESA | C36: P | D36: jabas | E36: 11 | F36: =IF($B36="","",IF($D36="kg",N($E36),IF($D36="sacos",N($E36)*97,IF($D36="jabas",N($E36)*IFERROR(VLOOKUP($C36,LISTAS!$A$2:$B$12,2,0),0),"")))) -> 198 | G36: 2984 | I36: =N($F36) -> 198
A37: 46217 | B37: ENVÍO A SUPESA | C37: C | D37: jabas | E37: 12 | F37: =IF($B37="","",IF($D37="kg",N($E37),IF($D37="sacos",N($E37)*97,IF($D37="jabas",N($E37)*IFERROR(VLOOKUP($C37,LISTAS!$A$2:$B$12,2,0),0),"")))) -> 204 | G37: 2984 | I37: =N($F37) -> 204
A38: 46217 | B38: ENVÍO A SUPESA | C38: M | D38: jabas | E38: 116 | F38: =IF($B38="","",IF($D38="kg",N($E38),IF($D38="sacos",N($E38)*97,IF($D38="jabas",N($E38)*IFERROR(VLOOKUP($C38,LISTAS!$A$2:$B$12,2,0),0),"")))) -> 1972 | G38: 2984 | I38: =N($F38) -> 1972
A39: 46218 | B39: COMPRA | C39: — | D39: sacos | E39: 40 | F39: =IF($B39="","",IF($D39="kg",N($E39),IF($D39="sacos",N($E39)*97,IF($D39="jabas",N($E39)*IFERROR(VLOOKUP($C39,LISTAS!$A$2:$B$12,2,0),0),"")))) -> 3880 | H39: peso aprox 95 kg/saco | I39: =N($F39) -> 3880
A40: 46218 | B40: PROCESO | C40: A | D40: jabas | E40: 79 | F40: =IF($B40="","",IF($D40="kg",N($E40),IF($D40="sacos",N($E40)*97,IF($D40="jabas",N($E40)*IFERROR(VLOOKUP($C40,LISTAS!$A$2:$B$12,2,0),0),"")))) -> 1185 | I40: =N($F40) -> 1185
A41: 46218 | B41: PROCESO | C41: P | D41: jabas | E41: 22 | F41: =IF($B41="","",IF($D41="kg",N($E41),IF($D41="sacos",N($E41)*97,IF($D41="jabas",N($E41)*IFERROR(VLOOKUP($C41,LISTAS!$A$2:$B$12,2,0),0),"")))) -> 396 | I41: =N($F41) -> 396
...

Sheet SALDO DIARIO
A1: AGRO PACAYALES · PLANTA CAMOTE 2026 | SALDO DIARIO — lo que queda en almacén al cierre de cada día
A2: Automático. Cada fila = cierre del día: jabas por calidad para contar el almacén, sacos de chancho y kg del kardex. RECHAZO no suma (va a reproceso); DEVOLUCIÓN sí suma completo. La última fila con datos es tu stock de HOY.
A4: Fecha | B4: A (jabas) | C4: P (jabas) | D4: C (jabas) | E4: M (jabas) | F4: Chancho (sacos) | G4: TOTAL jabas | H4: Stock Kg
A5: =IFERROR(INDEX(K$5:K$400,MATCH(ROW()-4,J$5:J$400,0)),"") -> 46214 | B5: =IF($A5="","",SUMPRODUCT((MOVIMIENTOS!$B$5:$B$400="SALDO INICIAL")*(MOVIMIENTOS!$C$5:$C$400="A")*(MOVIMIENTOS!$D$5:$D$400="jabas")*(MOVIMIENTOS!$A$5:$A$400<>"")*(MOVIMIENTOS!$A$5:$A$400<=$A5)*MOVIMIENTOS!$E$5:$E$400)+SUMPRODUCT((MOVIMIENTOS!$B$5:$B$400="PROCESO")*(MOVIMIENTOS!$C$5:$C$400="A")*(MOVIMIENTOS!$D$5:$D$400="jabas")*(MOVIMIENTOS!$A$5:$A$400<>"")*(MOVIMIENTOS!$A$5:$A$400<=$A5)*MOVIMIENTOS!$E$5:$E$400)-SUMPRODUCT((MOVIMIENTOS!$B$5:$B$400="ENVÍO A SUPESA")*(MOVIMIENTOS!$C$5:$C$400="A")*(MOVIMIENTOS!$D$5:$D$400="jabas")*(MOVIMIENTOS!$A$5:$A$400<>"")*(MOVIMIENTOS!$A$5:$A$400<=$A5)*MOVIMIENTOS!$E$5:$E$400)+SUMPRODUCT((MOVIMIENTOS!$B$5:$B$400="DEVOLUCIÓN")*(MOVIMIENTOS!$C$5:$C$400="A")*(MOVIMIENTOS!$D$5:$D$400="jabas")*(MOVIMIENTOS!$A$5:$A$400<>"")*(MOVIMIENTOS!$A$5:$A$400<=$A5)*MOVIMIENTOS!$E$5:$E$400)-SUMPRODUCT((MOVIMIENTOS!$B$5:$B$400="TRASIEGO")*(MOVIMIENTOS!$C$5:$C$400="A")*(MOVIMIENTOS!$D$5:$D$400="jabas")*(MOVIMIENTOS!$A$5:$A$400<>"")*(MOVIMIENTOS!$A$5:$A$400<=$A5)*MOVIMIENTOS!$E$5:$E$400)-SUMPRODUCT((MOVIMIENTOS!$B$5:$B$400="REGALO")*(MOVIMIENTOS!$C$5:$C$400="A")*(MOVIMIENTOS!$D$5:$D$400="jabas")*(MOVIMIENTOS!$A$5:$A$400<>"")*(MOVIMIENTOS!$A$5:$A$400<=$A5)*MOVIMIENTOS!$E$5:$E$400)-SUMPRODUCT((MOVIMIENTOS!$B$5:$B$400="VENTA")*(MOVIMIENTOS!$C$5:$C$400="A")*(MOVIMIENTOS!$D$5:$D$400="jabas")*(MOVIMIENTOS!$A$5:$A$400<>"")*(MOVIMIENTOS!$A$5:$A$400<=$A5)*MOVIMIENTOS!$E$5:$E$400)+SUMPRODUCT((MOVIMIENTOS!$B$5:$B$400="AJUSTE")*(MOVIMIENTOS!$C$5:$C$400="A")*(MOVIMIENTOS!$D$5:$D$400="jabas")*(MOVIMIENTOS!$A$5:$A$400<>"")*(MOVIMIENTOS!$A$5:$A$400<=$A5)*MOVIMIENTOS!$E$5:$E$400)) -> 2 | C5: =IF($A5="","",SUMPRODUCT((MOVIMIENTOS!$B$5:$B$400="SALDO INICIAL")*(MOVIMIENTOS!$C$5:$C$400="P")*(MOVIMIENTOS!$D$5:$D$400="jabas")*(MOVIMIENTOS!$A$5:$A$400<>"")*(MOVIMIENTOS!$A$5:$A$400<=$A5)*MOVIMIENTOS!$E$5:$E$400)+SUMPRODUCT((MOVIMIENTOS!$B$5:$B$400="PROCESO")*(MOVIMIENTOS!$C$5:$C$400="P")*(MOVIMIENTOS!$D$5:$D$400="jabas")*(MOVIMIENTOS!$A$5:$A$400<>"")*(MOVIMIENTOS!$A$5:$A$400<=$A5)*MOVIMIENTOS!$E$5:$E$400)-SUMPRODUCT((MOVIMIENTOS!$B$5:$B$400="ENVÍO A SUPESA")*(MOVIMIENTOS!$C$5:$C$400="P")*(MOVIMIENTOS!$D$5:$D$400="jabas")*(MOVIMIENTOS!$A$5:$A$400<>"")*(MOVIMIENTOS!$A$5:$A$400<=$A5)*MOVIMIENTOS!$E$5:$E$400)+SUMPRODUCT((MOVIMIENTOS!$B$5:$B$400="DEVOLUCIÓN")*(MOVIMIENTOS!$C$5:$C$400="P")*(MOVIMIENTOS!$D$5:$D$400="jabas")*(MOVIMIENTOS!$A$5:$A$400<>"")*(MOVIMIENTOS!$A$5:$A$400<=$A5)*MOVIMIENTOS!$E$5:$E$400)-SUMPRODUCT((MOVIMIENTOS!$B$5:$B$400="TRASIEGO")*(MOVIMIENTOS!$C$5:$C$400="P")*(MOVIMIENTOS!$D$5:$D$400="jabas")*(MOVIMIENTOS!$A$5:$A$400<>"")*(MOVIMIENTOS!$A$5:$A$400<=$A5)*MOVIMIENTOS!$E$5:$E$400)-SUMPRODUCT((MOVIMIENTOS!$B$5:$B$400="REGALO")*(MOVIMIENTOS!$C$5:$C$400="P")*(MOVIMIENTOS!$D$5:$D$400="jabas")*(MOVIMIENTOS!$A$5:$A$400<>"")*(MOVIMIENTOS!$A$5:$A$400<=$A5)*MOVIMIENTOS!$E$5:$E$400)-SUMPRODUCT((MOVIMIENTOS!$B$5:$B$400="VENTA")*(MOVIMIENTOS!$C$5:$C$400="P")*(MOVIMIENTOS!$D$5:$D$400="jabas")*(MOVIMIENTOS!$A$5:$A$400<>"")*(MOVIMIENTOS!$A$5:$A$400<=$A5)*MOVIMIENTOS!$E$5:$E$400)+SUMPRODUCT((MOVIMIENTOS!$B$5:$B$400="AJUSTE")*(MOVIMIENTOS!$C$5:$C$400="P")*(MOVIMIENTOS!$D$5:$D$400="jabas")*(MOVIMIENTOS!$A$5:$A$400<>"")*(MOVIMIENTOS!$A$5:$A$400<=$A5)*MOVIMIENTOS!$E$5:$E$400)) -> 0 | D5: =IF($A5="","",SUMPRODUCT((MOVIMIENTOS!$B$5:$B$400="SALDO INICIAL")*(MOVIMIENTOS!$C$5:$C$400="C")*(MOVIMIENTOS!$D$5:$D$400="jabas")*(MOVIMIENTOS!$A$5:$A$400<>"")*(MOVIMIENTOS!$A$5:$A$400<=$A5)*MOVIMIENTOS!$E$5:$E$400)+SUMPRODUCT((MOVIMIENTOS!$B$5:$B$400="PROCESO")*(MOVIMIENTOS!$C$5:$C$400="C")*(MOVIMIENTOS!$D$5:$D$400="jabas")*(MOVIMIENTOS!$A$5:$A$400<>"")*(MOVIMIENTOS!$A$5:$A$400<=$A5)*MOVIMIENTOS!$E$5:$E$400)-SUMPRODUCT((MOVIMIENTOS!$B$5:$B$400="ENVÍO A SUPESA")*(MOVIMIENTOS!$C$5:$C$400="C")*(MOVIMIENTOS!$D$5:$D$400="jabas")*(MOVIMIENTOS!$A$5:$A$400<>"")*(MOVIMIENTOS!$A$5:$A$400<=$A5)*MOVIMIENTOS!$E$5:$E$400)+SUMPRODUCT((MOVIMIENTOS!$B$5:$B$400="DEVOLUCIÓN")*(MOVIMIENTOS!$C$5:$C$400="C")*(MOVIMIENTOS!$D$5:$D$400="jabas")*(MOVIMIENTOS!$A$5:$A$400<>"")*(MOVIMIENTOS!$A$5:$A$400<=$A5)*MOVIMIENTOS!$E$5:$E$400)-SUMPRODUCT((MOVIMIENTOS!$B$5:$B$400="TRASIEGO")*(MOVIMIENTOS!$C$5:$C$400="C")*(MOVIMIENTOS!$D$5:$D$400="jabas")*(MOVIMIENTOS!$A$5:$A$400<>"")*(MOVIMIENTOS!$A$5:$A$400<=$A5)*MOVIMIENTOS!$E$5:$E$400)-SUMPRODUCT((MOVIMIENTOS!$B$5:$B$400="REGALO")*(MOVIMIENTOS!$C$5:$C$400="C")*(MOVIMIENTOS!$D$5:$D$400="jabas")*(MOVIMIENTOS!$A$5:$A$400<>"")*(MOVIMIENTOS!$A$5:$A$400<=$A5)*MOVIMIENTOS!$E$5:$E$400)-SUMPRODUCT((MOVIMIENTOS!$B$5:$B$400="VENTA")*(MOVIMIENTOS!$C$5:$C$400="C")*(MOVIMIENTOS!$D$5:$D$400="jabas")*(MOVIMIENTOS!$A$5:$A$400<>"")*(MOVIMIENTOS!$A$5:$A$400<=$A5)*MOVIMIENTOS!$E$5:$E$400)+SUMPRODUCT((MOVIMIENTOS!$B$5:$B$400="AJUSTE")*(MOVIMIENTOS!$C$5:$C$400="C")*(MOVIMIENTOS!$D$5:$D$400="jabas")*(MOVIMIENTOS!$A$5:$A$400<>"")*(MOVIMIENTOS!$A$5:$A$400<=$A5)*MOVIMIENTOS!$E$5:$E$400)) -> 0 | E5: =IF($A5="","",SUMPRODUCT((MOVIMIENTOS!$B$5:$B$400="SALDO INICIAL")*(MOVIMIENTOS!$C$5:$C$400="M")*(MOVIMIENTOS!$D$5:$D$400="jabas")*(MOVIMIENTOS!$A$5:$A$400<>"")*(MOVIMIENTOS!$A$5:$A$400<=$A5)*MOVIMIENTOS!$E$5:$E$400)+SUMPRODUCT((MOVIMIENTOS!$B$5:$B$400="PROCESO")*(MOVIMIENTOS!$C$5:$C$400="M")*(MOVIMIENTOS!$D$5:$D$400="jabas")*(MOVIMIENTOS!$A$5:$A$400<>"")*(MOVIMIENTOS!$A$5:$A$400<=$A5)*MOVIMIENTOS!$E$5:$E$400)-SUMPRODUCT((MOVIMIENTOS!$B$5:$B$400="ENVÍO A SUPESA")*(MOVIMIENTOS!$C$5:$C$400="M")*(MOVIMIENTOS!$D$5:$D$400="jabas")*(MOVIMIENTOS!$A$5:$A$400<>"")*(MOVIMIENTOS!$A$5:$A$400<=$A5)*MOVIMIENTOS!$E$5:$E$400)+SUMPRODUCT((MOVIMIENTOS!$B$5:$B$400="DEVOLUCIÓN")*(MOVIMIENTOS!$C$5:$C$400="M")*(MOVIMIENTOS!$D$5:$D$400="jabas")*(MOVIMIENTOS!$A$5:$A$400<>"")*(MOVIMIENTOS!$A$5:$A$400<=$A5)*MOVIMIENTOS!$E$5:$E$400)-SUMPRODUCT((MOVIMIENTOS!$B$5:$B$400="TRASIEGO")*(MOVIMIENTOS!$C$5:$C$400="M")*(MOVIMIENTOS!$D$5:$D$400="jabas")*(MOVIMIENTOS!$A$5:$A$400<>"")*(MOVIMIENTOS!$A$5:$A$400<=$A5)*MOVIMIENTOS!$E$5:$E$400)-SUMPRODUCT((MOVIMIENTOS!$B$5:$B$400="REGALO")*(MOVIMIENTOS!$C$5:$C$400="M")*(MOVIMIENTOS!$D$5:$D$400="jabas")*(MOVIMIENTOS!$A$5:$A$400<>"")*(MOVIMIENTOS!$A$5:$A$400<=$A5)*MOVIMIENTOS!$E$5:$E$400)-SUMPRODUCT((MOVIMIENTOS!$B$5:$B$400="VENTA")*(MOVIMIENTOS!$C$5:$C$400="M")*(MOVIMIENTOS!$D$5:$D$400="jabas")*(MOVIMIENTOS!$A$5:$A$400<>"")*(MOVIMIENTOS!$A$5:$A$400<=$A5)*MOVIMIENTOS!$E$5:$E$400)+SUMPRODUCT((MOVIMIENTOS!$B$5:$B$400="AJUSTE")*(MOVIMIENTOS!$C$5:$C$400="M")*(MOVIMIENTOS!$D$5:$D$400="jabas")*(MOVIMIENTOS!$A$5:$A$400<>"")*(MOVIMIENTOS!$A$5:$A$400<=$A5)*MOVIMIENTOS!$E$5:$E$400)) -> 8 | F5: =IF($A5="","",SUMPRODUCT((MOVIMIENTOS!$B$5:$B$400="SALDO INICIAL")*(MOVIMIENTOS!$C$5:$C$400="Chancho")*(MOVIMIENTOS!$D$5:$D$400="sacos")*(MOVIMIENTOS!$A$5:$A$400<>"")*(MOVIMIENTOS!$A$5:$A$400<=$A5)*MOVIMIENTOS!$E$5:$E$400)+SUMPRODUCT((MOVIMIENTOS!$B$5:$B$400="PROCESO")*(MOVIMIENTOS!$C$5:$C$400="Chancho")*(MOVIMIENTOS!$D$5:$D$400="sacos")*(MOVIMIENTOS!$A$5:$A$400<>"")*(MOVIMIENTOS!$A$5:$A$400<=$A5)*MOVIMIENTOS!$E$5:$E$400)-SUMPRODUCT((MOVIMIENTOS!$B$5:$B$400="VENTA CHANCHO")*(MOVIMIENTOS!$C$5:$C$400="Chancho")*(MOVIMIENTOS!$D$5:$D$400="sacos")*(MOVIMIENTOS!$A$5:$A$400<>"")*(MOVIMIENTOS!$A$5:$A$400<=$A5)*MOVIMIENTOS!$E$5:$E$400)-SUMPRODUCT((MOVIMIENTOS!$B$5:$B$400="REGALO")*(MOVIMIENTOS!$C$5:$C$400="Chancho")*(MOVIMIENTOS!$D$5:$D$400="sacos")*(MOVIMIENTOS!$A$5:$A$400<>"")*(MOVIMIENTOS!$A$5:$A$400<=$A5)*MOVIMIENTOS!$E$5:$E$400)-SUMPRODUCT((MOVIMIENTOS!$B$5:$B$400="VENTA")*(MOVIMIENTOS!$C$5:$C$400="Chancho")*(MOVIMIENTOS!$D$5:$D$400="sacos")*(MOVIMIENTOS!$A$5:$A$400<>"")*(MOVIMIENTOS!$A$5:$A$400<=$A5)*MOVIMIENTOS!$E$5:$E$400)+SUMPRODUCT((MOVIMIENTOS!$B$5:$B$400="AJUSTE")*(MOVIMIENTOS!$C$5:$C$400="Chancho")*(MOVIMIENTOS!$D$5:$D$400="sacos")*(MOVIMIENTOS!$A$5:$A$400<>"")*(MOVIMIENTOS!$A$5:$A$400<=$A5)*MOVIMIENTOS!$E$5:$E$400)) -> 20 | G5: =IF($A5="","",SUM(B5:E5)) -> 10 | H5: =IF($A5="","",SUMPRODUCT((((MOVIMIENTOS!$B$5:$B$400="SALDO INICIAL")*(MOVIMIENTOS!$C$5:$C$400<>"Chancho"))+(MOVIMIENTOS!$B$5:$B$400="COMPRA")+(MOVIMIENTOS!$B$5:$B$400="REPROCESO")+(MOVIMIENTOS!$B$5:$B$400="DEVOLUCIÓN")+((MOVIMIENTOS!$B$5:$B$400="AJUSTE")*(MOVIMIENTOS!$C$5:$C$400<>"Chancho")))*(MOVIMIENTOS!$A$5:$A$400<>"")*(MOVIMIENTOS!$A$5:$A$400<=$A5)*MOVIMIENTOS!$I$5:$I$400)-SUMPRODUCT(((MOVIMIENTOS!$B$5:$B$400="ENVÍO A SUPESA")+(MOVIMIENTOS!$B$5:$B$400="ENVÍO A TOTTUS")+(MOVIMIENTOS!$B$5:$B$400="ENVIO A TOTTUS")+(MOVIMIENTOS!$B$5:$B$400="MALOGRADO")+(MOVIMIENTOS!$B$5:$B$400="OTRA SALIDA")+((MOVIMIENTOS!$B$5:$B$400="PROCESO")*(MOVIMIENTOS!$C$5:$C$400="Chancho"))+((MOVIMIENTOS!$B$5:$B$400="REGALO")*(MOVIMIENTOS!$C$5:$C$400<>"Chancho"))+((MOVIMIENTOS!$B$5:$B$400="VENTA")*(MOVIMIENTOS!$C$5:$C$400<>"Chancho")))*(MOVIMIENTOS!$A$5:$A$400<>"")*(MOVIMIENTOS!$A$5:$A$400<=$A5)*MOVIMIENTOS!$I$5:$I$400)) -> 166 | J5: =IF(MOVIMIENTOS!$A$5<>"",1,"") -> 1 | K5: =MOVIMIENTOS!$A5 -> 46214
A6: =IFERROR(INDEX(K$5:K$400,MATCH(ROW()-4,J$5:J$400,0)),"") -> 46215 | B6: =IF($A6="","",SUMPRODUCT((MOVIMIENTOS!$B$5:$B$400="SALDO INICIAL")*(MOVIMIENTOS!$C$5:$C$400="A")*(MOVIMIENTOS!$D$5:$D$400="jabas")*(MOVIMIENTOS!$A$5:$A$400<>"")*(MOVIMIENTOS!$A$5:$A$400<=$A6)*MOVIMIENTOS!$E$5:$E$400)+SUMPRODUCT((MOVIMIENTOS!$B$5:$B$400="PROCESO")*(MOVIMIENTOS!$C$5:$C$400="A")*(MOVIMIENTOS!$D$5:$D$400="jabas")*(MOVIMIENTOS!$A$5:$A$400<>"")*(MOVIMIENTOS!$A$5:$A$400<=$A6)*MOVIMIENTOS!$E$5:$E$400)-SUMPRODUCT((MOVIMIENTOS!$B$5:$B$400="ENVÍO A SUPESA")*(MOVIMIENTOS!$C$5:$C$400="A")*(MOVIMIENTOS!$D$5:$D$400="jabas")*(MOVIMIENTOS!$A$5:$A$400<>"")*(MOVIMIENTOS!$A$5:$A$400<=$A6)*MOVIMIENTOS!$E$5:$E$400)+SUMPRODUCT((MOVIMIENTOS!$B$5:$B$400="DEVOLUCIÓN")*(MOVIMIENTOS!$C$5:$C$400="A")*(MOVIMIENTOS!$D$5:$D$400="jabas")*(MOVIMIENTOS!$A$5:$A$400<>"")*(MOVIMIENTOS!$A$5:$A$400<=$A6)*MOVIMIENTOS!$E$5:$E$400)-SUMPRODUCT((MOVIMIENTOS!$B$5:$B$400="TRASIEGO")*(MOVIMIENTOS!$C$5:$C$400="A")*(MOVIMIENTOS!$D$5:$D$400="jabas")*(MOVIMIENTOS!$A$5:$A$400<>"")*(MOVIMIENTOS!$A$5:$A$400<=$A6)*MOVIMIENTOS!$E$5:$E$400)-SUMPRODUCT((MOVIMIENTOS!$B$5:$B$400="REGALO")*(MOVIMIENTOS!$C$5:$C$400="A")*(MOVIMIENTOS!$D$5:$D$400="jabas")*(MOVIMIENTOS!$A$5:$A$400<>"")*(MOVIMIENTOS!$A$5:$A$400<=$A6)*MOVIMIENTOS!$E$5:$E$400)-SUMPRODUCT((MOVIMIENTOS!$B$5:$B$400="VENTA")*(MOVIMIENTOS!$C$5:$C$400="A")*(MOVIMIENTOS!$D$5:$D$400="jabas")*(MOVIMIENTOS!$A$5:$A$400<>"")*(MOVIMIENTOS!$A$5:$A$400<=$A6)*MOVIMIENTOS!$E$5:$E$400)+SUMPRODUCT((MOVIMIENTOS!$B$5:$B$400="AJUSTE")*(MOVIMIENTOS!$C$5:$C$400="A")*(MOVIMIENTOS!$D$5:$D$400="jabas")*(MOVIMIENTOS!$A$5:$A$400<>"")*(MOVIMIENTOS!$A$5:$A$400<=$A6)*MOVIMIENTOS!$E$5:$E$400)) -> -6 | C6: =IF($A6="","",SUMPRODUCT((MOVIMIENTOS!$B$5:$B$400="SALDO INICIAL")*(MOVIMIENTOS!$C$5:$C$400="P")*(MOVIMIENTOS!$D$5:$D$400="jabas")*(MOVIMIENTOS!$A$5:$A$400<>"")*(MOVIMIENTOS!$A$5:$A$400<=$A6)*MOVIMIENTOS!$E$5:$E$400)+SUMPRODUCT((MOVIMIENTOS!$B$5:$B$400="PROCESO")*(MOVIMIENTOS!$C$5:$C$400="P")*(MOVIMIENTOS!$D$5:$D$400="jabas")*(MOVIMIENTOS!$A$5:$A$400<>"")*(MOVIMIENTOS!$A$5:$A$400<=$A6)*MOVIMIENTOS!$E$5:$E$400)-SUMPRODUCT((MOVIMIENTOS!$B$5:$B$400="ENVÍO A SUPESA")*(MOVIMIENTOS!$C$5:$C$400="P")*(MOVIMIENTOS!$D$5:$D$400="jabas")*(MOVIMIENTOS!$A$5:$A$400<>"")*(MOVIMIENTOS!$A$5:$A$400<=$A6)*MOVIMIENTOS!$E$5:$E$400)+SUMPRODUCT((MOVIMIENTOS!$B$5:$B$400="DEVOLUCIÓN")*(MOVIMIENTOS!$C$5:$C$400="P")*(MOVIMIENTOS!$D$5:$D$400="jabas")*(MOVIMIENTOS!$A$5:$A$400<>"")*(MOVIMIENTOS!$A$5:$A$400<=$A6)*MOVIMIENTOS!$E$5:$E$400)-SUMPRODUCT((MOVIMIENTOS!$B$5:$B$400="TRASIEGO")*(MOVIMIENTOS!$C$5:$C$400="P")*(MOVIMIENTOS!$D$5:$D$400="jabas")*(MOVIMIENTOS!$A$5:$A$400<>"")*(MOVIMIENTOS!$A$5:$A$400<=$A6)*MOVIMIENTOS!$E$5:$E$400)-SUMPRODUCT((MOVIMIENTOS!$B$5:$B$400="REGALO")*(MOVIMIENTOS!$C$5:$C$400="P")*(MOVIMIENTOS!$D$5:$D$400="jabas")*(MOVIMIENTOS!$A$5:$A$400<>"")*(MOVIMIENTOS!$A$5:$A$400<=$A6)*MOVIMIENTOS!$E$5:$E$400)-SUMPRODUCT((MOVIMIENTOS!$B$5:$B$400="VENTA")*(MOVIMIENTOS!$C$5:$C$400="P")*(MOVIMIENTOS!$D$5:$D$400="jabas")*(MOVIMIENTOS!$A$5:$A$400<>"")*(MOVIMIENTOS!$A$5:$A$400<=$A6)*MOVIMIENTOS!$E$5:$E$400)+SUMPRODUCT((MOVIMIENTOS!$B$5:$B$400="AJUSTE")*(MOVIMIENTOS!$C$5:$C$400="P")*(MOVIMIENTOS!$D$5:$D$400="jabas")*(MOVIMIENTOS!$A$5:$A$400<>"")*(MOVIMIENTOS!$A$5:$A$400<=$A6)*MOVIMIENTOS!$E$5:$E$400)) -> 0 | D6: =IF($A6="","",SUMPRODUCT((MOVIMIENTOS!$B$5:$B$400="SALDO INICIAL")*(MOVIMIENTOS!$C$5:$C$400="C")*(MOVIMIENTOS!$D$5:$D$400="jabas")*(MOVIMIENTOS!$A$5:$A$400<>"")*(MOVIMIENTOS!$A$5:$A$400<=$A6)*MOVIMIENTOS!$E$5:$E$400)+SUMPRODUCT((MOVIMIENTOS!$B$5:$B$400="PROCESO")*(MOVIMIENTOS!$C$5:$C$400="C")*(MOVIMIENTOS!$D$5:$D$400="jabas")*(MOVIMIENTOS!$A$5:$A$400<>"")*(MOVIMIENTOS!$A$5:$A$400<=$A6)*MOVIMIENTOS!$E$5:$E$400)-SUMPRODUCT((MOVIMIENTOS!$B$5:$B$400="ENVÍO A SUPESA")*(MOVIMIENTOS!$C$5:$C$400="C")*(MOVIMIENTOS!$D$5:$D$400="jabas")*(MOVIMIENTOS!$A$5:$A$400<>"")*(MOVIMIENTOS!$A$5:$A$400<=$A6)*MOVIMIENTOS!$E$5:$E$400)+SUMPRODUCT((MOVIMIENTOS!$B$5:$B$400="DEVOLUCIÓN")*(MOVIMIENTOS!$C$5:$C$400="C")*(MOVIMIENTOS!$D$5:$D$400="jabas")*(MOVIMIENTOS!$A$5:$A$400<>"")*(MOVIMIENTOS!$A$5:$A$400<=$A6)*MOVIMIENTOS!$E$5:$E$400)-SUMPRODUCT((MOVIMIENTOS!$B$5:$B$400="TRASIEGO")*(MOVIMIENTOS!$C$5:$C$400="C")*(MOVIMIENTOS!$D$5:$D$400="jabas")*(MOVIMIENTOS!$A$5:$A$400<>"")*(MOVIMIENTOS!$A$5:$A$400<=$A6)*MOVIMIENTOS!$E$5:$E$400)-SUMPRODUCT((MOVIMIENTOS!$B$5:$B$400="REGALO")*(MOVIMIENTOS!$C$5:$C$400="C")*(MOVIMIENTOS!$D$5:$D$400="jabas")*(MOVIMIENTOS!$A$5:$A$400<>"")*(MOVIMIENTOS!$A$5:$A$400<=$A6)*MOVIMIENTOS!$E$5:$E$400)-SUMPRODUCT((MOVIMIENTOS!$B$5:$B$400="VENTA")*(MOVIMIENTOS!$C$5:$C$400="C")*(MOVIMIENTOS!$D$5:$D$400="jabas")*(MOVIMIENTOS!$A$5:$A$400<>"")*(MOVIMIENTOS!$A$5:$A$400<=$A6)*MOVIMIENTOS!$E$5:$E$400)+SUMPRODUCT((MOVIMIENTOS!$B$5:$B$400="AJUSTE")*(MOVIMIENTOS!$C$5:$C$400="C")*(MOVIMIENTOS!$D$5:$D$400="jabas")*(MOVIMIENTOS!$A$5:$A$400<>"")*(MOVIMIENTOS!$A$5:$A$400<=$A6)*MOVIMIENTOS!$E$5:$E$400)) -> 0 | E6: =IF($A6="","",SUMPRODUCT((MOVIMIENTOS!$B$5:$B$400="SALDO INICIAL")*(MOVIMIENTOS!$C$5:$C$400="M")*(MOVIMIENTOS!$D$5:$D$400="jabas")*(MOVIMIENTOS!$A$5:$A$400<>"")*(MOVIMIENTOS!$A$5:$A$400<=$A6)*MOVIMIENTOS!$E$5:$E$400)+SUMPRODUCT((MOVIMIENTOS!$B$5:$B$400="PROCESO")*(MOVIMIENTOS!$C$5:$C$400="M")*(MOVIMIENTOS!$D$5:$D$400="jabas")*(MOVIMIENTOS!$A$5:$A$400<>"")*(MOVIMIENTOS!$A$5:$A$400<=$A6)*MOVIMIENTOS!$E$5:$E$400)-SUMPRODUCT((MOVIMIENTOS!$B$5:$B$400="ENVÍO A SUPESA")*(MOVIMIENTOS!$C$5:$C$400="M")*(MOVIMIENTOS!$D$5:$D$400="jabas")*(MOVIMIENTOS!$A$5:$A$400<>"")*(MOVIMIENTOS!$A$5:$A$400<=$A6)*MOVIMIENTOS!$E$5:$E$400)+SUMPRODUCT((MOVIMIENTOS!$B$5:$B$400="DEVOLUCIÓN")*(MOVIMIENTOS!$C$5:$C$400="M")*(MOVIMIENTOS!$D$5:$D$400="jabas")*(MOVIMIENTOS!$A$5:$A$400<>"")*(MOVIMIENTOS!$A$5:$A$400<=$A6)*MOVIMIENTOS!$E$5:$E$400)-SUMPRODUCT((MOVIMIENTOS!$B$5:$B$400="TRASIEGO")*(MOVIMIENTOS!$C$5:$C$400="M")*(MOVIMIENTOS!$D$5:$D$400="jabas")*(MOVIMIENTOS!$A$5:$A$400<>"")*(MOVIMIENTOS!$A$5:$A$400<=$A6)*MOVIMIENTOS!$E$5:$E$400)-SUMPRODUCT((MOVIMIENTOS!$B$5:$B$400="REGALO")*(MOVIMIENTOS!$C$5:$C$400="M")*(MOVIMIENTOS!$D$5:$D$400="jabas")*(MOVIMIENTOS!$A$5:$A$400<>"")*(MOVIMIENTOS!$A$5:$A$400<=$A6)*MOVIMIENTOS!$E$5:$E$400)-SUMPRODUCT((MOVIMIENTOS!$B$5:$B$400="VENTA")*(MOVIMIENTOS!$C$5:$C$400="M")*(MOVIMIENTOS!$D$5:$D$400="jabas")*(MOVIMIENTOS!$A$5:$A$400<>"")*(MOVIMIENTOS!$A$5:$A$400<=$A6)*MOVIMIENTOS!$E$5:$E$400)+SUMPRODUCT((MOVIMIENTOS!$B$5:$B$400="AJUSTE")*(MOVIMIENTOS!$C$5:$C$400="M")*(MOVIMIENTOS!$D$5:$D$400="jabas")*(MOVIMIENTOS!$A$5:$A$400<>"")*(MOVIMIENTOS!$A$5:$A$400<=$A6)*MOVIMIENTOS!$E$5:$E$400)) -> 30 | F6: =IF($A6="","",SUMPRODUCT((MOVIMIENTOS!$B$5:$B$400="SALDO INICIAL")*(MOVIMIENTOS!$C$5:$C$400="Chancho")*(MOVIMIENTOS!$D$5:$D$400="sacos")*(MOVIMIENTOS!$A$5:$A$400<>"")*(MOVIMIENTOS!$A$5:$A$400<=$A6)*MOVIMIENTOS!$E$5:$E$400)+SUMPRODUCT((MOVIMIENTOS!$B$5:$B$400="PROCESO")*(MOVIMIENTOS!$C$5:$C$400="Chancho")*(MOVIMIENTOS!$D$5:$D$400="sacos")*(MOVIMIENTOS!$A$5:$A$400<>"")*(MOVIMIENTOS!$A$5:$A$400<=$A6)*MOVIMIENTOS!$E$5:$E$400)-SUMPRODUCT((MOVIMIENTOS!$B$5:$B$400="VENTA CHANCHO")*(MOVIMIENTOS!$C$5:$C$400="Chancho")*(MOVIMIENTOS!$D$5:$D$400="sacos")*(MOVIMIENTOS!$A$5:$A$400<>"")*(MOVIMIENTOS!$A$5:$A$400<=$A6)*MOVIMIENTOS!$E$5:$E$400)-SUMPRODUCT((MOVIMIENTOS!$B$5:$B$400="REGALO")*(MOVIMIENTOS!$C$5:$C$400="Chancho")*(MOVIMIENTOS!$D$5:$D$400="sacos")*(MOVIMIENTOS!$A$5:$A$400<>"")*(MOVIMIENTOS!$A$5:$A$400<=$A6)*MOVIMIENTOS!$E$5:$E$400)-SUMPRODUCT((MOVIMIENTOS!$B$5:$B$400="VENTA")*(MOVIMIENTOS!$C$5:$C$400="Chancho")*(MOVIMIENTOS!$D$5:$D$400="sacos")*(MOVIMIENTOS!$A$5:$A$400<>"")*(MOVIMIENTOS!$A$5:$A$400<=$A6)*MOVIMIENTOS!$E$5:$E$400)+SUMPRODUCT((MOVIMIENTOS!$B$5:$B$400="AJUSTE")*(MOVIMIENTOS!$C$5:$C$400="Chancho")*(MOVIMIENTOS!$D$5:$D$400="sacos")*(MOVIMIENTOS!$A$5:$A$400<>"")*(MOVIMIENTOS!$A$5:$A$400<=$A6)*MOVIMIENTOS!$E$5:$E$400)) -> 26 | G6: =IF($A6="","",SUM(B6:E6)) -> 24 | H6: =IF($A6="","",SUMPRODUCT((((MOVIMIENTOS!$B$5:$B$400="SALDO INICIAL")*(MOVIMIENTOS!$C$5:$C$400<>"Chancho"))+(MOVIMIENTOS!$B$5:$B$400="COMPRA")+(MOVIMIENTOS!$B$5:$B$400="REPROCESO")+(MOVIMIENTOS!$B$5:$B$400="DEVOLUCIÓN")+((MOVIMIENTOS!$B$5:$B$400="AJUSTE")*(MOVIMIENTOS!$C$5:$C$400<>"Chancho")))*(MOVIMIENTOS!$A$5:$A$400<>"")*(MOVIMIENTOS!$A$5:$A$400<=$A6)*MOVIMIENTOS!$I$5:$I$400)-SUMPRODUCT(((MOVIMIENTOS!$B$5:$B$400="ENVÍO A SUPESA")+(MOVIMIENTOS!$B$5:$B$400="ENVÍO A TOTTUS")+(MOVIMIENTOS!$B$5:$B$400="ENVIO A TOTTUS")+(MOVIMIENTOS!$B$5:$B$400="MALOGRADO")+(MOVIMIENTOS!$B$5:$B$400="OTRA SALIDA")+((MOVIMIENTOS!$B$5:$B$400="PROCESO")*(MOVIMIENTOS!$C$5:$C$400="Chancho"))+((MOVIMIENTOS!$B$5:$B$400="REGALO")*(MOVIMIENTOS!$C$5:$C$400<>"Chancho"))+((MOVIMIENTOS!$B$5:$B$400="VENTA")*(MOVIMIENTOS!$C$5:$C$400<>"Chancho")))*(MOVIMIENTOS!$A$5:$A$400<>"")*(MOVIMIENTOS!$A$5:$A$400<=$A6)*MOVIMIENTOS!$I$5:$I$400)) -> 373 | J6: =IF(AND(MOVIMIENTOS!$A6<>"",COUNTIF(MOVIMIENTOS!$A$5:$A5,MOVIMIENTOS!$A6)=0),COUNT(J$4:J5)+1,"") | K6: =MOVIMIENTOS!$A6 -> 46214
A7: =IFERROR(INDEX(K$5:K$400,MATCH(ROW()-4,J$5:J$400,0)),"") -> 46216 | B7: =IF($A7="","",SUMPRODUCT((MOVIMIENTOS!$B$5:$B$400="SALDO INICIAL")*(MOVIMIENTOS!$C$5:$C$400="A")*(MOVIMIENTOS!$D$5:$D$400="jabas")*(MOVIMIENTOS!$A$5:$A$400<>"")*(MOVIMIENTOS!$A$5:$A$400<=$A7)*MOVIMIENTOS!$E$5:$E$400)+SUMPRODUCT((MOVIMIENTOS!$B$5:$B$400="PROCESO")*(MOVIMIENTOS!$C$5:$C$400="A")*(MOVIMIENTOS!$D$5:$D$400="jabas")*(MOVIMIENTOS!$A$5:$A$400<>"")*(MOVIMIENTOS!$A$5:$A$400<=$A7)*MOVIMIENTOS!$E$5:$E$400)-SUMPRODUCT((MOVIMIENTOS!$B$5:$B$400="ENVÍO A SUPESA")*(MOVIMIENTOS!$C$5:$C$400="A")*(MOVIMIENTOS!$D$5:$D$400="jabas")*(MOVIMIENTOS!$A$5:$A$400<>"")*(MOVIMIENTOS!$A$5:$A$400<=$A7)*MOVIMIENTOS!$E$5:$E$400)+SUMPRODUCT((MOVIMIENTOS!$B$5:$B$400="DEVOLUCIÓN")*(MOVIMIENTOS!$C$5:$C$400="A")*(MOVIMIENTOS!$D$5:$D$400="jabas")*(MOVIMIENTOS!$A$5:$A$400<>"")*(MOVIMIENTOS!$A$5:$A$400<=$A7)*MOVIMIENTOS!$E$5:$E$400)-SUMPRODUCT((MOVIMIENTOS!$B$5:$B$400="TRASIEGO")*(MOVIMIENTOS!$C$5:$C$400="A")*(MOVIMIENTOS!$D$5:$D$400="jabas")*(MOVIMIENTOS!$A$5:$A$400<>"")*(MOVIMIENTOS!$A$5:$A$400<=$A7)*MOVIMIENTOS!$E$5:$E$400)-SUMPRODUCT((MOVIMIENTOS!$B$5:$B$400="REGALO")*(MOVIMIENTOS!$C$5:$C$400="A")*(MOVIMIENTOS!$D$5:$D$400="jabas")*(MOVIMIENTOS!$A$5:$A$400<>"")*(MOVIMIENTOS!$A$5:$A$400<=$A7)*MOVIMIENTOS!$E$5:$E$400)-SUMPRODUCT((MOVIMIENTOS!$B$5:$B$400="VENTA")*(MOVIMIENTOS!$C$5:$C$400="A")*(MOVIMIENTOS!$D$5:$D$400="jabas")*(MOVIMIENTOS!$A$5:$A$400<>"")*(MOVIMIENTOS!$A$5:$A$400<=$A7)*MOVIMIENTOS!$E$5:$E$400)+SUMPRODUCT((MOVIMIENTOS!$B$5:$B$400="AJUSTE")*(MOVIMIENTOS!$C$5:$C$400="A")*(MOVIMIENTOS!$D$5:$D$400="jabas")*(MOVIMIENTOS!$A$5:$A$400<>"")*(MOVIMIENTOS!$A$5:$A$400<=$A7)*MOVIMIENTOS!$E$5:$E$400)) -> 34 | C7: =IF($A7="","",SUMPRODUCT((MOVIMIENTOS!$B$5:$B$400="SALDO INICIAL")*(MOVIMIENTOS!$C$5:$C$400="P")*(MOVIMIENTOS!$D$5:$D$400="jabas")*(MOVIMIENTOS!$A$5:$A$400<>"")*(MOVIMIENTOS!$A$5:$A$400<=$A7)*MOVIMIENTOS!$E$5:$E$400)+SUMPRODUCT((MOVIMIENTOS!$B$5:$B$400="PROCESO")*(MOVIMIENTOS!$C$5:$C$400="P")*(MOVIMIENTOS!$D$5:$D$400="jabas")*(MOVIMIENTOS!$A$5:$A$400<>"")*(MOVIMIENTOS!$A$5:$A$400<=$A7)*MOVIMIENTOS!$E$5:$E$400)-SUMPRODUCT((MOVIMIENTOS!$B$5:$B$400="ENVÍO A SUPESA")*(MOVIMIENTOS!$C$5:$C$400="P")*(MOVIMIENTOS!$D$5:$D$400="jabas")*(MOVIMIENTOS!$A$5:$A$400<>"")*(MOVIMIENTOS!$A$5:$A$400<=$A7)*MOVIMIENTOS!$E$5:$E$400)+SUMPRODUCT((MOVIMIENTOS!$B$5:$B$400="DEVOLUCIÓN")*(MOVIMIENTOS!$C$5:$C$400="P")*(MOVIMIENTOS!$D$5:$D$400="jabas")*(MOVIMIENTOS!$A$5:$A$400<>"")*(MOVIMIENTOS!$A$5:$A$400<=$A7)*MOVIMIENTOS!$E$5:$E$400)-SUMPRODUCT((MOVIMIENTOS!$B$5:$B$400="TRASIEGO")*(MOVIMIENTOS!$C$5:$C$400="P")*(MOVIMIENTOS!$D$5:$D$400="jabas")*(MOVIMIENTOS!$A$5:$A$400<>"")*(MOVIMIENTOS!$A$5:$A$400<=$A7)*MOVIMIENTOS!$E$5:$E$400)-SUMPRODUCT((MOVIMIENTOS!$B$5:$B$400="REGALO")*(MOVIMIENTOS!$C$5:$C$400="P")*(MOVIMIENTOS!$D$5:$D$400="jabas")*(MOVIMIENTOS!$A$5:$A$400<>"")*(MOVIMIENTOS!$A$5:$A$400<=$A7)*MOVIMIENTOS!$E$5:$E$400)-SUMPRODUCT((MOVIMIENTOS!$B$5:$B$400="VENTA")*(MOVIMIENTOS!$C$5:$C$400="P")*(MOVIMIENTOS!$D$5:$D$400="jabas")*(MOVIMIENTOS!$A$5:$A$400<>"")*(MOVIMIENTOS!$A$5:$A$400<=$A7)*MOVIMIENTOS!$E$5:$E$400)+SUMPRODUCT((MOVIMIENTOS!$B$5:$B$400="AJUSTE")*(MOVIMIENTOS!$C$5:$C$400="P")*(MOVIMIENTOS!$D$5:$D$400="jabas")*(MOVIMIENTOS!$A$5:$A$400<>"")*(MOVIMIENTOS!$A$5:$A$400<=$A7)*MOVIMIENTOS!$E$5:$E$400)) -> 0 | D7: =IF($A7="","",SUMPRODUCT((MOVIMIENTOS!$B$5:$B$400="SALDO INICIAL")*(MOVIMIENTOS!$C$5:$C$400="C")*(MOVIMIENTOS!$D$5:$D$400="jabas")*(MOVIMIENTOS!$A$5:$A$400<>"")*(MOVIMIENTOS!$A$5:$A$400<=$A7)*MOVIMIENTOS!$E$5:$E$400)+SUMPRODUCT((MOVIMIENTOS!$B$5:$B$400="PROCESO")*(MOVIMIENTOS!$C$5:$C$400="C")*(MOVIMIENTOS!$D$5:$D$400="jabas")*(MOVIMIENTOS!$A$5:$A$400<>"")*(MOVIMIENTOS!$A$5:$A$400<=$A7)*MOVIMIENTOS!$E$5:$E$400)-SUMPRODUCT((MOVIMIENTOS!$B$5:$B$400="ENVÍO A SUPESA")*(MOVIMIENTOS!$C$5:$C$400="C")*(MOVIMIENTOS!$D$5:$D$400="jabas")*(MOVIMIENTOS!$A$5:$A$400<>"")*(MOVIMIENTOS!$A$5:$A$400<=$A7)*MOVIMIENTOS!$E$5:$E$400)+SUMPRODUCT((MOVIMIENTOS!$B$5:$B$400="DEVOLUCIÓN")*(MOVIMIENTOS!$C$5:$C$400="C")*(MOVIMIENTOS!$D$5:$D$400="jabas")*(MOVIMIENTOS!$A$5:$A$400<>"")*(MOVIMIENTOS!$A$5:$A$400<=$A7)*MOVIMIENTOS!$E$5:$E$400)-SUMPRODUCT((MOVIMIENTOS!$B$5:$B$400="TRASIEGO")*(MOVIMIENTOS!$C$5:$C$400="C")*(MOVIMIENTOS!$D$5:$D$400="jabas")*(MOVIMIENTOS!$A$5:$A$400<>"")*(MOVIMIENTOS!$A$5:$A$400<=$A7)*MOVIMIENTOS!$E$5:$E$400)-SUMPRODUCT((MOVIMIENTOS!$B$5:$B$400="REGALO")*(MOVIMIENTOS!$C$5:$C$400="C")*(MOVIMIENTOS!$D$5:$D$400="jabas")*(MOVIMIENTOS!$A$5:$A$400<>"")*(MOVIMIENTOS!$A$5:$A$400<=$A7)*MOVIMIENTOS!$E$5:$E$400)-SUMPRODUCT((MOVIMIENTOS!$B$5:$B$400="VENTA")*(MOVIMIENTOS!$C$5:$C$400="C")*(MOVIMIENTOS!$D$5:$D$400="jabas")*(MOVIMIENTOS!$A$5:$A$400<>"")*(MOVIMIENTOS!$A$5:$A$400<=$A7)*MOVIMIENTOS!$E$5:$E$400)+SUMPRODUCT((MOVIMIENTOS!$B$5:$B$400="AJUSTE")*(MOVIMIENTOS!$C$5:$C$400="C")*(MOVIMIENTOS!$D$5:$D$400="jabas")*(MOVIMIENTOS!$A$5:$A$400<>"")*(MOVIMIENTOS!$A$5:$A$400<=$A7)*MOVIMIENTOS!$E$5:$E$400)) -> 0 | E7: =IF($A7="","",SUMPRODUCT((MOVIMIENTOS!$B$5:$B$400="SALDO INICIAL")*(MOVIMIENTOS!$C$5:$C$400="M")*(MOVIMIENTOS!$D$5:$D$400="jabas")*(MOVIMIENTOS!$A$5:$A$400<>"")*(MOVIMIENTOS!$A$5:$A$400<=$A7)*MOVIMIENTOS!$E$5:$E$400)+SUMPRODUCT((MOVIMIENTOS!$B$5:$B$400="PROCESO")*(MOVIMIENTOS!$C$5:$C$400="M")*(MOVIMIENTOS!$D$5:$D$400="jabas")*(MOVIMIENTOS!$A$5:$A$400<>"")*(MOVIMIENTOS!$A$5:$A$400<=$A7)*MOVIMIENTOS!$E$5:$E$400)-SUMPRODUCT((MOVIMIENTOS!$B$5:$B$400="ENVÍO A SUPESA")*(MOVIMIENTOS!$C$5:$C$400="M")*(MOVIMIENTOS!$D$5:$D$400="jabas")*(MOVIMIENTOS!$A$5:$A$400<>"")*(MOVIMIENTOS!$A$5:$A$400<=$A7)*MOVIMIENTOS!$E$5:$E$400)+SUMPRODUCT((MOVIMIENTOS!$B$5:$B$400="DEVOLUCIÓN")*(MOVIMIENTOS!$C$5:$C$400="M")*(MOVIMIENTOS!$D$5:$D$400="jabas")*(MOVIMIENTOS!$A$5:$A$400<>"")*(MOVIMIENTOS!$A$5:$A$400<=$A7)*MOVIMIENTOS!$E$5:$E$400)-SUMPRODUCT((MOVIMIENTOS!$B$5:$B$400="TRASIEGO")*(MOVIMIENTOS!$C$5:$C$400="M")*(MOVIMIENTOS!$D$5:$D$400="jabas")*(MOVIMIENTOS!$A$5:$A$400<>"")*(MOVIMIENTOS!$A$5:$A$400<=$A7)*MOVIMIENTOS!$E$5:$E$400)-SUMPRODUCT((MOVIMIENTOS!$B$5:$B$400="REGALO")*(MOVIMIENTOS!$C$5:$C$400="M")*(MOVIMIENTOS!$D$5:$D$400="jabas")*(MOVIMIENTOS!$A$5:$A$400<>"")*(MOVIMIENTOS!$A$5:$A$400<=$A7)*MOVIMIENTOS!$E$5:$E$400)-SUMPRODUCT((MOVIMIENTOS!$B$5:$B$400="VENTA")*(MOVIMIENTOS!$C$5:$C$400="M")*(MOVIMIENTOS!$D$5:$D$400="jabas")*(MOVIMIENTOS!$A$5:$A$400<>"")*(MOVIMIENTOS!$A$5:$A$400<=$A7)*MOVIMIENTOS!$E$5:$E$400)+SUMPRODUCT((MOVIMIENTOS!$B$5:$B$400="AJUSTE")*(MOVIMIENTOS!$C$5:$C$400="M")*(MOVIMIENTOS!$D$5:$D$400="jabas")*(MOVIMIENTOS!$A$5:$A$400<>"")*(MOVIMIENTOS!$A$5:$A$400<=$A7)*MOVIMIENTOS!$E$5:$E$400)) -> 43 | F7: =IF($A7="","",SUMPRODUCT((MOVIMIENTOS!$B$5:$B$400="SALDO INICIAL")*(MOVIMIENTOS!$C$5:$C$400="Chancho")*(MOVIMIENTOS!$D$5:$D$400="sacos")*(MOVIMIENTOS!$A$5:$A$400<>"")*(MOVIMIENTOS!$A$5:$A$400<=$A7)*MOVIMIENTOS!$E$5:$E$400)+SUMPRODUCT((MOVIMIENTOS!$B$5:$B$400="PROCESO")*(MOVIMIENTOS!$C$5:$C$400="Chancho")*(MOVIMIENTOS!$D$5:$D$400="sacos")*(MOVIMIENTOS!$A$5:$A$400<>"")*(MOVIMIENTOS!$A$5:$A$400<=$A7)*MOVIMIENTOS!$E$5:$E$400)-SUMPRODUCT((MOVIMIENTOS!$B$5:$B$400="VENTA CHANCHO")*(MOVIMIENTOS!$C$5:$C$400="Chancho")*(MOVIMIENTOS!$D$5:$D$400="sacos")*(MOVIMIENTOS!$A$5:$A$400<>"")*(MOVIMIENTOS!$A$5:$A$400<=$A7)*MOVIMIENTOS!$E$5:$E$400)-SUMPRODUCT((MOVIMIENTOS!$B$5:$B$400="REGALO")*(MOVIMIENTOS!$C$5:$C$400="Chancho")*(MOVIMIENTOS!$D$5:$D$400="sacos")*(MOVIMIENTOS!$A$5:$A$400<>"")*(MOVIMIENTOS!$A$5:$A$400<=$A7)*MOVIMIENTOS!$E$5:$E$400)-SUMPRODUCT((MOVIMIENTOS!$B$5:$B$400="VENTA")*(MOVIMIENTOS!$C$5:$C$400="Chancho")*(MOVIMIENTOS!$D$5:$D$400="sacos")*(MOVIMIENTOS!$A$5:$A$400<>"")*(MOVIMIENTOS!$A$5:$A$400<=$A7)*MOVIMIENTOS!$E$5:$E$400)+SUMPRODUCT((MOVIMIENTOS!$B$5:$B$400="AJUSTE")*(MOVIMIENTOS!$C$5:$C$400="Chancho")*(MOVIMIENTOS!$D$5:$D$400="sacos")*(MOVIMIENTOS!$A$5:$A$400<>"")*(MOVIMIENTOS!$A$5:$A$400<=$A7)*MOVIMIENTOS!$E$5:$E$400)) -> 28 | G7: =IF($A7="","",SUM(B7:E7)) -> 77 | H7: =IF($A7="","",SUMPRODUCT((((MOVIMIENTOS!$B$5:$B$400="SALDO INICIAL")*(MOVIMIENTOS!$C$5:$C$400<>"Chancho"))+(MOVIMIENTOS!$B$5:$B$400="COMPRA")+(MOVIMIENTOS!$B$5:$B$400="REPROCESO")+(MOVIMIENTOS!$B$5:$B$400="DEVOLUCIÓN")+((MOVIMIENTOS!$B$5:$B$400="AJUSTE")*(MOVIMIENTOS!$C$5:$C$400<>"Chancho")))*(MOVIMIENTOS!$A$5:$A$400<>"")*(MOVIMIENTOS!$A$5:$A$400<=$A7)*MOVIMIENTOS!$I$5:$I$400)-SUMPRODUCT(((MOVIMIENTOS!$B$5:$B$400="ENVÍO A SUPESA")+(MOVIMIENTOS!$B$5:$B$400="ENVÍO A TOTTUS")+(MOVIMIENTOS!$B$5:$B$400="ENVIO A TOTTUS")+(MOVIMIENTOS!$B$5:$B$400="MALOGRADO")+(MOVIMIENTOS!$B$5:$B$400="OTRA SALIDA")+((MOVIMIENTOS!$B$5:$B$400="PROCESO")*(MOVIMIENTOS!$C$5:$C$400="Chancho"))+((MOVIMIENTOS!$B$5:$B$400="REGALO")*(MOVIMIENTOS!$C$5:$C$400<>"Chancho"))+((MOVIMIENTOS!$B$5:$B$400="VENTA")*(MOVIMIENTOS!$C$5:$C$400<>"Chancho")))*(MOVIMIENTOS!$A$5:$A$400<>"")*(MOVIMIENTOS!$A$5:$A$400<=$A7)*MOVIMIENTOS!$I$5:$I$400)) -> 1003 | J7: =IF(AND(MOVIMIENTOS!$A7<>"",COUNTIF(MOVIMIENTOS!$A$5:$A6,MOVIMIENTOS!$A7)=0),COUNT(J$4:J6)+1,"") | K7: =MOVIMIENTOS!$A7 -> 46214
A8: =IFERROR(INDEX(K$5:K$400,MATCH(ROW()-4,J$5:J$400,0)),"") -> 46217 | B8: =IF($A8="","",SUMPRODUCT((MOVIMIENTOS!$B$5:$B$400="SALDO INICIAL")*(MOVIMIENTOS!$C$5:$C$400="A")*(MOVIMIENTOS!$D$5:$D$400="jabas")*(MOVIMIENTOS!$A$5:$A$400<>"")*(MOVIMIENTOS!$A$5:$A$400<=$A8)*MOVIMIENTOS!$E$5:$E$400)+SUMPRODUCT((MOVIMIENTOS!$B$5:$B$400="PROCESO")*(MOVIMIENTOS!$C$5:$C$400="A")*(MOVIMIENTOS!$D$5:$D$400="jabas")*(MOVIMIENTOS!$A$5:$A$400<>"")*(MOVIMIENTOS!$A$5:$A$400<=$A8)*MOVIMIENTOS!$E$5:$E$400)-SUMPRODUCT((MOVIMIENTOS!$B$5:$B$400="ENVÍO A SUPESA")*(MOVIMIENTOS!$C$5:$C$400="A")*(MOVIMIENTOS!$D$5:$D$400="jabas")*(MOVIMIENTOS!$A$5:$A$400<>"")*(MOVIMIENTOS!$A$5:$A$400<=$A8)*MOVIMIENTOS!$E$5:$E$400)+SUMPRODUCT((MOVIMIENTOS!$B$5:$B$400="DEVOLUCIÓN")*(MOVIMIENTOS!$C$5:$C$400="A")*(MOVIMIENTOS!$D$5:$D$400="jabas")*(MOVIMIENTOS!$A$5:$A$400<>"")*(MOVIMIENTOS!$A$5:$A$400<=$A8)*MOVIMIENTOS!$E$5:$E$400)-SUMPRODUCT((MOVIMIENTOS!$B$5:$B$400="TRASIEGO")*(MOVIMIENTOS!$C$5:$C$400="A")*(MOVIMIENTOS!$D$5:$D$400="jabas")*(MOVIMIENTOS!$A$5:$A$400<>"")*(MOVIMIENTOS!$A$5:$A$400<=$A8)*MOVIMIENTOS!$E$5:$E$400)-SUMPRODUCT((MOVIMIENTOS!$B$5:$B$400="REGALO")*(MOVIMIENTOS!$C$5:$C$400="A")*(MOVIMIENTOS!$D$5:$D$400="jabas")*(MOVIMIENTOS!$A$5:$A$400<>"")*(MOVIMIENTOS!$A$5:$A$400<=$A8)*MOVIMIENTOS!$E$5:$E$400)-SUMPRODUCT((MOVIMIENTOS!$B$5:$B$400="VENTA")*(MOVIMIENTOS!$C$5:$C$400="A")*(MOVIMIENTOS!$D$5:$D$400="jabas")*(MOVIMIENTOS!$A$5:$A$400<>"")*(MOVIMIENTOS!$A$5:$A$400<=$A8)*MOVIMIENTOS!$E$5:$E$400)+SUMPRODUCT((MOVIMIENTOS!$B$5:$B$400="AJUSTE")*(MOVIMIENTOS!$C$5:$C$400="A")*(MOVIMIENTOS!$D$5:$D$400="jabas")*(MOVIMIENTOS!$A$5:$A$400<>"")*(MOVIMIENTOS!$A$5:$A$400<=$A8)*MOVIMIENTOS!$E$5:$E$400)) -> 12 | C8: =IF($A8="","",SUMPRODUCT((MOVIMIENTOS!$B$5:$B$400="SALDO INICIAL")*(MOVIMIENTOS!$C$5:$C$400="P")*(MOVIMIENTOS!$D$5:$D$400="jabas")*(MOVIMIENTOS!$A$5:$A$400<>"")*(MOVIMIENTOS!$A$5:$A$400<=$A8)*MOVIMIENTOS!$E$5:$E$400)+SUMPRODUCT((MOVIMIENTOS!$B$5:$B$400="PROCESO")*(MOVIMIENTOS!$C$5:$C$400="P")*(MOVIMIENTOS!$D$5:$D$400="jabas")*(MOVIMIENTOS!$A$5:$A$400<>"")*(MOVIMIENTOS!$A$5:$A$400<=$A8)*MOVIMIENTOS!$E$5:$E$400)-SUMPRODUCT((MOVIMIENTOS!$B$5:$B$400="ENVÍO A SUPESA")*(MOVIMIENTOS!$C$5:$C$400="P")*(MOVIMIENTOS!$D$5:$D$400="jabas")*(MOVIMIENTOS!$A$5:$A$400<>"")*(MOVIMIENTOS!$A$5:$A$400<=$A8)*MOVIMIENTOS!$E$5:$E$400)+SUMPRODUCT((MOVIMIENTOS!$B$5:$B$400="DEVOLUCIÓN")*(MOVIMIENTOS!$C$5:$C$400="P")*(MOVIMIENTOS!$D$5:$D$400="jabas")*(MOVIMIENTOS!$A$5:$A$400<>"")*(MOVIMIENTOS!$A$5:$A$400<=$A8)*MOVIMIENTOS!$E$5:$E$400)-SUMPRODUCT((MOVIMIENTOS!$B$5:$B$400="TRASIEGO")*(MOVIMIENTOS!$C$5:$C$400="P")*(MOVIMIENTOS!$D$5:$D$400="jabas")*(MOVIMIENTOS!$A$5:$A$400<>"")*(MOVIMIENTOS!$A$5:$A$400<=$A8)*MOVIMIENTOS!$E$5:$E$400)-SUMPRODUCT((MOVIMIENTOS!$B$5:$B$400="REGALO")*(MOVIMIENTOS!$C$5:$C$400="P")*(MOVIMIENTOS!$D$5:$D$400="jabas")*(MOVIMIENTOS!$A$5:$A$400<>"")*(MOVIMIENTOS!$A$5:$A$400<=$A8)*MOVIMIENTOS!$E$5:$E$400)-SUMPRODUCT((MOVIMIENTOS!$B$5:$B$400="VENTA")*(MOVIMIENTOS!$C$5:$C$400="P")*(MOVIMIENTOS!$D$5:$D$400="jabas")*(MOVIMIENTOS!$A$5:$A$400<>"")*(MOVIMIENTOS!$A$5:$A$400<=$A8)*MOVIMIENTOS!$E$5:$E$400)+SUMPRODUCT((MOVIMIENTOS!$B$5:$B$400="AJUSTE")*(MOVIMIENTOS!$C$5:$C$400="P")*(MOVIMIENTOS!$D$5:$D$400="jabas")*(MOVIMIENTOS!$A$5:$A$400<>"")*(MOVIMIENTOS!$A$5:$A$400<=$A8)*MOVIMIENTOS!$E$5:$E$400)) -> 0 | D8: =IF($A8="","",SUMPRODUCT((MOVIMIENTOS!$B$5:$B$400="SALDO INICIAL")*(MOVIMIENTOS!$C$5:$C$400="C")*(MOVIMIENTOS!$D$5:$D$400="jabas")*(MOVIMIENTOS!$A$5:$A$400<>"")*(MOVIMIENTOS!$A$5:$A$400<=$A8)*MOVIMIENTOS!$E$5:$E$400)+SUMPRODUCT((MOVIMIENTOS!$B$5:$B$400="PROCESO")*(MOVIMIENTOS!$C$5:$C$400="C")*(MOVIMIENTOS!$D$5:$D$400="jabas")*(MOVIMIENTOS!$A$5:$A$400<>"")*(MOVIMIENTOS!$A$5:$A$400<=$A8)*MOVIMIENTOS!$E$5:$E$400)-SUMPRODUCT((MOVIMIENTOS!$B$5:$B$400="ENVÍO A SUPESA")*(MOVIMIENTOS!$C$5:$C$400="C")*(MOVIMIENTOS!$D$5:$D$400="jabas")*(MOVIMIENTOS!$A$5:$A$400<>"")*(MOVIMIENTOS!$A$5:$A$400<=$A8)*MOVIMIENTOS!$E$5:$E$400)+SUMPRODUCT((MOVIMIENTOS!$B$5:$B$400="DEVOLUCIÓN")*(MOVIMIENTOS!$C$5:$C$400="C")*(MOVIMIENTOS!$D$5:$D$400="jabas")*(MOVIMIENTOS!$A$5:$A$400<>"")*(MOVIMIENTOS!$A$5:$A$400<=$A8)*MOVIMIENTOS!$E$5:$E$400)-SUMPRODUCT((MOVIMIENTOS!$B$5:$B$400="TRASIEGO")*(MOVIMIENTOS!$C$5:$C$400="C")*(MOVIMIENTOS!$D$5:$D$400="jabas")*(MOVIMIENTOS!$A$5:$A$400<>"")*(MOVIMIENTOS!$A$5:$A$400<=$A8)*MOVIMIENTOS!$E$5:$E$400)-SUMPRODUCT((MOVIMIENTOS!$B$5:$B$400="REGALO")*(MOVIMIENTOS!$C$5:$C$400="C")*(MOVIMIENTOS!$D$5:$D$400="jabas")*(MOVIMIENTOS!$A$5:$A$400<>"")*(MOVIMIENTOS!$A$5:$A$400<=$A8)*MOVIMIENTOS!$E$5:$E$400)-SUMPRODUCT((MOVIMIENTOS!$B$5:$B$400="VENTA")*(MOVIMIENTOS!$C$5:$C$400="C")*(MOVIMIENTOS!$D$5:$D$400="jabas")*(MOVIMIENTOS!$A$5:$A$400<>"")*(MOVIMIENTOS!$A$5:$A$400<=$A8)*MOVIMIENTOS!$E$5:$E$400)+SUMPRODUCT((MOVIMIENTOS!$B$5:$B$400="AJUSTE")*(MOVIMIENTOS!$C$5:$C$400="C")*(MOVIMIENTOS!$D$5:$D$400="jabas")*(MOVIMIENTOS!$A$5:$A$400<>"")*(MOVIMIENTOS!$A$5:$A$400<=$A8)*MOVIMIENTOS!$E$5:$E$400)) -> 0 | E8: =IF($A8="","",SUMPRODUCT((MOVIMIENTOS!$B$5:$B$400="SALDO INICIAL")*(MOVIMIENTOS!$C$5:$C$400="M")*(MOVIMIENTOS!$D$5:$D$400="jabas")*(MOVIMIENTOS!$A$5:$A$400<>"")*(MOVIMIENTOS!$A$5:$A$400<=$A8)*MOVIMIENTOS!$E$5:$E$400)+SUMPRODUCT((MOVIMIENTOS!$B$5:$B$400="PROCESO")*(MOVIMIENTOS!$C$5:$C$400="M")*(MOVIMIENTOS!$D$5:$D$400="jabas")*(MOVIMIENTOS!$A$5:$A$400<>"")*(MOVIMIENTOS!$A$5:$A$400<=$A8)*MOVIMIENTOS!$E$5:$E$400)-SUMPRODUCT((MOVIMIENTOS!$B$5:$B$400="ENVÍO A SUPESA")*(MOVIMIENTOS!$C$5:$C$400="M")*(MOVIMIENTOS!$D$5:$D$400="jabas")*(MOVIMIENTOS!$A$5:$A$400<>"")*(MOVIMIENTOS!$A$5:$A$400<=$A8)*MOVIMIENTOS!$E$5:$E$400)+SUMPRODUCT((MOVIMIENTOS!$B$5:$B$400="DEVOLUCIÓN")*(MOVIMIENTOS!$C$5:$C$400="M")*(MOVIMIENTOS!$D$5:$D$400="jabas")*(MOVIMIENTOS!$A$5:$A$400<>"")*(MOVIMIENTOS!$A$5:$A$400<=$A8)*MOVIMIENTOS!$E$5:$E$400)-SUMPRODUCT((MOVIMIENTOS!$B$5:$B$400="TRASIEGO")*(MOVIMIENTOS!$C$5:$C$400="M")*(MOVIMIENTOS!$D$5:$D$400="jabas")*(MOVIMIENTOS!$A$5:$A$400<>"")*(MOVIMIENTOS!$A$5:$A$400<=$A8)*MOVIMIENTOS!$E$5:$E$400)-SUMPRODUCT((MOVIMIENTOS!$B$5:$B$400="REGALO")*(MOVIMIENTOS!$C$5:$C$400="M")*(MOVIMIENTOS!$D$5:$D$400="jabas")*(MOVIMIENTOS!$A$5:$A$400<>"")*(MOVIMIENTOS!$A$5:$A$400<=$A8)*MOVIMIENTOS!$E$5:$E$400)-SUMPRODUCT((MOVIMIENTOS!$B$5:$B$400="VENTA")*(MOVIMIENTOS!$C$5:$C$400="M")*(MOVIMIENTOS!$D$5:$D$400="jabas")*(MOVIMIENTOS!$A$5:$A$400<>"")*(MOVIMIENTOS!$A$5:$A$400<=$A8)*MOVIMIENTOS!$E$5:$E$400)+SUMPRODUCT((MOVIMIENTOS!$B$5:$B$400="AJUSTE")*(MOVIMIENTOS!$C$5:$C$400="M")*(MOVIMIENTOS!$D$5:$D$400="jabas")*(MOVIMIENTOS!$A$5:$A$400<>"")*(MOVIMIENTOS!$A$5:$A$400<=$A8)*MOVIMIENTOS!$E$5:$E$400)) -> 48 | F8: =IF($A8="","",SUMPRODUCT((MOVIMIENTOS!$B$5:$B$400="SALDO INICIAL")*(MOVIMIENTOS!$C$5:$C$400="Chancho")*(MOVIMIENTOS!$D$5:$D$400="sacos")*(MOVIMIENTOS!$A$5:$A$400<>"")*(MOVIMIENTOS!$A$5:$A$400<=$A8)*MOVIMIENTOS!$E$5:$E$400)+SUMPRODUCT((MOVIMIENTOS!$B$5:$B$400="PROCESO")*(MOVIMIENTOS!$C$5:$C$400="Chancho")*(MOVIMIENTOS!$D$5:$D$400="sacos")*(MOVIMIENTOS!$A$5:$A$400<>"")*(MOVIMIENTOS!$A$5:$A$400<=$A8)*MOVIMIENTOS!$E$5:$E$400)-SUMPRODUCT((MOVIMIENTOS!$B$5:$B$400="VENTA CHANCHO")*(MOVIMIENTOS!$C$5:$C$400="Chancho")*(MOVIMIENTOS!$D$5:$D$400="sacos")*(MOVIMIENTOS!$A$5:$A$400<>"")*(MOVIMIENTOS!$A$5:$A$400<=$A8)*MOVIMIENTOS!$E$5:$E$400)-SUMPRODUCT((MOVIMIENTOS!$B$5:$B$400="REGALO")*(MOVIMIENTOS!$C$5:$C$400="Chancho")*(MOVIMIENTOS!$D$5:$D$400="sacos")*(MOVIMIENTOS!$A$5:$A$400<>"")*(MOVIMIENTOS!$A$5:$A$400<=$A8)*MOVIMIENTOS!$E$5:$E$400)-SUMPRODUCT((MOVIMIENTOS!$B$5:$B$400="VENTA")*(MOVIMIENTOS!$C$5:$C$400="Chancho")*(MOVIMIENTOS!$D$5:$D$400="sacos")*(MOVIMIENTOS!$A$5:$A$400<>"")*(MOVIMIENTOS!$A$5:$A$400<=$A8)*MOVIMIENTOS!$E$5:$E$400)+SUMPRODUCT((MOVIMIENTOS!$B$5:$B$400="AJUSTE")*(MOVIMIENTOS!$C$5:$C$400="Chancho")*(MOVIMIENTOS!$D$5:$D$400="sacos")*(MOVIMIENTOS!$A$5:$A$400<>"")*(MOVIMIENTOS!$A$5:$A$400<=$A8)*MOVIMIENTOS!$E$5:$E$400)) -> 35 | G8: =IF($A8="","",SUM(B8:E8)) -> 60 | H8: =IF($A8="","",SUMPRODUCT((((MOVIMIENTOS!$B$5:$B$400="SALDO INICIAL")*(MOVIMIENTOS!$C$5:$C$400<>"Chancho"))+(MOVIMIENTOS!$B$5:$B$400="COMPRA")+(MOVIMIENTOS!$B$5:$B$400="REPROCESO")+(MOVIMIENTOS!$B$5:$B$400="DEVOLUCIÓN")+((MOVIMIENTOS!$B$5:$B$400="AJUSTE")*(MOVIMIENTOS!$C$5:$C$400<>"Chancho")))*(MOVIMIENTOS!$A$5:$A$400<>"")*(MOVIMIENTOS!$A$5:$A$400<=$A8)*MOVIMIENTOS!$I$5:$I$400)-SUMPRODUCT(((MOVIMIENTOS!$B$5:$B$400="ENVÍO A SUPESA")+(MOVIMIENTOS!$B$5:$B$400="ENVÍO A TOTTUS")+(MOVIMIENTOS!$B$5:$B$400="ENVIO A TOTTUS")+(MOVIMIENTOS!$B$5:$B$400="MALOGRADO")+(MOVIMIENTOS!$B$5:$B$400="OTRA SALIDA")+((MOVIMIENTOS!$B$5:$B$400="PROCESO")*(MOVIMIENTOS!$C$5:$C$400="Chancho"))+((MOVIMIENTOS!$B$5:$B$400="REGALO")*(MOVIMIENTOS!$C$5:$C$400<>"Chancho"))+((MOVIMIENTOS!$B$5:$B$400="VENTA")*(MOVIMIENTOS!$C$5:$C$400<>"Chancho")))*(MOVIMIENTOS!$A$5:$A$400<>"")*(MOVIMIENTOS!$A$5:$A$400<=$A8)*MOVIMIENTOS!$I$5:$I$400)) -> 825 | J8: =IF(AND(MOVIMIENTOS!$A8<>"",COUNTIF(MOVIMIENTOS!$A$5:$A7,MOVIMIENTOS!$A8)=0),COUNT(J$4:J7)+1,"") | K8: =MOVIMIENTOS!$A8 -> 46214
A9: =IFERROR(INDEX(K$5:K$400,MATCH(ROW()-4,J$5:J$400,0)),"") -> 46218 | B9: =IF($A9="","",SUMPRODUCT((MOVIMIENTOS!$B$5:$B$400="SALDO INICIAL")*(MOVIMIENTOS!$C$5:$C$400="A")*(MOVIMIENTOS!$D$5:$D$400="jabas")*(MOVIMIENTOS!$A$5:$A$400<>"")*(MOVIMIENTOS!$A$5:$A$400<=$A9)*MOVIMIENTOS!$E$5:$E$400)+SUMPRODUCT((MOVIMIENTOS!$B$5:$B$400="PROCESO")*(MOVIMIENTOS!$C$5:$C$400="A")*(MOVIMIENTOS!$D$5:$D$400="jabas")*(MOVIMIENTOS!$A$5:$A$400<>"")*(MOVIMIENTOS!$A$5:$A$400<=$A9)*MOVIMIENTOS!$E$5:$E$400)-SUMPRODUCT((MOVIMIENTOS!$B$5:$B$400="ENVÍO A SUPESA")*(MOVIMIENTOS!$C$5:$C$400="A")*(MOVIMIENTOS!$D$5:$D$400="jabas")*(MOVIMIENTOS!$A$5:$A$400<>"")*(MOVIMIENTOS!$A$5:$A$400<=$A9)*MOVIMIENTOS!$E$5:$E$400)+SUMPRODUCT((MOVIMIENTOS!$B$5:$B$400="DEVOLUCIÓN")*(MOVIMIENTOS!$C$5:$C$400="A")*(MOVIMIENTOS!$D$5:$D$400="jabas")*(MOVIMIENTOS!$A$5:$A$400<>"")*(MOVIMIENTOS!$A$5:$A$400<=$A9)*MOVIMIENTOS!$E$5:$E$400)-SUMPRODUCT((MOVIMIENTOS!$B$5:$B$400="TRASIEGO")*(MOVIMIENTOS!$C$5:$C$400="A")*(MOVIMIENTOS!$D$5:$D$400="jabas")*(MOVIMIENTOS!$A$5:$A$400<>"")*(MOVIMIENTOS!$A$5:$A$400<=$A9)*MOVIMIENTOS!$E$5:$E$400)-SUMPRODUCT((MOVIMIENTOS!$B$5:$B$400="REGALO")*(MOVIMIENTOS!$C$5:$C$400="A")*(MOVIMIENTOS!$D$5:$D$400="jabas")*(MOVIMIENTOS!$A$5:$A$400<>"")*(MOVIMIENTOS!$A$5:$A$400<=$A9)*MOVIMIENTOS!$E$5:$E$400)-SUMPRODUCT((MOVIMIENTOS!$B$5:$B$400="VENTA")*(MOVIMIENTOS!$C$5:$C$400="A")*(MOVIMIENTOS!$D$5:$D$400="jabas")*(MOVIMIENTOS!$A$5:$A$400<>"")*(MOVIMIENTOS!$A$5:$A$400<=$A9)*MOVIMIENTOS!$E$5:$E$400)+SUMPRODUCT((MOVIMIENTOS!$B$5:$B$400="AJUSTE")*(MOVIMIENTOS!$C$5:$C$400="A")*(MOVIMIENTOS!$D$5:$D$400="jabas")*(MOVIMIENTOS!$A$5:$A$400<>"")*(MOVIMIENTOS!$A$5:$A$400<=$A9)*MOVIMIENTOS!$E$5:$E$400)) -> 24 | C9: =IF($A9="","",SUMPRODUCT((MOVIMIENTOS!$B$5:$B$400="SALDO INICIAL")*(MOVIMIENTOS!$C$5:$C$400="P")*(MOVIMIENTOS!$D$5:$D$400="jabas")*(MOVIMIENTOS!$A$5:$A$400<>"")*(MOVIMIENTOS!$A$5:$A$400<=$A9)*MOVIMIENTOS!$E$5:$E$400)+SUMPRODUCT((MOVIMIENTOS!$B$5:$B$400="PROCESO")*(MOVIMIENTOS!$C$5:$C$400="P")*(MOVIMIENTOS!$D$5:$D$400="jabas")*(MOVIMIENTOS!$A$5:$A$400<>"")*(MOVIMIENTOS!$A$5:$A$400<=$A9)*MOVIMIENTOS!$E$5:$E$400)-SUMPRODUCT((MOVIMIENTOS!$B$5:$B$400="ENVÍO A SUPESA")*(MOVIMIENTOS!$C$5:$C$400="P")*(MOVIMIENTOS!$D$5:$D$400="jabas")*(MOVIMIENTOS!$A$5:$A$400<>"")*(MOVIMIENTOS!$A$5:$A$400<=$A9)*MOVIMIENTOS!$E$5:$E$400)+SUMPRODUCT((MOVIMIENTOS!$B$5:$B$400="DEVOLUCIÓN")*(MOVIMIENTOS!$C$5:$C$400="P")*(MOVIMIENTOS!$D$5:$D$400="jabas")*(MOVIMIENTOS!$A$5:$A$400<>"")*(MOVIMIENTOS!$A$5:$A$400<=$A9)*MOVIMIENTOS!$E$5:$E$400)-SUMPRODUCT((MOVIMIENTOS!$B$5:$B$400="TRASIEGO")*(MOVIMIENTOS!$C$5:$C$400="P")*(MOVIMIENTOS!$D$5:$D$400="jabas")*(MOVIMIENTOS!$A$5:$A$400<>"")*(MOVIMIENTOS!$A$5:$A$400<=$A9)*MOVIMIENTOS!$E$5:$E$400)-SUMPRODUCT((MOVIMIENTOS!$B$5:$B$400="REGALO")*(MOVIMIENTOS!$C$5:$C$400="P")*(MOVIMIENTOS!$D$5:$D$400="jabas")*(MOVIMIENTOS!$A$5:$A$400<>"")*(MOVIMIENTOS!$A$5:$A$400<=$A9)*MOVIMIENTOS!$E$5:$E$400)-SUMPRODUCT((MOVIMIENTOS!$B$5:$B$400="VENTA")*(MOVIMIENTOS!$C$5:$C$400="P")*(MOVIMIENTOS!$D$5:$D$400="jabas")*(MOVIMIENTOS!$A$5:$A$400<>"")*(MOVIMIENTOS!$A$5:$A$400<=$A9)*MOVIMIENTOS!$E$5:$E$400)+SUMPRODUCT((MOVIMIENTOS!$B$5:$B$400="AJUSTE")*(MOVIMIENTOS!$C$5:$C$400="P")*(MOVIMIENTOS!$D$5:$D$400="jabas")*(MOVIMIENTOS!$A$5:$A$400<>"")*(MOVIMIENTOS!$A$5:$A$400<=$A9)*MOVIMIENTOS!$E$5:$E$400)) -> 11 | D9: =IF($A9="","",SUMPRODUCT((MOVIMIENTOS!$B$5:$B$400="SALDO INICIAL")*(MOVIMIENTOS!$C$5:$C$400="C")*(MOVIMIENTOS!$D$5:$D$400="jabas")*(MOVIMIENTOS!$A$5:$A$400<>"")*(MOVIMIENTOS!$A$5:$A$400<=$A9)*MOVIMIENTOS!$E$5:$E$400)+SUMPRODUCT((MOVIMIENTOS!$B$5:$B$400="PROCESO")*(MOVIMIENTOS!$C$5:$C$400="C")*(MOVIMIENTOS!$D$5:$D$400="jabas")*(MOVIMIENTOS!$A$5:$A$400<>"")*(MOVIMIENTOS!$A$5:$A$400<=$A9)*MOVIMIENTOS!$E$5:$E$400)-SUMPRODUCT((MOVIMIENTOS!$B$5:$B$400="ENVÍO A SUPESA")*(MOVIMIENTOS!$C$5:$C$400="C")*(MOVIMIENTOS!$D$5:$D$400="jabas")*(MOVIMIENTOS!$A$5:$A$400<>"")*(MOVIMIENTOS!$A$5:$A$400<=$A9)*MOVIMIENTOS!$E$5:$E$400)+SUMPRODUCT((MOVIMIENTOS!$B$5:$B$400="DEVOLUCIÓN")*(MOVIMIENTOS!$C$5:$C$400="C")*(MOVIMIENTOS!$D$5:$D$400="jabas")*(MOVIMIENTOS!$A$5:$A$400<>"")*(MOVIMIENTOS!$A$5:$A$400<=$A9)*MOVIMIENTOS!$E$5:$E$400)-SUMPRODUCT((MOVIMIENTOS!$B$5:$B$400="TRASIEGO")*(MOVIMIENTOS!$C$5:$C$400="C")*(MOVIMIENTOS!$D$5:$D$400="jabas")*(MOVIMIENTOS!$A$5:$A$400<>"")*(MOVIMIENTOS!$A$5:$A$400<=$A9)*MOVIMIENTOS!$E$5:$E$400)-SUMPRODUCT((MOVIMIENTOS!$B$5:$B$400="REGALO")*(MOVIMIENTOS!$C$5:$C$400="C")*(MOVIMIENTOS!$D$5:$D$400="jabas")*(MOVIMIENTOS!$A$5:$A$400<>"")*(MOVIMIENTOS!$A$5:$A$400<=$A9)*MOVIMIENTOS!$E$5:$E$400)-SUMPRODUCT((MOVIMIENTOS!$B$5:$B$400="VENTA")*(MOVIMIENTOS!$C$5:$C$400="C")*(MOVIMIENTOS!$D$5:$D$400="jabas")*(MOVIMIENTOS!$A$5:$A$400<>"")*(MOVIMIENTOS!$A$5:$A$400<=$A9)*MOVIMIENTOS!$E$5:$E$400)+SUMPRODUCT((MOVIMIENTOS!$B$5:$B$400="AJUSTE")*(MOVIMIENTOS!$C$5:$C$400="C")*(MOVIMIENTOS!$D$5:$D$400="jabas")*(MOVIMIENTOS!$A$5:$A$400<>"")*(MOVIMIENTOS!$A$5:$A$400<=$A9)*MOVIMIENTOS!$E$5:$E$400)) -> 12 | E9: =IF($A9="","",SUMPRODUCT((MOVIMIENTOS!$B$5:$B$400="SALDO INICIAL")*(MOVIMIENTOS!$C$5:$C$400="M")*(MOVIMIENTOS!$D$5:$D$400="jabas")*(MOVIMIENTOS!$A$5:$A$400<>"")*(MOVIMIENTOS!$A$5:$A$400<=$A9)*MOVIMIENTOS!$E$5:$E$400)+SUMPRODUCT((MOVIMIENTOS!$B$5:$B$400="PROCESO")*(MOVIMIENTOS!$C$5:$C$400="M")*(MOVIMIENTOS!$D$5:$D$400="jabas")*(MOVIMIENTOS!$A$5:$A$400<>"")*(MOVIMIENTOS!$A$5:$A$400<=$A9)*MOVIMIENTOS!$E$5:$E$400)-SUMPRODUCT((MOVIMIENTOS!$B$5:$B$400="ENVÍO A SUPESA")*(MOVIMIENTOS!$C$5:$C$400="M")*(MOVIMIENTOS!$D$5:$D$400="jabas")*(MOVIMIENTOS!$A$5:$A$400<>"")*(MOVIMIENTOS!$A$5:$A$400<=$A9)*MOVIMIENTOS!$E$5:$E$400)+SUMPRODUCT((MOVIMIENTOS!$B$5:$B$400="DEVOLUCIÓN")*(MOVIMIENTOS!$C$5:$C$400="M")*(MOVIMIENTOS!$D$5:$D$400="jabas")*(MOVIMIENTOS!$A$5:$A$400<>"")*(MOVIMIENTOS!$A$5:$A$400<=$A9)*MOVIMIENTOS!$E$5:$E$400)-SUMPRODUCT((MOVIMIENTOS!$B$5:$B$400="TRASIEGO")*(MOVIMIENTOS!$C$5:$C$400="M")*(MOVIMIENTOS!$D$5:$D$400="jabas")*(MOVIMIENTOS!$A$5:$A$400<>"")*(MOVIMIENTOS!$A$5:$A$400<=$A9)*MOVIMIENTOS!$E$5:$E$400)-SUMPRODUCT((MOVIMIENTOS!$B$5:$B$400="REGALO")*(MOVIMIENTOS!$C$5:$C$400="M")*(MOVIMIENTOS!$D$5:$D$400="jabas")*(MOVIMIENTOS!$A$5:$A$400<>"")*(MOVIMIENTOS!$A$5:$A$400<=$A9)*MOVIMIENTOS!$E$5:$E$400)-SUMPRODUCT((MOVIMIENTOS!$B$5:$B$400="VENTA")*(MOVIMIENTOS!$C$5:$C$400="M")*(MOVIMIENTOS!$D$5:$D$400="jabas")*(MOVIMIENTOS!$A$5:$A$400<>"")*(MOVIMIENTOS!$A$5:$A$400<=$A9)*MOVIMIENTOS!$E$5:$E$400)+SUMPRODUCT((MOVIMIENTOS!$B$5:$B$400="AJUSTE")*(MOVIMIENTOS!$C$5:$C$400="M")*(MOVIMIENTOS!$D$5:$D$400="jabas")*(MOVIMIENTOS!$A$5:$A$400<>"")*(MOVIMIENTOS!$A$5:$A$400<=$A9)*MOVIMIENTOS!$E$5:$E$400)) -> 36 | F9: =IF($A9="","",SUMPRODUCT((MOVIMIENTOS!$B$5:$B$400="SALDO INICIAL")*(MOVIMIENTOS!$C$5:$C$400="Chancho")*(MOVIMIENTOS!$D$5:$D$400="sacos")*(MOVIMIENTOS!$A$5:$A$400<>"")*(MOVIMIENTOS!$A$5:$A$400<=$A9)*MOVIMIENTOS!$E$5:$E$400)+SUMPRODUCT((MOVIMIENTOS!$B$5:$B$400="PROCESO")*(MOVIMIENTOS!$C$5:$C$400="Chancho")*(MOVIMIENTOS!$D$5:$D$400="sacos")*(MOVIMIENTOS!$A$5:$A$400<>"")*(MOVIMIENTOS!$A$5:$A$400<=$A9)*MOVIMIENTOS!$E$5:$E$400)-SUMPRODUCT((MOVIMIENTOS!$B$5:$B$400="VENTA CHANCHO")*(MOVIMIENTOS!$C$5:$C$400="Chancho")*(MOVIMIENTOS!$D$5:$D$400="sacos")*(MOVIMIENTOS!$A$5:$A$400<>"")*(MOVIMIENTOS!$A$5:$A$400<=$A9)*MOVIMIENTOS!$E$5:$E$400)-SUMPRODUCT((MOVIMIENTOS!$B$5:$B$400="REGALO")*(MOVIMIENTOS!$C$5:$C$400="Chancho")*(MOVIMIENTOS!$D$5:$D$400="sacos")*(MOVIMIENTOS!$A$5:$A$400<>"")*(MOVIMIENTOS!$A$5:$A$400<=$A9)*MOVIMIENTOS!$E$5:$E$400)-SUMPRODUCT((MOVIMIENTOS!$B$5:$B$400="VENTA")*(MOVIMIENTOS!$C$5:$C$400="Chancho")*(MOVIMIENTOS!$D$5:$D$400="sacos")*(MOVIMIENTOS!$A$5:$A$400<>"")*(MOVIMIENTOS!$A$5:$A$400<=$A9)*MOVIMIENTOS!$E$5:$E$400)+SUMPRODUCT((MOVIMIENTOS!$B$5:$B$400="AJUSTE")*(MOVIMIENTOS!$C$5:$C$400="Chancho")*(MOVIMIENTOS!$D$5:$D$400="sacos")*(MOVIMIENTOS!$A$5:$A$400<>"")*(MOVIMIENTOS!$A$5:$A$400<=$A9)*MOVIMIENTOS!$E$5:$E$400)) -> 5 | G9: =IF($A9="","",SUM(B9:E9)) -> 83 | H9: =IF($A9="","",SUMPRODUCT((((MOVIMIENTOS!$B$5:$B$400="SALDO INICIAL")*(MOVIMIENTOS!$C$5:$C$400<>"Chancho"))+(MOVIMIENTOS!$B$5:$B$400="COMPRA")+(MOVIMIENTOS!$B$5:$B$400="REPROCESO")+(MOVIMIENTOS!$B$5:$B$400="DEVOLUCIÓN")+((MOVIMIENTOS!$B$5:$B$400="AJUSTE")*(MOVIMIENTOS!$C$5:$C$400<>"Chancho")))*(MOVIMIENTOS!$A$5:$A$400<>"")*(MOVIMIENTOS!$A$5:$A$400<=$A9)*MOVIMIENTOS!$I$5:$I$400)-SUMPRODUCT(((MOVIMIENTOS!$B$5:$B$400="ENVÍO A SUPESA")+(MOVIMIENTOS!$B$5:$B$400="ENVÍO A TOTTUS")+(MOVIMIENTOS!$B$5:$B$400="ENVIO A TOTTUS")+(MOVIMIENTOS!$B$5:$B$400="MALOGRADO")+(MOVIMIENTOS!$B$5:$B$400="OTRA SALIDA")+((MOVIMIENTOS!$B$5:$B$400="PROCESO")*(MOVIMIENTOS!$C$5:$C$400="Chancho"))+((MOVIMIENTOS!$B$5:$B$400="REGALO")*(MOVIMIENTOS!$C$5:$C$400<>"Chancho"))+((MOVIMIENTOS!$B$5:$B$400="VENTA")*(MOVIMIENTOS!$C$5:$C$400<>"Chancho")))*(MOVIMIENTOS!$A$5:$A$400<>"")*(MOVIMIENTOS!$A$5:$A$400<=$A9)*MOVIMIENTOS!$I$5:$I$400)) -> 1249 | J9: =IF(AND(MOVIMIENTOS!$A9<>"",COUNTIF(MOVIMIENTOS!$A$5:$A8,MOVIMIENTOS!$A9)=0),COUNT(J$4:J8)+1,"") -> 2 | K9: =MOVIMIENTOS!$A9 -> 46215
